Workbook
Name Ana_Kompanent: [1]Atamalar!$A$10:$A$33
Name Ana_Kompanent: #REF!
Name Ant_2: #REF!
Name Araç_Şase: [1]Atamalar!#REF!
Name Araç_Şase: #REF!
Name Araç_Şase_Numaraları: [1]Atamalar!#REF!
Name Araç_Şase_Numaraları: #REF!
Name Araç_Tipi: [1]Atamalar!#REF!
Name Araç_Tipi: #REF!
Name Assembly_Line: [1]Atamalar!#REF!
Name Assembly_Line: #REF!
Name Auxiliary_Power_Unit: #REF!
Name Batarya: #REF!
Name Bogie: #REF!
Name Boji: #REF!
Name BOZANKAYA_Design: [1]Atamalar!#REF!
Name BOZANKAYA_Design: #REF!
Name Bölüm: [1]Atamalar!#REF!
Name Bölüm: #REF!
Name Brake_System: #REF!
Name CCTV: #REF!
Name Chassis_Design: [1]Atamalar!#REF!
Name Chassis_Design: #REF!
Name Chassis_Production: [1]Atamalar!#REF!
Name Chassis_Production: #REF!
Name Chassis_Quality: [1]Atamalar!#REF!
Name Chassis_Quality: #REF!
Name Chassis_Quality_Controls: [1]Atamalar!#REF!
Name Chassis_Quality_Controls: #REF!
Name Couplers: #REF!
Name Department: [1]Atamalar!#REF!
Name Department: #REF!
Name Door_System: #REF!
Name Driver_HVAC_System: #REF!
Name E_Kabinet: #REF!
Name Electrical_Design: [1]Atamalar!#REF!
Name Electrical_Design: #REF!
Name Electromechanic_Tasarım: [1]Atamalar!#REF!
Name Electromechanic_Tasarım: #REF!
Name Elektrik_Tasarım: [1]Atamalar!#REF!
Name Elektrik_Tasarım: #REF!
Name External_Light: #REF!
Name External_Trim: #REF!
Name Gangway_Articulation: #REF!
Name Gearbox: #REF!
Name Giriş_Kalite_Kontrol: [1]Atamalar!#REF!
Name Giriş_Kalite_Kontrol: #REF!
Name HataDurumu: '[2]Hata Durumu'!$B$2:$B$4
Name HataGidermeYöntemi1: '[2]Hata Giderme Yöntemi'!$B$2:$B$5
Name HataKaynağı: '[2]Hata Kaynağı'!$B$2:$B$5
Name HMI: #REF!
Name Horn_Bell: #REF!
Name HSCB: #REF!
Name IASI_16: #REF!
Name Internal_Light: #REF!
Name Internal_Trim: #REF!
Name Intervall_IS1_Name: [3]Overview!$H$30
Name Intervall_IS2_Name: [3]Overview!$H$31
Name Intervall_IS2I_Name: [3]Overview!$H$32
Name Intervall_IS2II_Name: [3]Overview!$H$33

Sheet FRACAS (YENİ)
N1: FRACAS(Hata Raporlama Analizi ve Düzeltici Aksiyon Sitemi) Formu FRACAS(Failure Reporting Analysis And Corrective Action System) Form | AB1: Doküman No / Document Code; FR-549 Yayımlama Tarih / Publish Datei; 23.05.2023 Revizyon Tarihi / Revision; 04.08.2025 Revizyon No: 4 | AP1: =TODAY() -> 46026 | AQ1: X | AR1: Proje Pik Saatleri Proje Peak Times | AS1: 0.27083333 | AT1: 0.39583333 | AU1: 0.66666667 | AV1: 0.8125 | AW1: Proje Ort Hız Proje Avr. Speed | AY1: 18 | AZ1: km | BA1: Proje İşçilik Maliyeti Project Labor Cost | BC1: 11 | BD1: hbm.142536
A3: Araç Bilgileri Vhicle Information | E3: Problem Bilgileri Failure Information | P3: (EN 50126-1:2017 Tabl C.3 | Q3: (EN 50126-1:2017 Tabl C.5 | R3: Çözüm Adımları ve Bilgileri Solution Steps And Information | AO3: Tamir İçin Gerekli Parçalar Needed Parts For Repairing | AW3: Maliyet Cost
A4: Project | B4: Araç Numarası Vehicle Number | C4: Araç Module Vehicle Module | D4: Araç Kilometresi Vehicle Kilometer | E4: FRACAS ID | F4: Hata Tarih/Date | G4: Hata Saat/Time | I4: Arıza Konumu Failure Location | J4: Arıza Tespit Yöntemi Failure Detection Method | K4: Kapsam Scope | L4: İlgili Tedarikçi Relevant Supplier | M4: Proje Bazında Fracas ID Fracas ID Based on Project | N4: Arıza Tanımı Failure Description | O4: DDU Arıza Sınıfı DDU Failure Class | P4: Arıza Sınıfı Failure Class | Q4: Arızanın Emniyetle İlgili Şiddet Kategorisi Safety Related Severity Category of Failure | R4: Arıza Kaynağı Source of Failure | S4: Arıza Tespitini Takiben Yapılan İşlem Action Followed by Fault Detection | T4: Aksiyon Action | U4: Garanti Kapsamı Warranty Coverage | V4: Tamir için Gerekli Personel Sayısı Required Personnel Quantity for Repair | W4: Tamir/Değiştirme Başlama Tarihi Date of Starting to Repair/Replace | X4: Tamir/Değiştirme Başlama Saati Time of Starting to Repair/Replace | Z4: Tamir/Değiştirme Bitiş Tarihi Date of Fnish to Repair/Replace | AA4: Tamir/Değiştirme Bitiş Saati Time of Fnish to Repair/Replace | AC4: Tamir Süresi (dakika) Repair Time (dakika) | AD4: Servise Veriliş Tarih Date of Ready to Service | AE4: Servise Veriliş Saati Time of Ready to Service | AG4: Arıza Tipi Failure Type | AH4: Detaylı Bilgi Detail İnformation | AI4: NCR Numarası NCR Number | AJ4: NCR Kapanış Tarihi NCR Closing Date | AK4: NCR Kapanış Saati NCR Closing Time | AM4: Araç MTTR / MDT | AN4: Kompanent MTTR / MDT | AO4: Ekipman Tedarikçisi Equipment Supplier | AP4: Parça Kodu Part Code | AQ4: Seri Numarası Serial Number | AR4: Parça Adı Part Name | AS4: Adeti Quantity | AT4: Sipariş No Order No | AU4: Sipariş Tarihi Order Date | AV4: Teslim Tarihi Delivery Date | AW4: Malzeme Maliyeti Material Cost | AX4: İşçilik Maliyeti Labor Cost
A5: TIM_1624 | B5: 1001 | D5: 200 | F5: 45636 | G5: 0.29166667 | H5: =F5+G5 -> 45636.292 | I5: Hat/Line | J5: Notified By Customer | K5: Brake_System | L5: Hanning&Kall | M5: =A5&"-"&E5 -> TIM_1624- | N5: abv | O5: B | P5: C:Küçük Arıza | Q5: A | R5: Customer | S5: bndsi | T5: Tamir Edilecek/To Be Repaired | U5: Evet/Yes | V5: 2 | W5: 45636 | X5: 0.45833333 | Y5: =W5+X5 -> 45636.458 | Z5: 45636 | AA5: 0.85416667 | AB5: =Z5+AA5 -> 45636.854 | AC5: =(AF5-H5)*24*60 -> 810 | AD5: 45636 | AE5: 0.85416667 | AF5: =AD5+AE5 -> 45636.854 | AG5: İlk defa karşılaşılan arıza / First time failure | AH5: Bu Arıza Aracın Servise Verilmesine Engel Değil | AL5: =AJ5+AK5 -> 0 | AM5: =IF(AND(P5<>"D:Arıza Değil",AH5="Bu Arıza Aracın Servise Verilmesine Engel Değil"),IF(Z5-F5>0,(AB5-Y5)*24,IF(OR(AND(G5>AS$1,G5<AT$1),AND(G5>AU$1,G5<AV$1)),(AF5-H5)*24,0)),AN5) -> 13.5 | AN5: =IF(P5<>"D:Arıza Değil",AC5,0) -> 810 | AP5: =IF(AQ1="X", IF(AND(G5>=AS1,G5<=AT1),IF(P5<>"D:Arıza Değil",AC5,0),FRACAS!BB5 IF(AND(G5>=AU1,G5<=AV1),IF(P5<>"D:Arıza Değil",AC5,0), "")), "") -> 810 | AW5: 0 | AX5: =V5*AC5*BC$1 -> 17820
A6: TIM_1625 | M6: =A6&"-"&E6 -> TIM_1625- | Y6: =W6+X6 -> 0 | AB6: =Z6+AA6 -> 0 | AC6: =(AB6-Y6)*24*60 -> 0 | AF6: =AD6+AE6 -> 0 | AL6: =AJ6+AK6 -> 0 | AM6: =IF(AND(P6<>"D:Arıza Değil",AH6="Bu Arıza Aracın Servise Verilmesine Engel Değil"),IF(Z6-F6>0,(AB6-Y6)*24,IF(OR(AND(G6>AS$1,G6<AT$1),AND(G6>AU$1,G6<AV$1)),(AL6-Y6)*24,0)),AN6) -> 0 | AN6: =IF(P6<>"D:Arıza Değil",AC6,0) -> 0 | AP6: =IF(AND(P5<>"D:Arıza Değil",AH5="Bu Arıza Aracın Servise Verilmesine Engel Değil"),IF(Z5-F5>0,(AB5-Y5)*24,IF(AQ1="X",IF(AND(G5>=AS1,G5<=AT1),IF(P5<>"D:Arıza Değil",AC5,0),IF(AND(G5>=AU1,G5<=AV1),IF(P5<>"D:Arıza Değil",AC5,0),"")),0)),AN5) -> 810 | AW6: 0 | AX6: =V6*AC6*BC$1 -> 0
M7: =A7&"-"&E7 -> - | Y7: =W7+X7 -> 0 | AB7: =Z7+AA7 -> 0 | AC7: =(AB7-Y7)*24*60 -> 0 | AF7: =AD7+AE7 -> 0 | AL7: =AJ7+AK7 -> 0 | AM7: =IF(AND(P7<>"D:Arıza Değil",AH7="Bu Arıza Aracın Servise Verilmesine Engel Değil"),IF(Z7-F7>0,(AB7-Y7)*24,IF(OR(AND(G7>AS$1,G7<AT$1),AND(G7>AU$1,G7<AV$1)),(AL7-Y7)*24,0)),AN7) -> 0 | AN7: =IF(P7<>"D:Arıza Değil",AC7,0) -> 0 | AW7: 0 | AX7: =V7*AC7*BC$1 -> 0
M8: =A8&"-"&E8 -> - | Y8: =W8+X8 -> 0 | AB8: =Z8+AA8 -> 0 | AC8: =(AB8-Y8)*24*60 -> 0 | AF8: =AD8+AE8 -> 0 | AL8: =AJ8+AK8 -> 0 | AM8: =IF(AND(P8<>"D:Arıza Değil",AH8="Bu Arıza Aracın Servise Verilmesine Engel Değil"),IF(Z8-F8>0,(AB8-Y8)*24,IF(OR(AND(G8>AS$1,G8<AT$1),AND(G8>AU$1,G8<AV$1)),(AL8-Y8)*24,0)),AN8) -> 0 | AN8: =IF(P8<>"D:Arıza Değil",AC8,0) -> 0 | AW8: 0 | AX8: =V8*AC8*BC$1 -> 0
M9: =A9&"-"&E9 -> - | Y9: =W9+X9 -> 0 | AB9: =Z9+AA9 -> 0 | AC9: =(AB9-Y9)*24*60 -> 0 | AF9: =AD9+AE9 -> 0 | AL9: =AJ9+AK9 -> 0 | AM9: =IF(AND(P9<>"D:Arıza Değil",AH9="Bu Arıza Aracın Servise Verilmesine Engel Değil"),IF(Z9-F9>0,(AB9-Y9)*24,IF(OR(AND(G9>AS$1,G9<AT$1),AND(G9>AU$1,G9<AV$1)),(AL9-Y9)*24,0)),AN9) -> 0 | AN9: =IF(P9<>"D:Arıza Değil",AC9,0) -> 0 | AW9: 0 | AX9: =V9*AC9*BC$1 -> 0
M10: =A10&"-"&E10 -> - | Y10: =W10+X10 -> 0 | AB10: =Z10+AA10 -> 0 | AC10: =(AB10-Y10)*24*60 -> 0 | AF10: =AD10+AE10 -> 0 | AL10: =AJ10+AK10 -> 0 | AM10: =IF(AND(P10<>"D:Arıza Değil",AH10="Bu Arıza Aracın Servise Verilmesine Engel Değil"),IF(Z10-F10>0,(AB10-Y10)*24,IF(OR(AND(G10>AS$1,G10<AT$1),AND(G10>AU$1,G10<AV$1)),(AL10-Y10)*24,0)),AN10) -> 0 | AN10: =IF(P10<>"D:Arıza Değil",AC10,0) -> 0 | AW10: 0 | AX10: =V10*AC10*BC$1 -> 0
M11: =A11&"-"&E11 -> - | Y11: =W11+X11 -> 0 | AB11: =Z11+AA11 -> 0 | AC11: =(AB11-Y11)*24*60 -> 0 | AF11: =AD11+AE11 -> 0 | AL11: =AJ11+AK11 -> 0 | AM11: =IF(AND(P11<>"D:Arıza Değil",AH11="Bu Arıza Aracın Servise Verilmesine Engel Değil"),IF(Z11-F11>0,(AB11-Y11)*24,IF(OR(AND(G11>AS$1,G11<AT$1),AND(G11>AU$1,G11<AV$1)),(AL11-Y11)*24,0)),AN11) -> 0 | AN11: =IF(P11<>"D:Arıza Değil",AC11,0) -> 0 | AW11: 0 | AX11: =V11*AC11*BC$1 -> 0
M12: =A12&"-"&E12 -> - | Y12: =W12+X12 -> 0 | AB12: =Z12+AA12 -> 0 | AC12: =(AB12-Y12)*24*60 -> 0 | AF12: =AD12+AE12 -> 0 | AL12: =AJ12+AK12 -> 0 | AM12: =IF(AND(P12<>"D:Arıza Değil",AH12="Bu Arıza Aracın Servise Verilmesine Engel Değil"),IF(Z12-F12>0,(AB12-Y12)*24,IF(OR(AND(G12>AS$1,G12<AT$1),AND(G12>AU$1,G12<AV$1)),(AL12-Y12)*24,0)),AN12) -> 0 | AN12: =IF(P12<>"D:Arıza Değil",AC12,0) -> 0 | AW12: 0 | AX12: =V12*AC12*BC$1 -> 0
M13: =A13&"-"&E13 -> - | Y13: =W13+X13 -> 0 | AB13: =Z13+AA13 -> 0 | AC13: =(AB13-Y13)*24*60 -> 0 | AF13: =AD13+AE13 -> 0 | AL13: =AJ13+AK13 -> 0 | AM13: =IF(AND(P13<>"D:Arıza Değil",AH13="Bu Arıza Aracın Servise Verilmesine Engel Değil"),IF(Z13-F13>0,(AB13-Y13)*24,IF(OR(AND(G13>AS$1,G13<AT$1),AND(G13>AU$1,G13<AV$1)),(AL13-Y13)*24,0)),AN13) -> 0 | AN13: =IF(P13<>"D:Arıza Değil",AC13,0) -> 0 | AW13: 0 | AX13: =V13*AC13*BC$1 -> 0
M14: =A14&"-"&E14 -> - | Y14: =W14+X14 -> 0 | AB14: =Z14+AA14 -> 0 | AC14: =(AB14-Y14)*24*60 -> 0 | AF14: =AD14+AE14 -> 0 | AL14: =AJ14+AK14 -> 0 | AM14: =IF(AND(P14<>"D:Arıza Değil",AH14="Bu Arıza Aracın Servise Verilmesine Engel Değil"),IF(Z14-F14>0,(AB14-Y14)*24,IF(OR(AND(G14>AS$1,G14<AT$1),AND(G14>AU$1,G14<AV$1)),(AL14-Y14)*24,0)),AN14) -> 0 | AN14: =IF(P14<>"D:Arıza Değil",AC14,0) -> 0 | AW14: 0 | AX14: =V14*AC14*BC$1 -> 0
M15: =A15&"-"&E15 -> - | Y15: =W15+X15 -> 0 | AB15: =Z15+AA15 -> 0 | AC15: =(AB15-Y15)*24*60 -> 0 | AF15: =AD15+AE15 -> 0 | AL15: =AJ15+AK15 -> 0 | AM15: =IF(AND(P15<>"D:Arıza Değil",AH15="Bu Arıza Aracın Servise Verilmesine Engel Değil"),IF(Z15-F15>0,(AB15-Y15)*24,IF(OR(AND(G15>AS$1,G15<AT$1),AND(G15>AU$1,G15<AV$1)),(AL15-Y15)*24,0)),AN15) -> 0 | AN15: =IF(P15<>"D:Arıza Değil",AC15,0) -> 0 | AW15: 0 | AX15: =V15*AC15*BC$1 -> 0
M16: =A16&"-"&E16 -> - | Y16: =W16+X16 -> 0 | AB16: =Z16+AA16 -> 0 | AC16: =(AB16-Y16)*24*60 -> 0 | AF16: =AD16+AE16 -> 0 | AL16: =AJ16+AK16 -> 0 | AM16: =IF(AND(P16<>"D:Arıza Değil",AH16="Bu Arıza Aracın Servise Verilmesine Engel Değil"),IF(Z16-F16>0,(AB16-Y16)*24,IF(OR(AND(G16>AS$1,G16<AT$1),AND(G16>AU$1,G16<AV$1)),(AL16-Y16)*24,0)),AN16) -> 0 | AN16: =IF(P16<>"D:Arıza Değil",AC16,0) -> 0 | AW16: 0 | AX16: =V16*AC16*BC$1 -> 0
M17: =A17&"-"&E17 -> - | Y17: =W17+X17 -> 0 | AB17: =Z17+AA17 -> 0 | AC17: =(AB17-Y17)*24*60 -> 0 | AF17: =AD17+AE17 -> 0 | AL17: =AJ17+AK17 -> 0 | AM17: =IF(AND(P17<>"D:Arıza Değil",AH17="Bu Arıza Aracın Servise Verilmesine Engel Değil"),IF(Z17-F17>0,(AB17-Y17)*24,IF(OR(AND(G17>AS$1,G17<AT$1),AND(G17>AU$1,G17<AV$1)),(AL17-Y17)*24,0)),AN17) -> 0 | AN17: =IF(P17<>"D:Arıza Değil",AC17,0) -> 0 | AW17: 0 | AX17: =V17*AC17*BC$1 -> 0
M18: =A18&"-"&E18 -> - | Y18: =W18+X18 -> 0 | AB18: =Z18+AA18 -> 0 | AC18: =(AB18-Y18)*24*60 -> 0 | AF18: =AD18+AE18 -> 0 | AL18: =AJ18+AK18 -> 0 | AM18: =IF(AND(P18<>"D:Arıza Değil",AH18="Bu Arıza Aracın Servise Verilmesine Engel Değil"),IF(Z18-F18>0,(AB18-Y18)*24,IF(OR(AND(G18>AS$1,G18<AT$1),AND(G18>AU$1,G18<AV$1)),(AL18-Y18)*24,0)),AN18) -> 0 | AN18: =IF(P18<>"D:Arıza Değil",AC18,0) -> 0 | AW18: 0 | AX18: =V18*AC18*BC$1 -> 0
... M856: =A856&"-"&E856 -> - | Y856: =W856+X856 -> 0 | AB856: =Z856+AA856 -> 0 | AC856: =(AB856-Y856)*24*60 -> 0 | AF856: =AD856+AE856 -> 0 | AL856: =AJ856+AK856 -> 0 | AM856: =IF(AND(P856<>"D:Arıza Değil",AH856="Bu Arıza Aracın Servise Verilmesine Engel Değil"),IF(Z856-F856>0,(AB856-Y856)*24,IF(OR(AND(G856>AS$1,G856<AT$1),AND(G856>AU$1,G856<AV$1)),(AL856-Y856)*24,0)),AN856) -> 0 | AN856: =IF(P856<>"D:Arıza Değil",AC856,0) -> 0 | AW856: 0 | AX856: =V856*AC856*BC$1 -> 0

Sheet FRACAS
N1: FRACAS(Hata Raporlama Analizi ve Düzeltici Aksiyon Sitemi) Formu FRACAS(Failure Reporting Analysis And Corrective Action System) Form | AP1: =TODAY() -> 46026 | AR1: Proje Pik Saatleri Proje Peak Times | AS1: 0.25 | AT1: 0.41666667 | AU1: 0.58333333 | AV1: 0.79166667 | AW1: Proje Ort Hız Proje Avr. Speed | AY1: 20 | BC1: 11 | BD1: hbm.142536
A4: Project | B4: Araç Numarası Vehicle Number | C4: Araç Module Vehicle Module | D4: Araç Kilometresi Vehicle Kilometer | E4: FRACAS ID | F4: Hata Tarih /Date | G4: Hata Saat /Time | H4: . | I4: Arıza Konumu Failure Location | J4: Arıza Tespit Yöntemi Failure Detection Method | K4: Kapsam Scope | L4: İlgili Tedarikçi Relevant Supplier | M4: Proje Bazında Fracas ID Fracas ID Based on Project | N4: Arıza Tanımı Failure Description | O4: DDU Arıza Sınıfı DDU Failure Class | P4: Arıza Sınıfı Failure Class | Q4: Arızanın Emniyetle İlgili Şiddet Kategorisi Safety Related Severity Category of Failure | R4: Arıza Kaynağı Source of Failure | S4: Arıza Tespitini Takiben Yapılan İşlem Action Followed by Fault Detection | T4: Aksiyon Action | U4: Garanti Kapsamı Warranty Coverage | V4: Tamir için Gerekli Personel Sayısı Required Personnel Quantity for Repair | W4: Tamir/Değiştirme Başlama Tarihi Date of Starting to Repair/Replace | X4: Tamir/Değiştirme Başlama Saati Time of Starting to Repair/Replace | Y4: . | Z4: Tamir/Değiştirme Bitiş Tarihi Date of Fnish to Repair/Replace | AA4: Tamir/Değiştirme Bitiş Saati Time of Fnish to Repair/Replace | AB4: . | AC4: Tamir Süresi (dakika) Repair Time (dakika) | AD4: Servise Veriliş Tarih Date of Ready to Service | AE4: Servise Veriliş Saati Time of Ready to Service | AF4: . | AG4: Arıza Tipi Failure Type | AH4: Detaylı Bilgi Detail İnformation | AI4: NCR Numarası NCR Number | AJ4: NCR Kapanış Tarihi NCR Closing Date | AK4: NCR Kapanış Saati | AL4: . | AM4: Araç MTTR / MDT | AN4: Kompanent MTTR / MDT | AO4: Ekipman Tedarikçisi Equipment Supplier | AP4: Parça Kodu Part Code | AQ4: Seri Numarası Serial Number | AR4: Parça Adı Part Name | AS4: Adeti Quantity | AT4: Sipariş No Order No | AU4: Sipariş Tarihi Order Date | AV4: Teslim Tarihi Delivery Date | AW4: Malzeme Maliyeti Material Cost | AX4: İşçilik Maliyeti Labor Cost | AY4: No | AZ4: Photo URL | BA4: Arıza Resmi | BB4: Pik Saat Hes. | BK4: NCR Bildirim Tarihi | BL4: Arıza Kaynağı (Sorumlu 2) | BN4: pik zaman kontrolü | BQ4: bekleme süresi | BR4: tamir süresi | BS4: arızalı kalma süresi | BV4: Tamirat | BY4: Tamire Başlama Süresi | BZ4: Tamirat süresi | CA4: toplam arıza süresi | CF4: arıza | CG4: tamir | CO4: Tamir Süresi (saat) Repair Time (hour) | CP4: tamir süresi TÜM (saat) | CQ4: Hata Tarih/Date | CR4: Tamir/Değiştirme Başlama Saati Time of Starting to Repair/Replace | CS4: Tamir/Değiştirme Bitiş Saati Time of Fnish to Repair/Replace | CT4: Bekleme süresi (dk) | CU4: Tamir süresi (dk) | CV4: Toplam Arıza süresi (dk) | CW4: Bekleme gecikme oranı
A5: =[4]SayfaKAY!C618 -> KAY5+6 | B5: =[4]SayfaKAY!D618 -> 3874(3) | C5: =[4]SayfaKAY!E618 -> MB | D5: =[4]SayfaKAY!F618 -> 143325 | E5: =[4]SayfaKAY!G618 -> BOZ-KAY5+6-FF-615 | F5: =IF(H5="","",INT(H5)) | G5: =IF(H5="","",MOD(H5,1)) | H5: =[4]SayfaKAY!H618 | I5: =[4]SayfaKAY!I618 -> Hat/Line | J5: =IF([4]SayfaKAY!J618="","",IF([4]SayfaKAY!J618="Müşteri","Notified by Customer","Notified by Bozankaya")) -> Notified by Customer | K5: =VLOOKUP([4]SayfaKAY!L618,#REF!,2,FALSE) -> #REF! | L5: =[4]SayfaKAY!X618 -> DENİZLER OTOMOTİV SAN. VE TİC.LTD.Ş | M5: =IF( E5="", "", A5&"-"&E5) -> KAY5+6-BOZ-KAY5+6-FF-615 | N5: =[4]SayfaKAY!M618 -> 3874 NOLU ARAÇ KABİN CB SİLECEK ARIZALI | O5: =[4]SayfaKAY!P618 -> D-Arıza değil | P5: =[4]SayfaKAY!Q618 -> B(Servisten çekmeye etki eden arıza) | Q5: =[4]SayfaKAY!R618 -> N.A(Yaralanma yok) | R5: {=IF([4]SayfaKAY!U618="","",_xlfn.IFS([4]SayfaKAY!U618="Bozankaya","Bozankaya",[4]SayfaKAY!U618="Müşteri","Customer",[4]SayfaKAY!U618="Tedarikçi","Equipment Supplier"))} -> Equipment Supplier | S5: =[4]SayfaKAY!N618 -> SİLECEK DEĞİŞİMİ YAPILDI | T5: =[4]SayfaKAY!AD618 -> Ekipman yenisi ile değiştirildi | U5: =[4]SayfaKAY!W618 -> Evet | V5: =[4]SayfaKAY!AZ618 -> 1 | W5: =IF(Y5="","",INT(Y5)) -> 45785 | X5: =IF(Y5="","",TEXT(Y5,"ss:dd")) -> 06:00 | Y5: =[4]SayfaKAY!AE618 -> 45785.25 | Z5: =IF(AB5="","",INT(AB5)) -> 45786 | AA5: =IF(AB5="","",TEXT(AB5,"ss:dd")) -> 09:00 | AB5: =[4]SayfaKAY!BA618 -> 45786.375 | AC5: =IF(AF5="","",(AF5-H5)*24*60) -> #VALUE! | AD5: =IF(AF5="","",INT(AF5)) -> 45786 | AE5: =IF(AF5="","",TEXT(AF5,"ss:dd")) -> 09:00 | AF5: =[4]SayfaKAY!BA618 -> 45786.375 | AG5: =[4]SayfaKAY!S618 -> (III) Farklı Araçlarda Tekrarlayan Arıza | AH5: =IF(P5="A(Hareket etmeyi engelleyen arıza)","Bu Arıza Aracın Servise Verilmesine Engel", IF(P5="B(Servisten çekmeye etki eden arıza)","Bu Arıza Aracın Servise Verilmesine Engel", IF(P5="C(Sisteme etki etmeyen arıza)","Bu Arıza Aracın Servise Verilmesine Engel Değil", IF(P5="D(Arıza Değil)","Bu Arıza Aracın Servise Verilmesine Engel Değil", "")))) -> Bu Arıza Aracın Servise Verilmesine Engel | AI5: =[4]SayfaKAY!AV618 | AJ5: =IF(AL5="","",INT(AL5)) | AK5: =IF(AL5="","",TEXT(AL5,"ss:dd")) | AL5: =[4]SayfaKAY!AX618 | AM5: {=IFERROR(IF(AND(P5<>"D(Arıza Değil)",AH5="Bu Arıza Aracın Servise Verilmesine Engel Değil"), IF(Z5-F5>0,(AB5-Y5)*24*60, IF(OR(AND(G5>$AS$1,G5<$AT$1),AND(G5>$AU$1,G5<$AV$1)), (AF5-H5)*24*60, BH:BH0)), AN5),0)} -> 0 | AN5: =IFERROR(IF(P5<>"D(Arıza Değil)",AC5,0),0) -> 0 | AO5: =[4]SayfaKAY!AG618 | AP5: =[4]SayfaKAY!AI618 | AQ5: =[4]SayfaKAY!AQ618 | AR5: =[4]SayfaKAY!AH618 | AS5: =[4]SayfaKAY!AJ618 | AT5: =[4]SayfaKAY!AM618 | AU5: =[4]SayfaKAY!AL618 | AV5: =[4]SayfaKAY!AP618 | AW5: =[4]SayfaKAY!AT618 | AX5: =IF(V5="","",V5*AC5*BC$1) -> #VALUE! | BB5: =IF($AQ$1="X", IF(AND(G5>=$AS$1,G5<=$AT$1),IF(P5<>"D(Arıza Değil)",AC5,0), IF(AND(G5>=$AU$1,G5<=$AV$1),IF(P5<>"D(Arıza Değil)",AC5,0), "")), "") | BH5: =IFERROR(FRACAS!AN621, "Hata Var") -> 1500 | BK5: =[4]SayfaKAY!AW618 | BL5: =[4]SayfaKAY!V618 -> Bozankaya | BN5: =IF($AQ$1="X", IF(AND(G5>=$AS$1,G5<=$AT$1),IF(P5<>"D(Arıza Değil",AC5,0),IF(AND(G5>=$AU$1,G5<=$AV$1),IF(P5<>"D:Arıza Değil",AC5,0), "x var")), "x yok") -> x yok | BO5: =IF(OR(AND(G5>$AS$1,G5<$AT$1),AND(G5>$AU$1,G5<$AV$1)),"aynı gün giderilen arıza") -> FALSE | BP5: =IF(Z5-F5>0,"Bir günden fazla süren arıza",IF(OR(AND(G5>$AS$1,G5<$AT$1),AND(G5>$AU$1,G5<$AV$1)),"aynı gün giderilen arıza")) -> #VALUE! | BQ5: =(Y5-H5)*24*60 -> #VALUE! | BR5: =(AB5-Y5)*24*60 -> 1620 | BS5: =(AF5-H5)*24*60 -> #VALUE! | BV5: =COUNTIFS(B$5:B$9980,B5,H$5:H$9980,"<="&AF5,AF$5:AF$9980,">="&H5)-1 -> -1 | BW5: =IF(COUNTIFS(B$5:B$9980,B5,H$5:H$9980,"<="&AF5,AF$5:AF$9980,">="&H5)>1,"Evet, çakışma var","Hayır, çakışma yok") -> Hayır, çakışma yok | BY5: =Y5-H5 -> #VALUE! | BZ5: =AB5-Y5 -> 1.125 | CA5: =AB5-H5 -> #VALUE! | CE5: 617 | CF5: =H5 | CG5: =AB5 -> 45786.375 | CK5: =AB5-Y5 -> 1.125 | CL5: =Y5-H5 -> #VALUE! | CM5: =AB5-H5 -> #VALUE! | CO5: =AC5 -> #VALUE! | CP5: =CU5/24 -> 67.5 | CQ5: =G5 | CR5: =Y5 -> 45785.25 | CS5: =AB5 -> 45786.375 | CT5: =(CR5-CQ5)*1440 -> #VALUE! | CU5: =(CS5-CR5)*1440 -> 1620 | CV5: =(CS5-CQ5)*1440 -> #VALUE! | CW5: =CT5/CV5 -> #VALUE!
A6: =[4]SayfaKAY!C620 -> KAY5+6 | B6: =[4]SayfaKAY!D620 -> 3873(2) | C6: =[4]SayfaKAY!E620 -> MA | D6: =[4]SayfaKAY!F620 -> 150 | E6: =[4]SayfaKAY!G620 -> BOZ-KAY5+6-FF-616 | F6: =IF(H6="","",INT(H6)) | G6: =IF(H6="","",MOD(H6,1)) | H6: =[4]SayfaKAY!H620 | I6: =[4]SayfaKAY!I620 -> Hat/Line | J6: =IF([4]SayfaKAY!J620="","",IF([4]SayfaKAY!J620="Müşteri","Notified by Customer","Notified by Bozankaya")) -> Notified by Customer | K6: =VLOOKUP([4]SayfaKAY!L620,#REF!,2,FALSE) -> #REF! | L6: =[4]SayfaKAY!X620 -> FATİH OTOMOTIV SAN TIC LTD STI | M6: =IF( E6="", "", A6&"-"&E6) -> KAY5+6-BOZ-KAY5+6-FF-616 | N6: =[4]SayfaKAY!M620 -> CA KABİN KORNA HAVA KAÇIRIYOR YETERSİZ | O6: =[4]SayfaKAY!P620 -> D-Arıza değil | P6: =[4]SayfaKAY!Q620 -> B(Servisten çekmeye etki eden arıza) | Q6: =[4]SayfaKAY!R620 -> N.A(Yaralanma yok) | R6: {=IF([4]SayfaKAY!U620="","",_xlfn.IFS([4]SayfaKAY!U620="Bozankaya","Bozankaya",[4]SayfaKAY!U620="Müşteri","Customer",[4]SayfaKAY!U620="Tedarikçi","Equipment Supplier"))} -> Equipment Supplier | S6: =[4]SayfaKAY!N620 -> KORNA DEĞİŞİMİ YAPILDI | T6: =[4]SayfaKAY!AD620 -> Ekipman yenisi ile değiştirildi | U6: =[4]SayfaKAY!W620 -> Evet | V6: =[4]SayfaKAY!AZ620 -> 1 | W6: =IF(Y6="","",INT(Y6)) -> 45785 | X6: =IF(Y6="","",TEXT(Y6,"ss:dd")) -> 06:00 | Y6: =[4]SayfaKAY!AE620 -> 45785.25 | Z6: =IF(AB6="","",INT(AB6)) -> 45786 | AA6: =IF(AB6="","",TEXT(AB6,"ss:dd")) -> 07:00 | AB6: =[4]SayfaKAY!BA620 -> 45786.292 | AC6: =IF(AF6="","",(AF6-H6)*24*60) -> #VALUE! | AD6: =IF(AF6="","",INT(AF6)) -> 45786 | AE6: =IF(AF6="","",TEXT(AF6,"ss:dd")) -> 07:00 | AF6: =[4]SayfaKAY!BA620 -> 45786.292 | AG6: =[4]SayfaKAY!S620 -> (III) Farklı Araçlarda Tekrarlayan Arıza | AH6: =IF(P6="A(Hareket etmeyi engelleyen arıza)","Bu Arıza Aracın Servise Verilmesine Engel", IF(P6="B(Servisten çekmeye etki eden arıza)","Bu Arıza Aracın Servise Verilmesine Engel", IF(P6="C(Sisteme etki etmeyen arıza)","Bu Arıza Aracın Servise Verilmesine Engel Değil", IF(P6="D(Arıza Değil)","Bu Arıza Aracın Servise Verilmesine Engel Değil", "")))) -> Bu Arıza Aracın Servise Verilmesine Engel | AI6: =[4]SayfaKAY!AV620 | AJ6: =IF(AL6="","",INT(AL6)) | AK6: =IF(AL6="","",TEXT(AL6,"ss:dd")) | AL6: =[4]SayfaKAY!AX620 | AM6: {=IFERROR(IF(AND(P6<>"D(Arıza Değil)",AH6="Bu Arıza Aracın Servise Verilmesine Engel Değil"), IF(Z6-F6>0,(AB6-Y6)*24*60, IF(OR(AND(G6>$AS$1,G6<$AT$1),AND(G6>$AU$1,G6<$AV$1)), (AF6-H6)*24*60, BH:BH0)), AN6),0)} -> 0 | AN6: =IFERROR(IF(P6<>"D(Arıza Değil)",AC6,0),0) -> 0 | AO6: =[4]SayfaKAY!AG620 | AP6: =[4]SayfaKAY!AI620 | AQ6: =[4]SayfaKAY!AQ620 | AR6: =[4]SayfaKAY!AH620 | AS6: =[4]SayfaKAY!AJ620 | AT6: =[4]SayfaKAY!AM620 | AU6: =[4]SayfaKAY!AL620 | AV6: =[4]SayfaKAY!AP620 | AW6: =[4]SayfaKAY!AT620 | AX6: =IF(V6="","",V6*AC6*BC$1) -> #VALUE! | BB6: =IF($AQ$1="X", IF(AND(G6>=$AS$1,G6<=$AT$1),IF(P6<>"D(Arıza Değil)",AC6,0), IF(AND(G6>=$AU$1,G6<=$AV$1),IF(P6<>"D(Arıza Değil)",AC6,0), "")), "") | BH6: =IFERROR(FRACAS!AN623, "Hata Var") -> 1109 | BK6: =[4]SayfaKAY!AW620 | BL6: =[4]SayfaKAY!V620 -> Bozankaya | BN6: =IF($AQ$1="X", IF(AND(G6>=$AS$1,G6<=$AT$1),IF(P6<>"D(Arıza Değil",AC6,0),IF(AND(G6>=$AU$1,G6<=$AV$1),IF(P6<>"D:Arıza Değil",AC6,0), "x var")), "x yok") -> x yok | BO6: =IF(OR(AND(G6>$AS$1,G6<$AT$1),AND(G6>$AU$1,G6<$AV$1)),"aynı gün giderilen arıza") -> FALSE | BP6: =IF(Z6-F6>0,"Bir günden fazla süren arıza",IF(OR(AND(G6>$AS$1,G6<$AT$1),AND(G6>$AU$1,G6<$AV$1)),"aynı gün giderilen arıza")) -> #VALUE! | BQ6: =(Y6-H6)*24*60 -> #VALUE! | BR6: =(AB6-Y6)*24*60 -> 1500 | BS6: =(AF6-H6)*24*60 -> #VALUE! | BV6: =COUNTIFS(B$5:B$9980,B6,H$5:H$9980,"<="&AF6,AF$5:AF$9980,">="&H6)-1 -> -1 | BW6: =IF(COUNTIFS(B$5:B$9980,B6,H$5:H$9980,"<="&AF6,AF$5:AF$9980,">="&H6)>1,"Evet, çakışma var","Hayır, çakışma yok") -> Hayır, çakışma yok | BY6: =Y6-H6 -> #VALUE! | BZ6: =AB6-Y6 -> 1.0416667 | CA6: =AB6-H6 -> #VALUE! | CE6: 619 | CF6: =H6 | CG6: =AB6 -> 45786.292 | CK6: =AB6-Y6 -> 1.0416667 | CL6: =Y6-H6 -> #VALUE! | CM6: =AB6-H6 -> #VALUE! | CO6: =AC6 -> #VALUE! | CP6: =CU6/24 -> 62.5 | CQ6: =G6 | CR6: =Y6 -> 45785.25 | CS6: =AB6 -> 45786.292 | CT6: =(CR6-CQ6)*1440 -> #VALUE! | CU6: =(CS6-CR6)*1440 -> 1500 | CV6: =(CS6-CQ6)*1440 -> #VALUE! | CW6: =CT6/CV6 -> #VALUE!
A7: =[4]SayfaKAY!C622 -> KAY5+6 | B7: =[4]SayfaKAY!D622 -> 3872(1) | C7: =[4]SayfaKAY!E622 -> MA | D7: =[4]SayfaKAY!F622 -> 128 | E7: =[4]SayfaKAY!G622 -> BOZ-KAY5+6-FF-617 | F7: =IF(H7="","",INT(H7)) | G7: =IF(H7="","",MOD(H7,1)) | H7: =[4]SayfaKAY!H622 | I7: =[4]SayfaKAY!I622 -> Hat/Line | J7: =IF([4]SayfaKAY!J622="","",IF([4]SayfaKAY!J622="Müşteri","Notified by Customer","Notified by Bozankaya")) -> Notified by Customer | K7: =VLOOKUP([4]SayfaKAY!L622,#REF!,2,FALSE) -> #REF! | L7: =[4]SayfaKAY!X622 -> GREBO OTOMOTİV SANAYİ A.Ş | M7: =IF( E7="", "", A7&"-"&E7) -> KAY5+6-BOZ-KAY5+6-FF-617 | N7: =[4]SayfaKAY!M622 -> 3872 NOLU ARAÇ KABİN CA KAPI İÇERDEN KİLİTLENMİYOR | O7: =[4]SayfaKAY!P622 -> D-Arıza değil | P7: =[4]SayfaKAY!Q622 -> C(Sisteme etki etmeyen arıza) | Q7: =[4]SayfaKAY!R622 -> N.A(Yaralanma yok) | R7: {=IF([4]SayfaKAY!U622="","",_xlfn.IFS([4]SayfaKAY!U622="Bozankaya","Bozankaya",[4]SayfaKAY!U622="Müşteri","Customer",[4]SayfaKAY!U622="Tedarikçi","Equipment Supplier"))} -> Equipment Supplier | S7: =[4]SayfaKAY!N622 -> İÇERDEN KİLİTLEME BRAKET DEĞİŞİMİ VE ONARIMI YAPILDI | T7: =[4]SayfaKAY!AD622 -> Gevşek bağlantı vidaları sıkıldı | U7: =[4]SayfaKAY!W622 | V7: =[4]SayfaKAY!AZ622 | W7: =IF(Y7="","",INT(Y7)) -> 45784 | X7: =IF(Y7="","",TEXT(Y7,"ss:dd")) -> 09:39 | Y7: =[4]SayfaKAY!AE622 -> 45784.402 | Z7: =IF(AB7="","",INT(AB7)) -> 45786 | AA7: =IF(AB7="","",TEXT(AB7,"ss:dd")) -> 12:00 | AB7: =[4]SayfaKAY!BA622 -> 45786.5 | AC7: =IF(AF7="","",(AF7-H7)*24*60) -> #VALUE! | AD7: =IF(AF7="","",INT(AF7)) -> 45786 | AE7: =IF(AF7="","",TEXT(AF7,"ss:dd")) -> 12:00 | AF7: =[4]SayfaKAY!BA622 -> 45786.5 | AG7: =[4]SayfaKAY!S622 -> (III) Farklı Araçlarda Tekrarlayan Arıza | AH7: =IF(P7="A(Hareket etmeyi engelleyen arıza)","Bu Arıza Aracın Servise Verilmesine Engel", IF(P7="B(Servisten çekmeye etki eden arıza)","Bu Arıza Aracın Servise Verilmesine Engel", IF(P7="C(Sisteme etki etmeyen arıza)","Bu Arıza Aracın Servise Verilmesine Engel Değil", IF(P7="D(Arıza Değil)","Bu Arıza Aracın Servise Verilmesine Engel Değil", "")))) -> Bu Arıza Aracın Servise Verilmesine Engel Değil | AI7: =[4]SayfaKAY!AV622 | AJ7: =IF(AL7="","",INT(AL7)) | AK7: =IF(AL7="","",TEXT(AL7,"ss:dd")) | AL7: =[4]SayfaKAY!AX622 | AM7: {=IFERROR(IF(AND(P7<>"D(Arıza Değil)",AH7="Bu Arıza Aracın Servise Verilmesine Engel Değil"), IF(Z7-F7>0,(AB7-Y7)*24*60, IF(OR(AND(G7>$AS$1,G7<$AT$1),AND(G7>$AU$1,G7<$AV$1)), (AF7-H7)*24*60, BH:BH0)), AN7),0)} -> 0 | AN7: =IFERROR(IF(P7<>"D(Arıza Değil)",AC7,0),0) -> 0 | AO7: =[4]SayfaKAY!AG622 -> GREBO OTOMOTİV SANAYİ A.Ş | AP7: =[4]SayfaKAY!AI622 -> T110-7469 | AQ7: =[4]SayfaKAY!AQ622 | AR7: =[4]SayfaKAY!AH622 -> SÜRÜCÜ KAPI KARKASI | AS7: =[4]SayfaKAY!AJ622 | AT7: =[4]SayfaKAY!AM622 | AU7: =[4]SayfaKAY!AL622 | AV7: =[4]SayfaKAY!AP622 | AW7: =[4]SayfaKAY!AT622 | AX7: =IF(V7="","",V7*AC7*BC$1) | BB7: =IF($AQ$1="X", IF(AND(G7>=$AS$1,G7<=$AT$1),IF(P7<>"D(Arıza Değil)",AC7,0), IF(AND(G7>=$AU$1,G7<=$AV$1),IF(P7<>"D(Arıza Değil)",AC7,0), "")), "") | BH7: =IFERROR(FRACAS!AN625, "Hata Var") -> 150 | BK7: =[4]SayfaKAY!AW622 | BL7: =[4]SayfaKAY!V622 -> Bozankaya | BN7: =IF($AQ$1="X", IF(AND(G7>=$AS$1,G7<=$AT$1),IF(P7<>"D(Arıza Değil",AC7,0),IF(AND(G7>=$AU$1,G7<=$AV$1),IF(P7<>"D:Arıza Değil",AC7,0), "x var")), "x yok") -> x yok | BO7: =IF(OR(AND(G7>$AS$1,G7<$AT$1),AND(G7>$AU$1,G7<$AV$1)),"aynı gün giderilen arıza") -> FALSE | BP7: =IF(Z7-F7>0,"Bir günden fazla süren arıza",IF(OR(AND(G7>$AS$1,G7<$AT$1),AND(G7>$AU$1,G7<$AV$1)),"aynı gün giderilen arıza")) -> #VALUE! | BQ7: =(Y7-H7)*24*60 -> #VALUE! | BR7: =(AB7-Y7)*24*60 -> 3021 | BS7: =(AF7-H7)*24*60 -> #VALUE! | BV7: =COUNTIFS(B$5:B$9980,B7,H$5:H$9980,"<="&AF7,AF$5:AF$9980,">="&H7)-1 -> -1 | BW7: =IF(COUNTIFS(B$5:B$9980,B7,H$5:H$9980,"<="&AF7,AF$5:AF$9980,">="&H7)>1,"Evet, çakışma var","Hayır, çakışma yok") -> Hayır, çakışma yok | BY7: =Y7-H7 -> #VALUE! | BZ7: =AB7-Y7 -> 2.0979167 | CA7: =AB7-H7 -> #VALUE! | CE7: 621 | CF7: =H7 | CG7: =AB7 -> 45786.5 | CK7: =AB7-Y7 -> 2.0979167 | CL7: =Y7-H7 -> #VALUE! | CM7: =AB7-H7 -> #VALUE! | CO7: =AC7 -> #VALUE! | CP7: =CU7/24 -> 125.875 | CQ7: =G7 | CR7: =Y7 -> 45784.402 | CS7: =AB7 -> 45786.5 | CT7: =(CR7-CQ7)*1440 -> #VALUE! | CU7: =(CS7-CR7)*1440 -> 3021 | CV7: =(CS7-CQ7)*1440 -> #VALUE! | CW7: =CT7/CV7 -> #VALUE!
A8: =[4]SayfaKAY!C624 -> KAY5+6 | B8: =[4]SayfaKAY!D624 -> 3879(8) | C8: =[4]SayfaKAY!E624 -> MB | D8: =[4]SayfaKAY!F624 -> 103.5 | E8: =[4]SayfaKAY!G624 -> BOZ-KAY5+6-FF-618 | F8: =IF(H8="","",INT(H8)) | G8: =IF(H8="","",MOD(H8,1)) | H8: =[4]SayfaKAY!H624 | I8: =[4]SayfaKAY!I624 -> Hat/Line | J8: =IF([4]SayfaKAY!J624="","",IF([4]SayfaKAY!J624="Müşteri","Notified by Customer","Notified by Bozankaya")) -> Notified by Customer | K8: =VLOOKUP([4]SayfaKAY!L624,#REF!,2,FALSE) -> #REF! | L8: =[4]SayfaKAY!X624 -> KNORR-BREMSE GMBH DİVİSİON IFE AUTO | M8: =IF( E8="", "", A8&"-"&E8) -> KAY5+6-BOZ-KAY5+6-FF-618 | N8: =[4]SayfaKAY!M624 -> 12 NUMARALI KAPI KAPANMADIĞI İÇİN İZOLE EDİLDİ | O8: =[4]SayfaKAY!P624 -> B-Hız veya güç azalması | P8: =[4]SayfaKAY!Q624 -> B(Servisten çekmeye etki eden arıza) | Q8: =[4]SayfaKAY!R624 -> N.A(Yaralanma yok) | R8: {=IF([4]SayfaKAY!U624="","",_xlfn.IFS([4]SayfaKAY!U624="Bozankaya","Bozankaya",[4]SayfaKAY!U624="Müşteri","Customer",[4]SayfaKAY!U624="Tedarikçi","Equipment Supplier"))} -> Equipment Supplier | S8: =[4]SayfaKAY!N624 -> HASSAS KENAR KABLOSU ZEDELENMİŞ,LEHİMLENDİ | T8: =[4]SayfaKAY!AD624 -> Ekipman yenisi ile değiştirildi | U8: =[4]SayfaKAY!W624 | V8: =[4]SayfaKAY!AZ624 | W8: =IF(Y8="","",INT(Y8)) -> 45781 | X8: =IF(Y8="","",TEXT(Y8,"ss:dd")) -> 04:25 | Y8: =[4]SayfaKAY!AE624 -> 45781.184 | Z8: =IF(AB8="","",INT(AB8)) -> 45782 | AA8: =IF(AB8="","",TEXT(AB8,"ss:dd")) -> 06:38 | AB8: =[4]SayfaKAY!BA624 -> 45782.276 | AC8: =IF(AF8="","",(AF8-H8)*24*60) -> #VALUE! | AD8: =IF(AF8="","",INT(AF8)) -> 45782 | AE8: =IF(AF8="","",TEXT(AF8,"ss:dd")) -> 06:38 | AF8: =[4]SayfaKAY!BA624 -> 45782.276 | AG8: =[4]SayfaKAY!S624 -> (III) Farklı Araçlarda Tekrarlayan Arıza | AH8: =IF(P8="A(Hareket etmeyi engelleyen arıza)","Bu Arıza Aracın Servise Verilmesine Engel", IF(P8="B(Servisten çekmeye etki eden arıza)","Bu Arıza Aracın Servise Verilmesine Engel", IF(P8="C(Sisteme etki etmeyen arıza)","Bu Arıza Aracın Servise Verilmesine Engel Değil", IF(P8="D(Arıza Değil)","Bu Arıza Aracın Servise Verilmesine Engel Değil", "")))) -> Bu Arıza Aracın Servise Verilmesine Engel | AI8: =[4]SayfaKAY!AV624 | AJ8: =IF(AL8="","",INT(AL8)) | AK8: =IF(AL8="","",TEXT(AL8,"ss:dd")) | AL8: =[4]SayfaKAY!AX624 | AM8: {=IFERROR(IF(AND(P8<>"D(Arıza Değil)",AH8="Bu Arıza Aracın Servise Verilmesine Engel Değil"), IF(Z8-F8>0,(AB8-Y8)*24*60, IF(OR(AND(G8>$AS$1,G8<$AT$1),AND(G8>$AU$1,G8<$AV$1)), (AF8-H8)*24*60, BH:BH0)), AN8),0)} -> 0 | AN8: =IFERROR(IF(P8<>"D(Arıza Değil)",AC8,0),0) -> 0 | AO8: =[4]SayfaKAY!AG624 | AP8: =[4]SayfaKAY!AI624 | AQ8: =[4]SayfaKAY!AQ624 | AR8: =[4]SayfaKAY!AH624 | AS8: =[4]SayfaKAY!AJ624 | AT8: =[4]SayfaKAY!AM624 | AU8: =[4]SayfaKAY!AL624 | AV8: =[4]SayfaKAY!AP624 | AW8: =[4]SayfaKAY!AT624 | AX8: =IF(V8="","",V8*AC8*BC$1) | BB8: =IF($AQ$1="X", IF(AND(G8>=$AS$1,G8<=$AT$1),IF(P8<>"D(Arıza Değil)",AC8,0), IF(AND(G8>=$AU$1,G8<=$AV$1),IF(P8<>"D(Arıza Değil)",AC8,0), "")), "") | BH8: =IFERROR(FRACAS!AN627, "Hata Var") -> 240 | BK8: =[4]SayfaKAY!AW624 | BL8: =[4]SayfaKAY!V624 -> KNORR-BREMSE GMBH DİVİSİON IFE AUTO | BN8: =IF($AQ$1="X", IF(AND(G8>=$AS$1,G8<=$AT$1),IF(P8<>"D(Arıza Değil",AC8,0),IF(AND(G8>=$AU$1,G8<=$AV$1),IF(P8<>"D:Arıza Değil",AC8,0), "x var")), "x yok") -> x yok | BO8: =IF(OR(AND(G8>$AS$1,G8<$AT$1),AND(G8>$AU$1,G8<$AV$1)),"aynı gün giderilen arıza") -> FALSE | BP8: =IF(Z8-F8>0,"Bir günden fazla süren arıza",IF(OR(AND(G8>$AS$1,G8<$AT$1),AND(G8>$AU$1,G8<$AV$1)),"aynı gün giderilen arıza")) -> #VALUE! | BQ8: =(Y8-H8)*24*60 -> #VALUE! | BR8: =(AB8-Y8)*24*60 -> 1573 | BS8: =(AF8-H8)*24*60 -> #VALUE! | BV8: =COUNTIFS(B$5:B$9980,B8,H$5:H$9980,"<="&AF8,AF$5:AF$9980,">="&H8)-1 -> -1 | BW8: =IF(COUNTIFS(B$5:B$9980,B8,H$5:H$9980,"<="&AF8,AF$5:AF$9980,">="&H8)>1,"Evet, çakışma var","Hayır, çakışma yok") -> Hayır, çakışma yok | BY8: =Y8-H8 -> #VALUE! | BZ8: =AB8-Y8 -> 1.0923611 | CA8: =AB8-H8 -> #VALUE! | CE8: 623 | CF8: =H8 | CG8: =AB8 -> 45782.276 | CK8: =AB8-Y8 -> 1.0923611 | CL8: =Y8-H8 -> #VALUE! | CM8: =AB8-H8 -> #VALUE! | CO8: =AC8 -> #VALUE! | CP8: =CU8/24 -> 65.541667 | CQ8: =G8 | CR8: =Y8 -> 45781.184 | CS8: =AB8 -> 45782.276 | CT8: =(CR8-CQ8)*1440 -> #VALUE! | CU8: =(CS8-CR8)*1440 -> 1573 | CV8: =(CS8-CQ8)*1440 -> #VALUE! | CW8: =CT8/CV8 -> #VALUE!
A9: =[4]SayfaKAY!C692 -> KAY5+6 | B9: =[4]SayfaKAY!D692 -> 3874(3) | C9: =[4]SayfaKAY!E692 -> MB | D9: =[4]SayfaKAY!F692 -> 110620 | E9: =[4]SayfaKAY!G692 -> BOZ-KAY5+6-FF-679 | F9: =IF(H9="","",INT(H9)) | G9: =IF(H9="","",MOD(H9,1)) | H9: =[4]SayfaKAY!H692 | I9: =[4]SayfaKAY!I692 -> Hat/Line | J9: =IF([4]SayfaKAY!J692="","",IF([4]SayfaKAY!J692="Müşteri","Notified by Customer","Notified by Bozankaya")) -> Notified by Customer | K9: =VLOOKUP([4]SayfaKAY!L692,#REF!,2,FALSE) -> #REF! | L9: =[4]SayfaKAY!X692 -> ELTESAN ELEKTRO MEKANİK SOĞUTMA SAN | M9: =IF( E9="", "", A9&"-"&E9) -> KAY5+6-BOZ-KAY5+6-FF-679 | N9: =[4]SayfaKAY!M692 -> Kabin soğuk | O9: =[4]SayfaKAY!P692 -> C-Uyarı, sürüş devamlılığı | P9: =[4]SayfaKAY!Q692 -> B(Servisten çekmeye etki eden arıza) | Q9: =[4]SayfaKAY!R692 -> N.A(Yaralanma yok) | R9: {=IF([4]SayfaKAY!U692="","",_xlfn.IFS([4]SayfaKAY!U692="Bozankaya","Bozankaya",[4]SayfaKAY!U692="Müşteri","Customer",[4]SayfaKAY!U692="Tedarikçi","Equipment Supplier"))} -> Equipment Supplier | S9: =[4]SayfaKAY!N692 -> Sensör(kabin içi) modifikasyonu yapıldı | T9: =[4]SayfaKAY!AD692 -> Yazılım tekrar yüklendi | U9: =[4]SayfaKAY!W692 -> Evet | V9: =[4]SayfaKAY!AZ692 -> 2 | W9: =IF(Y9="","",INT(Y9)) -> 45628 | X9: =IF(Y9="","",TEXT(Y9,"ss:dd")) -> 05:00 | Y9: =[4]SayfaKAY!AE692 -> 45628.208 | Z9: =IF(AB9="","",INT(AB9)) -> 45629 | AA9: =IF(AB9="","",TEXT(AB9,"ss:dd")) -> 08:00 | AB9: =[4]SayfaKAY!BA692 -> 45629.333 | AC9: =IF(AF9="","",(AF9-H9)*24*60) -> #VALUE! | AD9: =IF(AF9="","",INT(AF9)) -> 45629 | AE9: =IF(AF9="","",TEXT(AF9,"ss:dd")) -> 08:00 | AF9: =[4]SayfaKAY!BA692 -> 45629.333 | AG9: =[4]SayfaKAY!S692 -> (III) Farklı Araçlarda Tekrarlayan Arıza | AH9: =IF(P9="A(Hareket etmeyi engelleyen arıza)","Bu Arıza Aracın Servise Verilmesine Engel", IF(P9="B(Servisten çekmeye etki eden arıza)","Bu Arıza Aracın Servise Verilmesine Engel", IF(P9="C(Sisteme etki etmeyen arıza)","Bu Arıza Aracın Servise Verilmesine Engel Değil", IF(P9="D(Arıza Değil)","Bu Arıza Aracın Servise Verilmesine Engel Değil", "")))) -> Bu Arıza Aracın Servise Verilmesine Engel | AI9: =[4]SayfaKAY!AV692 | AJ9: =IF(AL9="","",INT(AL9)) | AK9: =IF(AL9="","",TEXT(AL9,"ss:dd")) | AL9: =[4]SayfaKAY!AX692 | AM9: {=IFERROR(IF(AND(P9<>"D(Arıza Değil)",AH9="Bu Arıza Aracın Servise Verilmesine Engel Değil"), IF(Z9-F9>0,(AB9-Y9)*24*60, IF(OR(AND(G9>$AS$1,G9<$AT$1),AND(G9>$AU$1,G9<$AV$1)), (AF9-H9)*24*60, BH:BH0)), AN9),0)} -> 0 | AN9: =IFERROR(IF(P9<>"D(Arıza Değil)",AC9,0),0) -> 0 | AO9: =[4]SayfaKAY!AG692 | AP9: =[4]SayfaKAY!AI692 | AQ9: =[4]SayfaKAY!AQ692 | AR9: =[4]SayfaKAY!AH692 | AS9: =[4]SayfaKAY!AJ692 | AT9: =[4]SayfaKAY!AM692 | AU9: =[4]SayfaKAY!AL692 | AV9: =[4]SayfaKAY!AP692 | AW9: =[4]SayfaKAY!AT692 | AX9: =IF(V9="","",V9*AC9*BC$1) -> #VALUE! | BB9: =IF($AQ$1="X", IF(AND(G9>=$AS$1,G9<=$AT$1),IF(P9<>"D(Arıza Değil)",AC9,0), IF(AND(G9>=$AU$1,G9<=$AV$1),IF(P9<>"D(Arıza Değil)",AC9,0), "")), "") | BH9: =IFERROR(FRACAS!AN695, "Hata Var") -> 1485 | BK9: =[4]SayfaKAY!AW692 | BL9: =[4]SayfaKAY!V692 -> ELTESAN ELEKTRO MEKANİK SOĞUTMA SAN | BN9: =IF($AQ$1="X", IF(AND(G9>=$AS$1,G9<=$AT$1),IF(P9<>"D(Arıza Değil",AC9,0),IF(AND(G9>=$AU$1,G9<=$AV$1),IF(P9<>"D:Arıza Değil",AC9,0), "x var")), "x yok") -> x yok | BO9: =IF(OR(AND(G9>$AS$1,G9<$AT$1),AND(G9>$AU$1,G9<$AV$1)),"aynı gün giderilen arıza") -> FALSE | BP9: =IF(Z9-F9>0,"Bir günden fazla süren arıza",IF(OR(AND(G9>$AS$1,G9<$AT$1),AND(G9>$AU$1,G9<$AV$1)),"aynı gün giderilen arıza")) -> #VALUE! | BQ9: =(Y9-H9)*24*60 -> #VALUE! | BR9: =(AB9-Y9)*24*60 -> 1620 | BS9: =(AF9-H9)*24*60 -> #VALUE! | BV9: =COUNTIFS(B$5:B$9980,B9,H$5:H$9980,"<="&AF9,AF$5:AF$9980,">="&H9)-1 -> -1 | BW9: =IF(COUNTIFS(B$5:B$9980,B9,H$5:H$9980,"<="&AF9,AF$5:AF$9980,">="&H9)>1,"Evet, çakışma var","Hayır, çakışma yok") -> Hayır, çakışma yok | BY9: =Y9-H9 -> #VALUE! | BZ9: =AB9-Y9 -> 1.125 | CA9: =AB9-H9 -> #VALUE! | CE9: 691 | CF9: =H9 | CG9: =AB9 -> 45629.333 | CK9: =AB9-Y9 -> 1.125 | CL9: =Y9-H9 -> #VALUE! | CM9: =AB9-H9 -> #VALUE! | CO9: =AC9 -> #VALUE! | CP9: =CU9/24 -> 67.5 | CQ9: =G9 | CR9: =Y9 -> 45628.208 | CS9: =AB9 -> 45629.333 | CT9: =(CR9-CQ9)*1440 -> #VALUE! | CU9: =(CS9-CR9)*1440 -> 1620 | CV9: =(CS9-CQ9)*1440 -> #VALUE! | CW9: =CT9/CV9 -> #VALUE!
A10: =[4]SayfaKAY!C843 | B10: =[4]SayfaKAY!D843 | C10: =[4]SayfaKAY!E843 | D10: =[4]SayfaKAY!F843 | E10: =[4]SayfaKAY!G843 | F10: =IF(H10="","",INT(H10)) | G10: =IF(H10="","",MOD(H10,1)) | H10: =[4]SayfaKAY!H843 | I10: =[4]SayfaKAY!I843 | J10: =IF([4]SayfaKAY!J843="","",IF([4]SayfaKAY!J843="Müşteri","Notified by Customer","Notified by Bozankaya")) | K10: =VLOOKUP([4]SayfaKAY!L843,#REF!,2,FALSE) -> #REF! | L10: =[4]SayfaKAY!X843 | M10: =IF( E10="", "", A10&"-"&E10) | N10: =[4]SayfaKAY!M843 | O10: =[4]SayfaKAY!P843 | P10: =[4]SayfaKAY!Q843 | Q10: =[4]SayfaKAY!R843 | R10: {=IF([4]SayfaKAY!U843="","",_xlfn.IFS([4]SayfaKAY!U843="Bozankaya","Bozankaya",[4]SayfaKAY!U843="Müşteri","Customer",[4]SayfaKAY!U843="Tedarikçi","Equipment Supplier"))} | S10: =[4]SayfaKAY!N843 | T10: =[4]SayfaKAY!AD843 | U10: =[4]SayfaKAY!W843 | V10: =[4]SayfaKAY!AZ843 | W10: =IF(Y10="","",INT(Y10)) | X10: =IF(Y10="","",TEXT(Y10,"ss:dd")) | Y10: =[4]SayfaKAY!AE843 | Z10: =IF(AB10="","",INT(AB10)) | AA10: =IF(AB10="","",TEXT(AB10,"ss:dd")) | AB10: =[4]SayfaKAY!BA843 | AC10: =IF(AF10="","",(AF10-H10)*24*60) | AD10: =IF(AF10="","",INT(AF10)) | AE10: =IF(AF10="","",TEXT(AF10,"ss:dd")) | AF10: =[4]SayfaKAY!BA843 | AG10: =[4]SayfaKAY!S843 | AH10: =IF(P10="A(Hareket etmeyi engelleyen arıza)","Bu Arıza Aracın Servise Verilmesine Engel", IF(P10="B(Servisten çekmeye etki eden arıza)","Bu Arıza Aracın Servise Verilmesine Engel", IF(P10="C(Sisteme etki etmeyen arıza)","Bu Arıza Aracın Servise Verilmesine Engel Değil", IF(P10="D(Arıza Değil)","Bu Arıza Aracın Servise Verilmesine Engel Değil", "")))) | AI10: =[4]SayfaKAY!AV843 | AJ10: =IF(AL10="","",INT(AL10)) | AK10: =IF(AL10="","",TEXT(AL10,"ss:dd")) | AL10: =[4]SayfaKAY!AX843 | AM10: {=IFERROR(IF(AND(P10<>"D(Arıza Değil)",AH10="Bu Arıza Aracın Servise Verilmesine Engel Değil"), IF(Z10-F10>0,(AB10-Y10)*24*60, IF(OR(AND(G10>$AS$1,G10<$AT$1),AND(G10>$AU$1,G10<$AV$1)), (AF10-H10)*24*60, BH:BH0)), AN10),0)} | AN10: =IFERROR(IF(P10<>"D(Arıza Değil)",AC10,0),0) | AO10: =[4]SayfaKAY!AG843 | AP10: =[4]SayfaKAY!AI843 | AQ10: =[4]SayfaKAY!AQ843 | AR10: =[4]SayfaKAY!AH843 | AS10: =[4]SayfaKAY!AJ843 | AT10: =[4]SayfaKAY!AM843 | AU10: =[4]SayfaKAY!AL843 | AV10: =[4]SayfaKAY!AP843 | AW10: =[4]SayfaKAY!AT843 | AX10: =IF(V10="","",V10*AC10*BC$1) | BB10: =IF($AQ$1="X", IF(AND(G10>=$AS$1,G10<=$AT$1),IF(P10<>"D(Arıza Değil)",AC10,0), IF(AND(G10>=$AU$1,G10<=$AV$1),IF(P10<>"D(Arıza Değil)",AC10,0), "")), "") | BH10: =IFERROR(FRACAS!AN846, "Hata Var") -> 91 | BK10: =[4]SayfaKAY!AW843 | BL10: =[4]SayfaKAY!V843 | BN10: =IF($AQ$1="X", IF(AND(G10>=$AS$1,G10<=$AT$1),IF(P10<>"D(Arıza Değil",AC10,0),IF(AND(G10>=$AU$1,G10<=$AV$1),IF(P10<>"D:Arıza Değil",AC10,0), "x var")), "x yok") -> x yok | BO10: =IF(OR(AND(G10>$AS$1,G10<$AT$1),AND(G10>$AU$1,G10<$AV$1)),"aynı gün giderilen arıza") -> FALSE | BP10: =IF(Z10-F10>0,"Bir günden fazla süren arıza",IF(OR(AND(G10>$AS$1,G10<$AT$1),AND(G10>$AU$1,G10<$AV$1)),"aynı gün giderilen arıza")) -> #VALUE! | BQ10: =(Y10-H10)*24*60 -> #VALUE! | BR10: =(AB10-Y10)*24*60 -> #VALUE! | BS10: =(AF10-H10)*24*60 -> #VALUE! | BV10: =COUNTIFS(B$5:B$9980,B10,H$5:H$9980,"<="&AF10,AF$5:AF$9980,">="&H10)-1 -> -1 | BW10: =IF(COUNTIFS(B$5:B$9980,B10,H$5:H$9980,"<="&AF10,AF$5:AF$9980,">="&H10)>1,"Evet, çakışma var","Hayır, çakışma yok") -> Hayır, çakışma yok | BY10: =Y10-H10 -> #VALUE! | BZ10: =AB10-Y10 -> #VALUE! | CA10: =AB10-H10 -> #VALUE! | CE10: 842 | CF10: =H10 | CG10: =AB10 | CK10: =AB10-Y10 -> #VALUE! | CL10: =Y10-H10 -> #VALUE! | CM10: =AB10-H10 -> #VALUE! | CO10: =AC10 | CP10: =CU10/24 -> #VALUE! | CQ10: =G10 | CR10: =Y10 | CS10: =AB10 | CT10: =(CR10-CQ10)*1440 -> #VALUE! | CU10: =(CS10-CR10)*1440 -> #VALUE! | CV10: =(CS10-CQ10)*1440 -> #VALUE! | CW10: =CT10/CV10 -> #VALUE!
A11: =[4]SayfaKAY!C844 | B11: =[4]SayfaKAY!D844 | C11: =[4]SayfaKAY!E844 | D11: =[4]SayfaKAY!F844 | E11: =[4]SayfaKAY!G844 | F11: =IF(H11="","",INT(H11)) | G11: =IF(H11="","",MOD(H11,1)) | H11: =[4]SayfaKAY!H844 | I11: =[4]SayfaKAY!I844 | J11: =IF([4]SayfaKAY!J844="","",IF([4]SayfaKAY!J844="Müşteri","Notified by Customer","Notified by Bozankaya")) | K11: =VLOOKUP([4]SayfaKAY!L844,#REF!,2,FALSE) -> #REF! | L11: =[4]SayfaKAY!X844 | M11: =IF( E11="", "", A11&"-"&E11) | N11: =[4]SayfaKAY!M844 | O11: =[4]SayfaKAY!P844 | P11: =[4]SayfaKAY!Q844 | Q11: =[4]SayfaKAY!R844 | R11: {=IF([4]SayfaKAY!U844="","",_xlfn.IFS([4]SayfaKAY!U844="Bozankaya","Bozankaya",[4]SayfaKAY!U844="Müşteri","Customer",[4]SayfaKAY!U844="Tedarikçi","Equipment Supplier"))} | S11: =[4]SayfaKAY!N844 | T11: =[4]SayfaKAY!AD844 | U11: =[4]SayfaKAY!W844 | V11: =[4]SayfaKAY!AZ844 | W11: =IF(Y11="","",INT(Y11)) | X11: =IF(Y11="","",TEXT(Y11,"ss:dd")) | Y11: =[4]SayfaKAY!AE844 | Z11: =IF(AB11="","",INT(AB11)) | AA11: =IF(AB11="","",TEXT(AB11,"ss:dd")) | AB11: =[4]SayfaKAY!BA844 | AC11: =IF(AF11="","",(AF11-H11)*24*60) | AD11: =IF(AF11="","",INT(AF11)) | AE11: =IF(AF11="","",TEXT(AF11,"ss:dd")) | AF11: =[4]SayfaKAY!BA844 | AG11: =[4]SayfaKAY!S844 | AH11: =IF(P11="A(Hareket etmeyi engelleyen arıza)","Bu Arıza Aracın Servise Verilmesine Engel", IF(P11="B(Servisten çekmeye etki eden arıza)","Bu Arıza Aracın Servise Verilmesine Engel", IF(P11="C(Sisteme etki etmeyen arıza)","Bu Arıza Aracın Servise Verilmesine Engel Değil", IF(P11="D(Arıza Değil)","Bu Arıza Aracın Servise Verilmesine Engel Değil", "")))) | AI11: =[4]SayfaKAY!AV844 | AJ11: =IF(AL11="","",INT(AL11)) | AK11: =IF(AL11="","",TEXT(AL11,"ss:dd")) | AL11: =[4]SayfaKAY!AX844 | AM11: {=IFERROR(IF(AND(P11<>"D(Arıza Değil)",AH11="Bu Arıza Aracın Servise Verilmesine Engel Değil"), IF(Z11-F11>0,(AB11-Y11)*24*60, IF(OR(AND(G11>$AS$1,G11<$AT$1),AND(G11>$AU$1,G11<$AV$1)), (AF11-H11)*24*60, BH:BH0)), AN11),0)} | AN11: =IFERROR(IF(P11<>"D(Arıza Değil)",AC11,0),0) | AO11: =[4]SayfaKAY!AG844 | AP11: =[4]SayfaKAY!AI844 | AQ11: =[4]SayfaKAY!AQ844 | AR11: =[4]SayfaKAY!AH844 | AS11: =[4]SayfaKAY!AJ844 | AT11: =[4]SayfaKAY!AM844 | AU11: =[4]SayfaKAY!AL844 | AV11: =[4]SayfaKAY!AP844 | AW11: =[4]SayfaKAY!AT844 | AX11: =IF(V11="","",V11*AC11*BC$1) | BB11: =IF($AQ$1="X", IF(AND(G11>=$AS$1,G11<=$AT$1),IF(P11<>"D(Arıza Değil)",AC11,0), IF(AND(G11>=$AU$1,G11<=$AV$1),IF(P11<>"D(Arıza Değil)",AC11,0), "")), "") | BH11: =IFERROR(FRACAS!AN847, "Hata Var") -> 676 | BK11: =[4]SayfaKAY!AW844 | BL11: =[4]SayfaKAY!V844 | BN11: =IF($AQ$1="X", IF(AND(G11>=$AS$1,G11<=$AT$1),IF(P11<>"D(Arıza Değil",AC11,0),IF(AND(G11>=$AU$1,G11<=$AV$1),IF(P11<>"D:Arıza Değil",AC11,0), "x var")), "x yok") -> x yok | BO11: =IF(OR(AND(G11>$AS$1,G11<$AT$1),AND(G11>$AU$1,G11<$AV$1)),"aynı gün giderilen arıza") -> FALSE | BP11: =IF(Z11-F11>0,"Bir günden fazla süren arıza",IF(OR(AND(G11>$AS$1,G11<$AT$1),AND(G11>$AU$1,G11<$AV$1)),"aynı gün giderilen arıza")) -> #VALUE! | BQ11: =(Y11-H11)*24*60 -> #VALUE! | BR11: =(AB11-Y11)*24*60 -> #VALUE! | BS11: =(AF11-H11)*24*60 -> #VALUE! | BV11: =COUNTIFS(B$5:B$9980,B11,H$5:H$9980,"<="&AF11,AF$5:AF$9980,">="&H11)-1 -> -1 | BW11: =IF(COUNTIFS(B$5:B$9980,B11,H$5:H$9980,"<="&AF11,AF$5:AF$9980,">="&H11)>1,"Evet, çakışma var","Hayır, çakışma yok") -> Hayır, çakışma yok | BY11: =Y11-H11 -> #VALUE! | BZ11: =AB11-Y11 -> #VALUE! | CA11: =AB11-H11 -> #VALUE! | CE11: 843 | CF11: =H11 | CG11: =AB11 | CK11: =AB11-Y11 -> #VALUE! | CL11: =Y11-H11 -> #VALUE! | CM11: =AB11-H11 -> #VALUE! | CO11: =AC11 | CP11: =CU11/24 -> #VALUE! | CQ11: =G11 | CR11: =Y11 | CS11: =AB11 | CT11: =(CR11-CQ11)*1440 -> #VALUE! | CU11: =(CS11-CR11)*1440 -> #VALUE! | CV11: =(CS11-CQ11)*1440 -> #VALUE! | CW11: =CT11/CV11 -> #VALUE!
A12: =[4]SayfaKAY!C845 | B12: =[4]SayfaKAY!D845 | C12: =[4]SayfaKAY!E845 | D12: =[4]SayfaKAY!F845 | E12: =[4]SayfaKAY!G845 | F12: =IF(H12="","",INT(H12)) | G12: =IF(H12="","",MOD(H12,1)) | H12: =[4]SayfaKAY!H845 | I12: =[4]SayfaKAY!I845 | J12: =IF([4]SayfaKAY!J845="","",IF([4]SayfaKAY!J845="Müşteri","Notified by Customer","Notified by Bozankaya")) | K12: =VLOOKUP([4]SayfaKAY!L845,#REF!,2,FALSE) -> #REF! | L12: =[4]SayfaKAY!X845 | M12: =IF( E12="", "", A12&"-"&E12) | N12: =[4]SayfaKAY!M845 | O12: =[4]SayfaKAY!P845 | P12: =[4]SayfaKAY!Q845 | Q12: =[4]SayfaKAY!R845 | R12: {=IF([4]SayfaKAY!U845="","",_xlfn.IFS([4]SayfaKAY!U845="Bozankaya","Bozankaya",[4]SayfaKAY!U845="Müşteri","Customer",[4]SayfaKAY!U845="Tedarikçi","Equipment Supplier"))} | S12: =[4]SayfaKAY!N845 | T12: =[4]SayfaKAY!AD845 | U12: =[4]SayfaKAY!W845 | V12: =[4]SayfaKAY!AZ845 | W12: =IF(Y12="","",INT(Y12)) | X12: =IF(Y12="","",TEXT(Y12,"ss:dd")) | Y12: =[4]SayfaKAY!AE845 | Z12: =IF(AB12="","",INT(AB12)) | AA12: =IF(AB12="","",TEXT(AB12,"ss:dd")) | AB12: =[4]SayfaKAY!BA845 | AC12: =IF(AF12="","",(AF12-H12)*24*60) | AD12: =IF(AF12="","",INT(AF12)) | AE12: =IF(AF12="","",TEXT(AF12,"ss:dd")) | AF12: =[4]SayfaKAY!BA845 | AG12: =[4]SayfaKAY!S845 | AH12: =IF(P12="A(Hareket etmeyi engelleyen arıza)","Bu Arıza Aracın Servise Verilmesine Engel", IF(P12="B(Servisten çekmeye etki eden arıza)","Bu Arıza Aracın Servise Verilmesine Engel", IF(P12="C(Sisteme etki etmeyen arıza)","Bu Arıza Aracın Servise Verilmesine Engel Değil", IF(P12="D(Arıza Değil)","Bu Arıza Aracın Servise Verilmesine Engel Değil", "")))) | AI12: =[4]SayfaKAY!AV845 | AJ12: =IF(AL12="","",INT(AL12)) | AK12: =IF(AL12="","",TEXT(AL12,"ss:dd")) | AL12: =[4]SayfaKAY!AX845 | AM12: {=IFERROR(IF(AND(P12<>"D(Arıza Değil)",AH12="Bu Arıza Aracın Servise Verilmesine Engel Değil"), IF(Z12-F12>0,(AB12-Y12)*24*60, IF(OR(AND(G12>$AS$1,G12<$AT$1),AND(G12>$AU$1,G12<$AV$1)), (AF12-H12)*24*60, BH:BH0)), AN12),0)} | AN12: =IFERROR(IF(P12<>"D(Arıza Değil)",AC12,0),0) | AO12: =[4]SayfaKAY!AG845 | AP12: =[4]SayfaKAY!AI845 | AQ12: =[4]SayfaKAY!AQ845 | AR12: =[4]SayfaKAY!AH845 | AS12: =[4]SayfaKAY!AJ845 | AT12: =[4]SayfaKAY!AM845 | AU12: =[4]SayfaKAY!AL845 | AV12: =[4]SayfaKAY!AP845 | AW12: =[4]SayfaKAY!AT845 | AX12: =IF(V12="","",V12*AC12*BC$1) | BB12: =IF($AQ$1="X", IF(AND(G12>=$AS$1,G12<=$AT$1),IF(P12<>"D(Arıza Değil)",AC12,0), IF(AND(G12>=$AU$1,G12<=$AV$1),IF(P12<>"D(Arıza Değil)",AC12,0), "")), "") | BH12: =IFERROR(FRACAS!AN848, "Hata Var") -> 159.96667 | BK12: =[4]SayfaKAY!AW845 | BL12: =[4]SayfaKAY!V845 | BN12: =IF($AQ$1="X", IF(AND(G12>=$AS$1,G12<=$AT$1),IF(P12<>"D(Arıza Değil",AC12,0),IF(AND(G12>=$AU$1,G12<=$AV$1),IF(P12<>"D:Arıza Değil",AC12,0), "x var")), "x yok") -> x yok | BO12: =IF(OR(AND(G12>$AS$1,G12<$AT$1),AND(G12>$AU$1,G12<$AV$1)),"aynı gün giderilen arıza") -> FALSE | BP12: =IF(Z12-F12>0,"Bir günden fazla süren arıza",IF(OR(AND(G12>$AS$1,G12<$AT$1),AND(G12>$AU$1,G12<$AV$1)),"aynı gün giderilen arıza")) -> #VALUE! | BQ12: =(Y12-H12)*24*60 -> #VALUE! | BR12: =(AB12-Y12)*24*60 -> #VALUE! | BS12: =(AF12-H12)*24*60 -> #VALUE! | BV12: =COUNTIFS(B$5:B$9980,B12,H$5:H$9980,"<="&AF12,AF$5:AF$9980,">="&H12)-1 -> -1 | BW12: =IF(COUNTIFS(B$5:B$9980,B12,H$5:H$9980,"<="&AF12,AF$5:AF$9980,">="&H12)>1,"Evet, çakışma var","Hayır, çakışma yok") -> Hayır, çakışma yok | BY12: =Y12-H12 -> #VALUE! | BZ12: =AB12-Y12 -> #VALUE! | CA12: =AB12-H12 -> #VALUE! | CE12: 844 | CF12: =H12 | CG12: =AB12 | CK12: =AB12-Y12 -> #VALUE! | CL12: =Y12-H12 -> #VALUE! | CM12: =AB12-H12 -> #VALUE! | CO12: =AC12 | CP12: =CU12/24 -> #VALUE! | CQ12: =G12 | CR12: =Y12 | CS12: =AB12 | CT12: =(CR12-CQ12)*1440 -> #VALUE! | CU12: =(CS12-CR12)*1440 -> #VALUE! | CV12: =(CS12-CQ12)*1440 -> #VALUE! | CW12: =CT12/CV12 -> #VALUE!
A13: =[4]SayfaKAY!C846 | B13: =[4]SayfaKAY!D846 | C13: =[4]SayfaKAY!E846 | D13: =[4]SayfaKAY!F846 | E13: =[4]SayfaKAY!G846 | F13: =IF(H13="","",INT(H13)) | G13: =IF(H13="","",MOD(H13,1)) | H13: =[4]SayfaKAY!H846 | I13: =[4]SayfaKAY!I846 | J13: =IF([4]SayfaKAY!J846="","",IF([4]SayfaKAY!J846="Müşteri","Notified by Customer","Notified by Bozankaya")) | K13: =VLOOKUP([4]SayfaKAY!L846,#REF!,2,FALSE) -> #REF! | L13: =[4]SayfaKAY!X846 | M13: =IF( E13="", "", A13&"-"&E13) | N13: =[4]SayfaKAY!M846 | O13: =[4]SayfaKAY!P846 | P13: =[4]SayfaKAY!Q846 | Q13: =[4]SayfaKAY!R846 | R13: {=IF([4]SayfaKAY!U846="","",_xlfn.IFS([4]SayfaKAY!U846="Bozankaya","Bozankaya",[4]SayfaKAY!U846="Müşteri","Customer",[4]SayfaKAY!U846="Tedarikçi","Equipment Supplier"))} | S13: =[4]SayfaKAY!N846 | T13: =[4]SayfaKAY!AD846 | U13: =[4]SayfaKAY!W846 | V13: =[4]SayfaKAY!AZ846 | W13: =IF(Y13="","",INT(Y13)) | X13: =IF(Y13="","",TEXT(Y13,"ss:dd")) | Y13: =[4]SayfaKAY!AE846 | Z13: =IF(AB13="","",INT(AB13)) | AA13: =IF(AB13="","",TEXT(AB13,"ss:dd")) | AB13: =[4]SayfaKAY!BA846 | AC13: =IF(AF13="","",(AF13-H13)*24*60) | AD13: =IF(AF13="","",INT(AF13)) | AE13: =IF(AF13="","",TEXT(AF13,"ss:dd")) | AF13: =[4]SayfaKAY!BA846 | AG13: =[4]SayfaKAY!S846 | AH13: =IF(P13="A(Hareket etmeyi engelleyen arıza)","Bu Arıza Aracın Servise Verilmesine Engel", IF(P13="B(Servisten çekmeye etki eden arıza)","Bu Arıza Aracın Servise Verilmesine Engel", IF(P13="C(Sisteme etki etmeyen arıza)","Bu Arıza Aracın Servise Verilmesine Engel Değil", IF(P13="D(Arıza Değil)","Bu Arıza Aracın Servise Verilmesine Engel Değil", "")))) | AI13: =[4]SayfaKAY!AV846 | AJ13: =IF(AL13="","",INT(AL13)) | AK13: =IF(AL13="","",TEXT(AL13,"ss:dd")) | AL13: =[4]SayfaKAY!AX846 | AM13: {=IFERROR(IF(AND(P13<>"D(Arıza Değil)",AH13="Bu Arıza Aracın Servise Verilmesine Engel Değil"), IF(Z13-F13>0,(AB13-Y13)*24*60, IF(OR(AND(G13>$AS$1,G13<$AT$1),AND(G13>$AU$1,G13<$AV$1)), (AF13-H13)*24*60, BH:BH0)), AN13),0)} | AN13: =IFERROR(IF(P13<>"D(Arıza Değil)",AC13,0),0) | AO13: =[4]SayfaKAY!AG846 | AP13: =[4]SayfaKAY!AI846 | AQ13: =[4]SayfaKAY!AQ846 | AR13: =[4]SayfaKAY!AH846 | AS13: =[4]SayfaKAY!AJ846 | AT13: =[4]SayfaKAY!AM846 | AU13: =[4]SayfaKAY!AL846 | AV13: =[4]SayfaKAY!AP846 | AW13: =[4]SayfaKAY!AT846 | AX13: =IF(V13="","",V13*AC13*BC$1) | BB13: =IF($AQ$1="X", IF(AND(G13>=$AS$1,G13<=$AT$1),IF(P13<>"D(Arıza Değil)",AC13,0), IF(AND(G13>=$AU$1,G13<=$AV$1),IF(P13<>"D(Arıza Değil)",AC13,0), "")), "") | BH13: =IFERROR(FRACAS!AN849, "Hata Var") -> 74 | BK13: =[4]SayfaKAY!AW846 | BL13: =[4]SayfaKAY!V846 | BN13: =IF($AQ$1="X", IF(AND(G13>=$AS$1,G13<=$AT$1),IF(P13<>"D(Arıza Değil",AC13,0),IF(AND(G13>=$AU$1,G13<=$AV$1),IF(P13<>"D:Arıza Değil",AC13,0), "x var")), "x yok") -> x yok | BO13: =IF(OR(AND(G13>$AS$1,G13<$AT$1),AND(G13>$AU$1,G13<$AV$1)),"aynı gün giderilen arıza") -> FALSE | BP13: =IF(Z13-F13>0,"Bir günden fazla süren arıza",IF(OR(AND(G13>$AS$1,G13<$AT$1),AND(G13>$AU$1,G13<$AV$1)),"aynı gün giderilen arıza")) -> #VALUE! | BQ13: =(Y13-H13)*24*60 -> #VALUE! | BR13: =(AB13-Y13)*24*60 -> #VALUE! | BS13: =(AF13-H13)*24*60 -> #VALUE! | BV13: =COUNTIFS(B$5:B$9980,B13,H$5:H$9980,"<="&AF13,AF$5:AF$9980,">="&H13)-1 -> -1 | BW13: =IF(COUNTIFS(B$5:B$9980,B13,H$5:H$9980,"<="&AF13,AF$5:AF$9980,">="&H13)>1,"Evet, çakışma var","Hayır, çakışma yok") -> Hayır, çakışma yok | BY13: =Y13-H13 -> #VALUE! | BZ13: =AB13-Y13 -> #VALUE! | CA13: =AB13-H13 -> #VALUE! | CE13: 845 | CF13: =H13 | CG13: =AB13 | CK13: =AB13-Y13 -> #VALUE! | CL13: =Y13-H13 -> #VALUE! | CM13: =AB13-H13 -> #VALUE! | CO13: =AC13 | CP13: =CU13/24 -> #VALUE! | CQ13: =G13 | CR13: =Y13 | CS13: =AB13 | CT13: =(CR13-CQ13)*1440 -> #VALUE! | CU13: =(CS13-CR13)*1440 -> #VALUE! | CV13: =(CS13-CQ13)*1440 -> #VALUE! | CW13: =CT13/CV13 -> #VALUE!
A14: =[4]SayfaKAY!C847 | B14: =[4]SayfaKAY!D847 | C14: =[4]SayfaKAY!E847 | D14: =[4]SayfaKAY!F847 | E14: =[4]SayfaKAY!G847 | F14: =IF(H14="","",INT(H14)) | G14: =IF(H14="","",MOD(H14,1)) | H14: =[4]SayfaKAY!H847 | I14: =[4]SayfaKAY!I847 | J14: =IF([4]SayfaKAY!J847="","",IF([4]SayfaKAY!J847="Müşteri","Notified by Customer","Notified by Bozankaya")) | K14: =VLOOKUP([4]SayfaKAY!L847,#REF!,2,FALSE) -> #REF! | L14: =[4]SayfaKAY!X847 | M14: =IF( E14="", "", A14&"-"&E14) | N14: =[4]SayfaKAY!M847 | O14: =[4]SayfaKAY!P847 | P14: =[4]SayfaKAY!Q847 | Q14: =[4]SayfaKAY!R847 | R14: {=IF([4]SayfaKAY!U847="","",_xlfn.IFS([4]SayfaKAY!U847="Bozankaya","Bozankaya",[4]SayfaKAY!U847="Müşteri","Customer",[4]SayfaKAY!U847="Tedarikçi","Equipment Supplier"))} | S14: =[4]SayfaKAY!N847 | T14: =[4]SayfaKAY!AD847 | U14: =[4]SayfaKAY!W847 | V14: =[4]SayfaKAY!AZ847 | W14: =IF(Y14="","",INT(Y14)) | X14: =IF(Y14="","",TEXT(Y14,"ss:dd")) | Y14: =[4]SayfaKAY!AE847 | Z14: =IF(AB14="","",INT(AB14)) | AA14: =IF(AB14="","",TEXT(AB14,"ss:dd")) | AB14: =[4]SayfaKAY!BA847 | AC14: =IF(AF14="","",(AF14-H14)*24*60) | AD14: =IF(AF14="","",INT(AF14)) | AE14: =IF(AF14="","",TEXT(AF14,"ss:dd")) | AF14: =[4]SayfaKAY!BA847 | AG14: =[4]SayfaKAY!S847 | AH14: =IF(P14="A(Hareket etmeyi engelleyen arıza)","Bu Arıza Aracın Servise Verilmesine Engel", IF(P14="B(Servisten çekmeye etki eden arıza)","Bu Arıza Aracın Servise Verilmesine Engel", IF(P14="C(Sisteme etki etmeyen arıza)","Bu Arıza Aracın Servise Verilmesine Engel Değil", IF(P14="D(Arıza Değil)","Bu Arıza Aracın Servise Verilmesine Engel Değil", "")))) | AI14: =[4]SayfaKAY!AV847 | AJ14: =IF(AL14="","",INT(AL14)) | AK14: =IF(AL14="","",TEXT(AL14,"ss:dd")) | AL14: =[4]SayfaKAY!AX847 | AM14: {=IFERROR(IF(AND(P14<>"D(Arıza Değil)",AH14="Bu Arıza Aracın Servise Verilmesine Engel Değil"), IF(Z14-F14>0,(AB14-Y14)*24*60, IF(OR(AND(G14>$AS$1,G14<$AT$1),AND(G14>$AU$1,G14<$AV$1)), (AF14-H14)*24*60, BH:BH0)), AN14),0)} | AN14: =IFERROR(IF(P14<>"D(Arıza Değil)",AC14,0),0) | AO14: =[4]SayfaKAY!AG847 | AP14: =[4]SayfaKAY!AI847 | AQ14: =[4]SayfaKAY!AQ847 | AR14: =[4]SayfaKAY!AH847 | AS14: =[4]SayfaKAY!AJ847 | AT14: =[4]SayfaKAY!AM847 | AU14: =[4]SayfaKAY!AL847 | AV14: =[4]SayfaKAY!AP847 | AW14: =[4]SayfaKAY!AT847 | AX14: =IF(V14="","",V14*AC14*BC$1) | BB14: =IF($AQ$1="X", IF(AND(G14>=$AS$1,G14<=$AT$1),IF(P14<>"D(Arıza Değil)",AC14,0), IF(AND(G14>=$AU$1,G14<=$AV$1),IF(P14<>"D(Arıza Değil)",AC14,0), "")), "") | BH14: =IFERROR(FRACAS!AN850, "Hata Var") -> 136 | BK14: =[4]SayfaKAY!AW847 | BL14: =[4]SayfaKAY!V847 | BN14: =IF($AQ$1="X", IF(AND(G14>=$AS$1,G14<=$AT$1),IF(P14<>"D(Arıza Değil",AC14,0),IF(AND(G14>=$AU$1,G14<=$AV$1),IF(P14<>"D:Arıza Değil",AC14,0), "x var")), "x yok") -> x yok | BO14: =IF(OR(AND(G14>$AS$1,G14<$AT$1),AND(G14>$AU$1,G14<$AV$1)),"aynı gün giderilen arıza") -> FALSE | BP14: =IF(Z14-F14>0,"Bir günden fazla süren arıza",IF(OR(AND(G14>$AS$1,G14<$AT$1),AND(G14>$AU$1,G14<$AV$1)),"aynı gün giderilen arıza")) -> #VALUE! | BQ14: =(Y14-H14)*24*60 -> #VALUE! | BR14: =(AB14-Y14)*24*60 -> #VALUE! | BS14: =(AF14-H14)*24*60 -> #VALUE! | BV14: =COUNTIFS(B$5:B$9980,B14,H$5:H$9980,"<="&AF14,AF$5:AF$9980,">="&H14)-1 -> -1 | BW14: =IF(COUNTIFS(B$5:B$9980,B14,H$5:H$9980,"<="&AF14,AF$5:AF$9980,">="&H14)>1,"Evet, çakışma var","Hayır, çakışma yok") -> Hayır, çakışma yok | BY14: =Y14-H14 -> #VALUE! | BZ14: =AB14-Y14 -> #VALUE! | CA14: =AB14-H14 -> #VALUE! | CE14: 846 | CF14: =H14 | CG14: =AB14 | CK14: =AB14-Y14 -> #VALUE! | CL14: =Y14-H14 -> #VALUE! | CM14: =AB14-H14 -> #VALUE! | CO14: =AC14 | CP14: =CU14/24 -> #VALUE! | CQ14: =G14 | CR14: =Y14 | CS14: =AB14 | CT14: =(CR14-CQ14)*1440 -> #VALUE! | CU14: =(CS14-CR14)*1440 -> #VALUE! | CV14: =(CS14-CQ14)*1440 -> #VALUE! | CW14: =CT14/CV14 -> #VALUE!
A15: =[4]SayfaKAY!C848 | B15: =[4]SayfaKAY!D848 | C15: =[4]SayfaKAY!E848 | D15: =[4]SayfaKAY!F848 | E15: =[4]SayfaKAY!G848 | F15: =IF(H15="","",INT(H15)) | G15: =IF(H15="","",MOD(H15,1)) | H15: =[4]SayfaKAY!H848 | I15: =[4]SayfaKAY!I848 | J15: =IF([4]SayfaKAY!J848="","",IF([4]SayfaKAY!J848="Müşteri","Notified by Customer","Notified by Bozankaya")) | K15: =VLOOKUP([4]SayfaKAY!L848,#REF!,2,FALSE) -> #REF! | L15: =[4]SayfaKAY!X848 | M15: =IF( E15="", "", A15&"-"&E15) | N15: =[4]SayfaKAY!M848 | O15: =[4]SayfaKAY!P848 | P15: =[4]SayfaKAY!Q848 | Q15: =[4]SayfaKAY!R848 | R15: {=IF([4]SayfaKAY!U848="","",_xlfn.IFS([4]SayfaKAY!U848="Bozankaya","Bozankaya",[4]SayfaKAY!U848="Müşteri","Customer",[4]SayfaKAY!U848="Tedarikçi","Equipment Supplier"))} | S15: =[4]SayfaKAY!N848 | T15: =[4]SayfaKAY!AD848 | U15: =[4]SayfaKAY!W848 | V15: =[4]SayfaKAY!AZ848 | W15: =IF(Y15="","",INT(Y15)) | X15: =IF(Y15="","",TEXT(Y15,"ss:dd")) | Y15: =[4]SayfaKAY!AE848 | Z15: =IF(AB15="","",INT(AB15)) | AA15: =IF(AB15="","",TEXT(AB15,"ss:dd")) | AB15: =[4]SayfaKAY!BA848 | AC15: =IF(AF15="","",(AF15-H15)*24*60) | AD15: =IF(AF15="","",INT(AF15)) | AE15: =IF(AF15="","",TEXT(AF15,"ss:dd")) | AF15: =[4]SayfaKAY!BA848 | AG15: =[4]SayfaKAY!S848 | AH15: =IF(P15="A(Hareket etmeyi engelleyen arıza)","Bu Arıza Aracın Servise Verilmesine Engel", IF(P15="B(Servisten çekmeye etki eden arıza)","Bu Arıza Aracın Servise Verilmesine Engel", IF(P15="C(Sisteme etki etmeyen arıza)","Bu Arıza Aracın Servise Verilmesine Engel Değil", IF(P15="D(Arıza Değil)","Bu Arıza Aracın Servise Verilmesine Engel Değil", "")))) | AI15: =[4]SayfaKAY!AV848 | AJ15: =IF(AL15="","",INT(AL15)) | AK15: =IF(AL15="","",TEXT(AL15,"ss:dd")) | AL15: =[4]SayfaKAY!AX848 | AM15: {=IFERROR(IF(AND(P15<>"D(Arıza Değil)",AH15="Bu Arıza Aracın Servise Verilmesine Engel Değil"), IF(Z15-F15>0,(AB15-Y15)*24*60, IF(OR(AND(G15>$AS$1,G15<$AT$1),AND(G15>$AU$1,G15<$AV$1)), (AF15-H15)*24*60, BH:BH0)), AN15),0)} | AN15: =IFERROR(IF(P15<>"D(Arıza Değil)",AC15,0),0) | AO15: =[4]SayfaKAY!AG848 | AP15: =[4]SayfaKAY!AI848 | AQ15: =[4]SayfaKAY!AQ848 | AR15: =[4]SayfaKAY!AH848 | AS15: =[4]SayfaKAY!AJ848 | AT15: =[4]SayfaKAY!AM848 | AU15: =[4]SayfaKAY!AL848 | AV15: =[4]SayfaKAY!AP848 | AW15: =[4]SayfaKAY!AT848 | AX15: =IF(V15="","",V15*AC15*BC$1) | BB15: =IF($AQ$1="X", IF(AND(G15>=$AS$1,G15<=$AT$1),IF(P15<>"D(Arıza Değil)",AC15,0), IF(AND(G15>=$AU$1,G15<=$AV$1),IF(P15<>"D(Arıza Değil)",AC15,0), "")), "") | BH15: =IFERROR(FRACAS!AN851, "Hata Var") -> 204 | BK15: =[4]SayfaKAY!AW848 | BL15: =[4]SayfaKAY!V848 | BN15: =IF($AQ$1="X", IF(AND(G15>=$AS$1,G15<=$AT$1),IF(P15<>"D(Arıza Değil",AC15,0),IF(AND(G15>=$AU$1,G15<=$AV$1),IF(P15<>"D:Arıza Değil",AC15,0), "x var")), "x yok") -> x yok | BO15: =IF(OR(AND(G15>$AS$1,G15<$AT$1),AND(G15>$AU$1,G15<$AV$1)),"aynı gün giderilen arıza") -> FALSE | BP15: =IF(Z15-F15>0,"Bir günden fazla süren arıza",IF(OR(AND(G15>$AS$1,G15<$AT$1),AND(G15>$AU$1,G15<$AV$1)),"aynı gün giderilen arıza")) -> #VALUE! | BQ15: =(Y15-H15)*24*60 -> #VALUE! | BR15: =(AB15-Y15)*24*60 -> #VALUE! | BS15: =(AF15-H15)*24*60 -> #VALUE! | BV15: =COUNTIFS(B$5:B$9980,B15,H$5:H$9980,"<="&AF15,AF$5:AF$9980,">="&H15)-1 -> -1 | BW15: =IF(COUNTIFS(B$5:B$9980,B15,H$5:H$9980,"<="&AF15,AF$5:AF$9980,">="&H15)>1,"Evet, çakışma var","Hayır, çakışma yok") -> Hayır, çakışma yok | BY15: =Y15-H15 -> #VALUE! | BZ15: =AB15-Y15 -> #VALUE! | CA15: =AB15-H15 -> #VALUE! | CE15: 847 | CF15: =H15 | CG15: =AB15 | CK15: =AB15-Y15 -> #VALUE! | CL15: =Y15-H15 -> #VALUE! | CM15: =AB15-H15 -> #VALUE! | CO15: =AC15 | CP15: =CU15/24 -> #VALUE! | CQ15: =G15 | CR15: =Y15 | CS15: =AB15 | CT15: =(CR15-CQ15)*1440 -> #VALUE! | CU15: =(CS15-CR15)*1440 -> #VALUE! | CV15: =(CS15-CQ15)*1440 -> #VALUE! | CW15: =CT15/CV15 -> #VALUE!
