Workbook
Name Ana_Kompanent: [1]Atamalar!$A$10:$A$33
Name Ana_Kompanent: [1]Atamalar!$A$10:$A$33
Name Ana_Kompanent: Atamalar!$B$10:$B$51
Name Ant_2: Atamalar!$B$250:$B$251
Name Araç_Şase: [1]Atamalar!#REF!
Name Araç_Şase: [1]Atamalar!#REF!
Name Araç_Şase: Atamalar!#REF!
Name Araç_Şase_Numaraları: [1]Atamalar!#REF!
Name Araç_Şase_Numaraları: [1]Atamalar!#REF!
Name Araç_Şase_Numaraları: Atamalar!#REF!
Name Araç_Tipi: [1]Atamalar!#REF!
Name Araç_Tipi: [1]Atamalar!#REF!
Name Araç_Tipi: Atamalar!#REF!
Name Assembly_Line: [1]Atamalar!#REF!
Name Assembly_Line: [1]Atamalar!#REF!
Name Assembly_Line: Atamalar!#REF!
Name Auxiliary_Power_Unit: Atamalar!$B$59:$B$60
Name Batarya: Atamalar!$B$170:$B$171
Name Bogie: Atamalar!$B$102
Name Boji: Atamalar!$B$102
Name BOZANKAYA_Design: [1]Atamalar!#REF!
Name BOZANKAYA_Design: [1]Atamalar!#REF!
Name BOZANKAYA_Design: Atamalar!#REF!
Name Bölüm: [1]Atamalar!#REF!
Name Bölüm: [1]Atamalar!#REF!
Name Bölüm: Atamalar!#REF!
Name Brake_System: Atamalar!$B$63:$B$64
Name CCTV: Atamalar!$B$87:$B$89
Name Chassis_Design: [1]Atamalar!#REF!
Name Chassis_Design: [1]Atamalar!#REF!
Name Chassis_Design: Atamalar!#REF!
Name Chassis_Production: [1]Atamalar!#REF!
Name Chassis_Production: [1]Atamalar!#REF!
Name Chassis_Production: Atamalar!#REF!
Name Chassis_Quality: [1]Atamalar!#REF!
Name Chassis_Quality: [1]Atamalar!#REF!
Name Chassis_Quality: Atamalar!#REF!
Name Chassis_Quality_Controls: [1]Atamalar!#REF!
Name Chassis_Quality_Controls: [1]Atamalar!#REF!
Name Chassis_Quality_Controls: Atamalar!#REF!
Name Couplers: Atamalar!$B$145:$B$147
Name Department: [1]Atamalar!#REF!
Name Department: [1]Atamalar!#REF!
Name Department: Atamalar!#REF!
Name Door_System: Atamalar!$B$118:$B$119
Name Driver_HVAC_System: Atamalar!$B$79:$B$81
Name E_Kabinet: Atamalar!$B$125
Name Electrical_Design: [1]Atamalar!#REF!
Name Electrical_Design: [1]Atamalar!#REF!
Name Electrical_Design: Atamalar!#REF!
Name Electromechanic_Tasarım: [1]Atamalar!#REF!
Name Electromechanic_Tasarım: [1]Atamalar!#REF!
Name Electromechanic_Tasarım: Atamalar!#REF!
Name Elektrik_Tasarım: [1]Atamalar!#REF!
Name Elektrik_Tasarım: [1]Atamalar!#REF!
Name Elektrik_Tasarım: Atamalar!#REF!
Name External_Light: Atamalar!$B$153:$B$155
Name External_Trim: Atamalar!$B$167
Name Gangway_Articulation: Atamalar!$B$160:$B$162
Name Gearbox: Atamalar!$B$110:$B$112

Sheet FRACAS (YENİ)
N1: FRACAS(Hata Raporlama Analizi ve Düzeltici Aksiyon Sitemi) Formu FRACAS(Failure Reporting Analysis And Corrective Action System) Form | AB1: Doküman No / Document Code; FR-549 Yayımlama Tarih / Publish Datei; 23.05.2023 Revizyon Tarihi / Revision; 04.08.2025 Revizyon No: 4 | AP1: =TODAY() -> 46026 | AQ1: X | AR1: Proje Pik Saatleri Proje Peak Times | AS1: 0.27083333 | AT1: 0.39583333 | AU1: 0.66666667 | AV1: 0.8125 | AW1: Proje Ort Hız Proje Avr. Speed | AY1: 18 | AZ1: km | BA1: Proje İşçilik Maliyeti Project Labor Cost | BC1: 11 | BD1: hbm.142536
A3: Araç Bilgileri Vhicle Information | E3: Problem Bilgileri Failure Information | P3: (EN 50126-1:2017 Tabl C.3 | Q3: (EN 50126-1:2017 Tabl C.5 | R3: Çözüm Adımları ve Bilgileri Solution Steps And Information | AO3: Tamir İçin Gerekli Parçalar Needed Parts For Repairing | AW3: Maliyet Cost
A4: Project | B4: Araç Numarası Vehicle Number | C4: Araç Module Vehicle Module | D4: Araç Kilometresi Vehicle Kilometer | E4: FRACAS ID | F4: Hata Tarih/Date | G4: Hata Saat/Time | I4: Arıza Konumu Failure Location | J4: Arıza Tespit Yöntemi Failure Detection Method | K4: Kapsam Scope | L4: İlgili Tedarikçi Relevant Supplier | M4: Proje Bazında Fracas ID Fracas ID Based on Project | N4: Arıza Tanımı Failure Description | O4: DDU Arıza Sınıfı DDU Failure Class | P4: Arıza Sınıfı Failure Class | Q4: Arızanın Emniyetle İlgili Şiddet Kategorisi Safety Related Severity Category of Failure | R4: Arıza Kaynağı Source of Failure | S4: Arıza Tespitini Takiben Yapılan İşlem Action Followed by Fault Detection | T4: Aksiyon Action | U4: Garanti Kapsamı Warranty Coverage | V4: Tamir için Gerekli Personel Sayısı Required Personnel Quantity for Repair | W4: Tamir/Değiştirme Başlama Tarihi Date of Starting to Repair/Replace | X4: Tamir/Değiştirme Başlama Saati Time of Starting to Repair/Replace | Z4: Tamir/Değiştirme Bitiş Tarihi Date of Fnish to Repair/Replace | AA4: Tamir/Değiştirme Bitiş Saati Time of Fnish to Repair/Replace | AC4: Tamir Süresi (dakika) Repair Time (dakika) | AD4: Servise Veriliş Tarih Date of Ready to Service | AE4: Servise Veriliş Saati Time of Ready to Service | AG4: Arıza Tipi Failure Type | AH4: Detaylı Bilgi Detail İnformation | AI4: NCR Numarası NCR Number | AJ4: NCR Kapanış Tarihi NCR Closing Date | AK4: NCR Kapanış Saati NCR Closing Time | AM4: Araç MTTR / MDT | AN4: Kompanent MTTR / MDT | AO4: Ekipman Tedarikçisi Equipment Supplier | AP4: Parça Kodu Part Code | AQ4: Seri Numarası Serial Number | AR4: Parça Adı Part Name | AS4: Adeti Quantity | AT4: Sipariş No Order No | AU4: Sipariş Tarihi Order Date | AV4: Teslim Tarihi Delivery Date | AW4: Malzeme Maliyeti Material Cost | AX4: İşçilik Maliyeti Labor Cost
A5: TIM_1624 | B5: 1001 | D5: 200 | F5: 45636 | G5: 0.29166667 | H5: =F5+G5 -> 45636.292 | I5: Hat/Line | J5: Notified By Customer | K5: Brake_System | L5: Hanning&Kall | M5: =A5&"-"&E5 -> TIM_1624- | N5: abv | O5: B | P5: C:Küçük Arıza | Q5: A | R5: Customer | S5: bndsi | T5: Tamir Edilecek/To Be Repaired | U5: Evet/Yes | V5: 2 | W5: 45636 | X5: 0.45833333 | Y5: =W5+X5 -> 45636.458 | Z5: 45636 | AA5: 0.85416667 | AB5: =Z5+AA5 -> 45636.854 | AC5: =(AF5-H5)*24*60 -> 810 | AD5: 45636 | AE5: 0.85416667 | AF5: =AD5+AE5 -> 45636.854 | AG5: İlk defa karşılaşılan arıza / First time failure | AH5: Bu Arıza Aracın Servise Verilmesine Engel Değil | AL5: =AJ5+AK5 -> 0 | AM5: =IF(AND(P5<>"D:Arıza Değil",AH5="Bu Arıza Aracın Servise Verilmesine Engel Değil"),IF(Z5-F5>0,(AB5-Y5)*24,IF(OR(AND(G5>AS$1,G5<AT$1),AND(G5>AU$1,G5<AV$1)),(AF5-H5)*24,0)),AN5) -> 13.5 | AN5: =IF(P5<>"D:Arıza Değil",AC5,0) -> 810 | AP5: =IF(AQ1="X", IF(AND(G5>=AS1,G5<=AT1),IF(P5<>"D:Arıza Değil",AC5,0),FRACAS!BB5 IF(AND(G5>=AU1,G5<=AV1),IF(P5<>"D:Arıza Değil",AC5,0), "")), "") -> 810 | AW5: 0 | AX5: =V5*AC5*BC$1 -> 17820
A6: TIM_1625 | M6: =A6&"-"&E6 -> TIM_1625- | Y6: =W6+X6 -> 0 | AB6: =Z6+AA6 -> 0 | AC6: =(AB6-Y6)*24*60 -> 0 | AF6: =AD6+AE6 -> 0 | AL6: =AJ6+AK6 -> 0 | AM6: =IF(AND(P6<>"D:Arıza Değil",AH6="Bu Arıza Aracın Servise Verilmesine Engel Değil"),IF(Z6-F6>0,(AB6-Y6)*24,IF(OR(AND(G6>AS$1,G6<AT$1),AND(G6>AU$1,G6<AV$1)),(AL6-Y6)*24,0)),AN6) -> 0 | AN6: =IF(P6<>"D:Arıza Değil",AC6,0) -> 0 | AP6: =IF(AND(P5<>"D:Arıza Değil",AH5="Bu Arıza Aracın Servise Verilmesine Engel Değil"),IF(Z5-F5>0,(AB5-Y5)*24,IF(AQ1="X",IF(AND(G5>=AS1,G5<=AT1),IF(P5<>"D:Arıza Değil",AC5,0),IF(AND(G5>=AU1,G5<=AV1),IF(P5<>"D:Arıza Değil",AC5,0),"")),0)),AN5) -> 810 | AW6: 0 | AX6: =V6*AC6*BC$1 -> 0
M7: =A7&"-"&E7 -> - | Y7: =W7+X7 -> 0 | AB7: =Z7+AA7 -> 0 | AC7: =(AB7-Y7)*24*60 -> 0 | AF7: =AD7+AE7 -> 0 | AL7: =AJ7+AK7 -> 0 | AM7: =IF(AND(P7<>"D:Arıza Değil",AH7="Bu Arıza Aracın Servise Verilmesine Engel Değil"),IF(Z7-F7>0,(AB7-Y7)*24,IF(OR(AND(G7>AS$1,G7<AT$1),AND(G7>AU$1,G7<AV$1)),(AL7-Y7)*24,0)),AN7) -> 0 | AN7: =IF(P7<>"D:Arıza Değil",AC7,0) -> 0 | AW7: 0 | AX7: =V7*AC7*BC$1 -> 0
M8: =A8&"-"&E8 -> - | Y8: =W8+X8 -> 0 | AB8: =Z8+AA8 -> 0 | AC8: =(AB8-Y8)*24*60 -> 0 | AF8: =AD8+AE8 -> 0 | AL8: =AJ8+AK8 -> 0 | AM8: =IF(AND(P8<>"D:Arıza Değil",AH8="Bu Arıza Aracın Servise Verilmesine Engel Değil"),IF(Z8-F8>0,(AB8-Y8)*24,IF(OR(AND(G8>AS$1,G8<AT$1),AND(G8>AU$1,G8<AV$1)),(AL8-Y8)*24,0)),AN8) -> 0 | AN8: =IF(P8<>"D:Arıza Değil",AC8,0) -> 0 | AW8: 0 | AX8: =V8*AC8*BC$1 -> 0
M9: =A9&"-"&E9 -> - | Y9: =W9+X9 -> 0 | AB9: =Z9+AA9 -> 0 | AC9: =(AB9-Y9)*24*60 -> 0 | AF9: =AD9+AE9 -> 0 | AL9: =AJ9+AK9 -> 0 | AM9: =IF(AND(P9<>"D:Arıza Değil",AH9="Bu Arıza Aracın Servise Verilmesine Engel Değil"),IF(Z9-F9>0,(AB9-Y9)*24,IF(OR(AND(G9>AS$1,G9<AT$1),AND(G9>AU$1,G9<AV$1)),(AL9-Y9)*24,0)),AN9) -> 0 | AN9: =IF(P9<>"D:Arıza Değil",AC9,0) -> 0 | AW9: 0 | AX9: =V9*AC9*BC$1 -> 0
M10: =A10&"-"&E10 -> - | Y10: =W10+X10 -> 0 | AB10: =Z10+AA10 -> 0 | AC10: =(AB10-Y10)*24*60 -> 0 | AF10: =AD10+AE10 -> 0 | AL10: =AJ10+AK10 -> 0 | AM10: =IF(AND(P10<>"D:Arıza Değil",AH10="Bu Arıza Aracın Servise Verilmesine Engel Değil"),IF(Z10-F10>0,(AB10-Y10)*24,IF(OR(AND(G10>AS$1,G10<AT$1),AND(G10>AU$1,G10<AV$1)),(AL10-Y10)*24,0)),AN10) -> 0 | AN10: =IF(P10<>"D:Arıza Değil",AC10,0) -> 0 | AW10: 0 | AX10: =V10*AC10*BC$1 -> 0
M11: =A11&"-"&E11 -> - | Y11: =W11+X11 -> 0 | AB11: =Z11+AA11 -> 0 | AC11: =(AB11-Y11)*24*60 -> 0 | AF11: =AD11+AE11 -> 0 | AL11: =AJ11+AK11 -> 0 | AM11: =IF(AND(P11<>"D:Arıza Değil",AH11="Bu Arıza Aracın Servise Verilmesine Engel Değil"),IF(Z11-F11>0,(AB11-Y11)*24,IF(OR(AND(G11>AS$1,G11<AT$1),AND(G11>AU$1,G11<AV$1)),(AL11-Y11)*24,0)),AN11) -> 0 | AN11: =IF(P11<>"D:Arıza Değil",AC11,0) -> 0 | AW11: 0 | AX11: =V11*AC11*BC$1 -> 0
M12: =A12&"-"&E12 -> - | Y12: =W12+X12 -> 0 | AB12: =Z12+AA12 -> 0 | AC12: =(AB12-Y12)*24*60 -> 0 | AF12: =AD12+AE12 -> 0 | AL12: =AJ12+AK12 -> 0 | AM12: =IF(AND(P12<>"D:Arıza Değil",AH12="Bu Arıza Aracın Servise Verilmesine Engel Değil"),IF(Z12-F12>0,(AB12-Y12)*24,IF(OR(AND(G12>AS$1,G12<AT$1),AND(G12>AU$1,G12<AV$1)),(AL12-Y12)*24,0)),AN12) -> 0 | AN12: =IF(P12<>"D:Arıza Değil",AC12,0) -> 0 | AW12: 0 | AX12: =V12*AC12*BC$1 -> 0
M13: =A13&"-"&E13 -> - | Y13: =W13+X13 -> 0 | AB13: =Z13+AA13 -> 0 | AC13: =(AB13-Y13)*24*60 -> 0 | AF13: =AD13+AE13 -> 0 | AL13: =AJ13+AK13 -> 0 | AM13: =IF(AND(P13<>"D:Arıza Değil",AH13="Bu Arıza Aracın Servise Verilmesine Engel Değil"),IF(Z13-F13>0,(AB13-Y13)*24,IF(OR(AND(G13>AS$1,G13<AT$1),AND(G13>AU$1,G13<AV$1)),(AL13-Y13)*24,0)),AN13) -> 0 | AN13: =IF(P13<>"D:Arıza Değil",AC13,0) -> 0 | AW13: 0 | AX13: =V13*AC13*BC$1 -> 0
M14: =A14&"-"&E14 -> - | Y14: =W14+X14 -> 0 | AB14: =Z14+AA14 -> 0 | AC14: =(AB14-Y14)*24*60 -> 0 | AF14: =AD14+AE14 -> 0 | AL14: =AJ14+AK14 -> 0 | AM14: =IF(AND(P14<>"D:Arıza Değil",AH14="Bu Arıza Aracın Servise Verilmesine Engel Değil"),IF(Z14-F14>0,(AB14-Y14)*24,IF(OR(AND(G14>AS$1,G14<AT$1),AND(G14>AU$1,G14<AV$1)),(AL14-Y14)*24,0)),AN14) -> 0 | AN14: =IF(P14<>"D:Arıza Değil",AC14,0) -> 0 | AW14: 0 | AX14: =V14*AC14*BC$1 -> 0
M15: =A15&"-"&E15 -> - | Y15: =W15+X15 -> 0 | AB15: =Z15+AA15 -> 0 | AC15: =(AB15-Y15)*24*60 -> 0 | AF15: =AD15+AE15 -> 0 | AL15: =AJ15+AK15 -> 0 | AM15: =IF(AND(P15<>"D:Arıza Değil",AH15="Bu Arıza Aracın Servise Verilmesine Engel Değil"),IF(Z15-F15>0,(AB15-Y15)*24,IF(OR(AND(G15>AS$1,G15<AT$1),AND(G15>AU$1,G15<AV$1)),(AL15-Y15)*24,0)),AN15) -> 0 | AN15: =IF(P15<>"D:Arıza Değil",AC15,0) -> 0 | AW15: 0 | AX15: =V15*AC15*BC$1 -> 0
M16: =A16&"-"&E16 -> - | Y16: =W16+X16 -> 0 | AB16: =Z16+AA16 -> 0 | AC16: =(AB16-Y16)*24*60 -> 0 | AF16: =AD16+AE16 -> 0 | AL16: =AJ16+AK16 -> 0 | AM16: =IF(AND(P16<>"D:Arıza Değil",AH16="Bu Arıza Aracın Servise Verilmesine Engel Değil"),IF(Z16-F16>0,(AB16-Y16)*24,IF(OR(AND(G16>AS$1,G16<AT$1),AND(G16>AU$1,G16<AV$1)),(AL16-Y16)*24,0)),AN16) -> 0 | AN16: =IF(P16<>"D:Arıza Değil",AC16,0) -> 0 | AW16: 0 | AX16: =V16*AC16*BC$1 -> 0
M17: =A17&"-"&E17 -> - | Y17: =W17+X17 -> 0 | AB17: =Z17+AA17 -> 0 | AC17: =(AB17-Y17)*24*60 -> 0 | AF17: =AD17+AE17 -> 0 | AL17: =AJ17+AK17 -> 0 | AM17: =IF(AND(P17<>"D:Arıza Değil",AH17="Bu Arıza Aracın Servise Verilmesine Engel Değil"),IF(Z17-F17>0,(AB17-Y17)*24,IF(OR(AND(G17>AS$1,G17<AT$1),AND(G17>AU$1,G17<AV$1)),(AL17-Y17)*24,0)),AN17) -> 0 | AN17: =IF(P17<>"D:Arıza Değil",AC17,0) -> 0 | AW17: 0 | AX17: =V17*AC17*BC$1 -> 0
M18: =A18&"-"&E18 -> - | Y18: =W18+X18 -> 0 | AB18: =Z18+AA18 -> 0 | AC18: =(AB18-Y18)*24*60 -> 0 | AF18: =AD18+AE18 -> 0 | AL18: =AJ18+AK18 -> 0 | AM18: =IF(AND(P18<>"D:Arıza Değil",AH18="Bu Arıza Aracın Servise Verilmesine Engel Değil"),IF(Z18-F18>0,(AB18-Y18)*24,IF(OR(AND(G18>AS$1,G18<AT$1),AND(G18>AU$1,G18<AV$1)),(AL18-Y18)*24,0)),AN18) -> 0 | AN18: =IF(P18<>"D:Arıza Değil",AC18,0) -> 0 | AW18: 0 | AX18: =V18*AC18*BC$1 -> 0
... M856: =A856&"-"&E856 -> - | Y856: =W856+X856 -> 0 | AB856: =Z856+AA856 -> 0 | AC856: =(AB856-Y856)*24*60 -> 0 | AF856: =AD856+AE856 -> 0 | AL856: =AJ856+AK856 -> 0 | AM856: =IF(AND(P856<>"D:Arıza Değil",AH856="Bu Arıza Aracın Servise Verilmesine Engel Değil"),IF(Z856-F856>0,(AB856-Y856)*24,IF(OR(AND(G856>AS$1,G856<AT$1),AND(G856>AU$1,G856<AV$1)),(AL856-Y856)*24,0)),AN856) -> 0 | AN856: =IF(P856<>"D:Arıza Değil",AC856,0) -> 0 | AW856: 0 | AX856: =V856*AC856*BC$1 -> 0

Sheet FRACAS
N1: FRACAS(Hata Raporlama Analizi ve Düzeltici Aksiyon Sitemi) Formu FRACAS(Failure Reporting Analysis And Corrective Action System) Form | AB1: Doküman No / Document Code; FR-549 Yayımlama Tarih / Publish Datei; 23.05.2023 Revizyon Tarihi / Revision; 23.05.2023 Revizyon No; 2 | AP1: =TODAY() -> 46026 | AQ1: x | AR1: Proje Pik Saatleri Proje Peak Times | AS1: 0.29166667 | AT1: 0.375 | AU1: 0.70833333 | AV1: 0.79166667 | AW1: Proje Ort Hız Proje Avr. Speed | AY1: 20 | AZ1: Km | BA1: Proje İşçilik Maliyeti Project Labor Cost | BC1: 11 | BD1: hbm.142536 | BP1: {=EĞERSAYI(G5)} -> #NAME? | BQ1: {=_xludf.ISNUMBER(G5)} -> #NAME? | BR1: =LEN(G5) -> 0
A3: Araç Bilgileri Vhicle Information | E3: Problem Bilgileri Failure Information | P3: (EN 50126-1:2017 Tabl C.3 | Q3: (EN 50126-1:2017 Tabl C.5 | R3: Çözüm Adımları ve Bilgileri Solution Steps And Information | AO3: Tamir İçin Gerekli Parçalar Needed Parts For Repairing | AW3: Maliyet Cost | AY3: SSH Detayı | BB3: X | BN3: Araç MTTR / MDT
A4: Project | B4: Araç Numarası Vehicle Number | C4: Araç Module Vehicle Module | D4: Araç Kilometresi Vehicle Kilometer | E4: FRACAS ID | F4: Hata Tarih /Date | G4: Hata Saat /Time | H4: . | I4: Arıza Konumu Failure Location | J4: Arıza Tespit Yöntemi Failure Detection Method | K4: Kapsam Scope | L4: İlgili Tedarikçi Relevant Supplier | M4: Proje Bazında Fracas ID Fracas ID Based on Project | N4: Arıza Tanımı Failure Description | O4: DDU Arıza Sınıfı DDU Failure Class | P4: Arıza Sınıfı Failure Class | Q4: Arızanın Emniyetle İlgili Şiddet Kategorisi Safety Related Severity Category of Failure | R4: Arıza Kaynağı Source of Failure | S4: Arıza Tespitini Takiben Yapılan İşlem Action Followed by Fault Detection | T4: Aksiyon Action | U4: Garanti Kapsamı Warranty Coverage | V4: Tamir için Gerekli Personel Sayısı Required Personnel Quantity for Repair | W4: Tamir/Değiştirme Başlama Tarihi Date of Starting to Repair/Replace | X4: Tamir/Değiştirme Başlama Saati Time of Starting to Repair/Replace | Y4: . | Z4: Tamir/Değiştirme Bitiş Tarihi Date of Fnish to Repair/Replace | AA4: Tamir/Değiştirme Bitiş Saati Time of Fnish to Repair/Replace | AB4: . | AC4: Tamir Süresi (dakika) Repair Time (dakika) | AD4: Servise Veriliş Tarih Date of Ready to Service | AE4: Servise Veriliş Saati Time of Ready to Service | AF4: . | AG4: Arıza Tipi Failure Type | AH4: Detaylı Bilgi Detail İnformation | AI4: NCR Numarası NCR Number | AJ4: NCR Kapanış Tarihi NCR Closing Date | AK4: NCR Kapanış Saati | AL4: . | AM4: Araç MTTR / MDT | AN4: Kompanent MTTR / MDT | AO4: Ekipman Tedarikçisi Equipment Supplier | AP4: Parça Kodu Part Code | AQ4: Seri Numarası Serial Number | AR4: Parça Adı Part Name | AS4: Adeti Quantity | AT4: Sipariş No Order No | AU4: Sipariş Tarihi Order Date | AV4: Teslim Tarihi Delivery Date | AW4: Malzeme Maliyeti Material Cost | AX4: İşçilik Maliyeti Labor Cost | AY4: No | AZ4: Photo URL | BA4: Arıza Resmi | BB4: Pik Saat Hes. | BK4: =[4]SayfaKOC!U1 -> Arıza Kaynağı (Sorumlu ) | BL4: =[4]SayfaKOC!V1 -> Arıza Kaynağı (Sorumlu 2) | BN4: pik zaman kontrolü | BQ4: bekleme süresi | BR4: tamir süresi | BS4: arızalı kalma süresi | BV4: Tamirat | BY4: Tamire Başlama Süresi | BZ4: Tamirat süresi | CA4: toplam arıza süresi | CF4: arıza | CG4: tamir | CO4: Tamir Süresi (saat) Repair Time (hour) | CP4: tamir süresi TÜM (saat) | CQ4: Hata Tarih/Date | CR4: Tamir/Değiştirme Başlama Saati Time of Starting to Repair/Replace | CS4: Tamir/Değiştirme Bitiş Saati Time of Fnish to Repair/Replace | CT4: Bekleme süresi (dk) | CU4: Tamir süresi (dk) | CV4: Toplam Arıza süresi (dk) | CW4: Bekleme gecikme oranı
F5: =IF(H5="","",INT(H5)) | G5: =IF(H5="","",MOD(H5,1)) | BN5: =IF($AQ$1="X", IF(AND(G5>=$AS$1,G5<=$AT$1),IF(P5<>"D(Arıza Değil",AC5,0),IF(AND(G5>=$AU$1,G5<=$AV$1),IF(P5<>"D:Arıza Değil",AC5,0), "x var")), "x yok") -> x var | BO5: =IF(OR(AND(G5>$AS$1,G5<$AT$1),AND(G5>$AU$1,G5<$AV$1)),"aynı gün giderilen arıza") -> FALSE | BP5: =IF(Z5-F5>0,"Bir günden fazla süren arıza",IF(OR(AND(G5>$AS$1,G5<$AT$1),AND(G5>$AU$1,G5<$AV$1)),"aynı gün giderilen arıza")) -> #VALUE! | BQ5: =(Y5-H5)*24*60 -> 0 | BR5: =(AB5-Y5)*24*60 -> 0 | BS5: =(AF5-H5)*24*60 -> 0 | BY5: =Y5-H5 -> 0 | BZ5: =AB5-Y5 -> 0 | CA5: =AB5-H5 -> 0 | CQ5: =G5 | CR5: =Y5 -> 0 | CS5: =AB5 -> 0 | CT5: =(CR5-CQ5)*1440 -> #VALUE! | CU5: =(CS5-CR5)*1440 -> 0 | CV5: =(CS5-CQ5)*1440 -> #VALUE! | CW5: =CT5/CV5 -> #VALUE!
F6: =IF(H6="","",INT(H6)) | G6: =IF(H6="","",MOD(H6,1)) | BN6: =IF($AQ$1="X", IF(AND(G6>=$AS$1,G6<=$AT$1),IF(P6<>"D(Arıza Değil",AC6,0),IF(AND(G6>=$AU$1,G6<=$AV$1),IF(P6<>"D:Arıza Değil",AC6,0), "x var")), "x yok") -> x var | BO6: =IF(OR(AND(G6>$AS$1,G6<$AT$1),AND(G6>$AU$1,G6<$AV$1)),"aynı gün giderilen arıza") -> FALSE | BP6: =IF(Z6-F6>0,"Bir günden fazla süren arıza",IF(OR(AND(G6>$AS$1,G6<$AT$1),AND(G6>$AU$1,G6<$AV$1)),"aynı gün giderilen arıza")) -> #VALUE! | BQ6: =(Y6-H6)*24*60 -> 0 | BR6: =(AB6-Y6)*24*60 -> 0 | BS6: =(AF6-H6)*24*60 -> 0 | CQ6: =G6 | CR6: =Y6 -> 0 | CS6: =AB6 -> 0 | CT6: =(CR6-CQ6)*1440 -> #VALUE! | CU6: =(CS6-CR6)*1440 -> 0 | CV6: =(CS6-CQ6)*1440 -> #VALUE! | CW6: =CT6/CV6 -> #VALUE!
A7: =[4]SayfaKOC!C96 -> KOC10 | B7: =[4]SayfaKOC!D96 -> 4123(5) | C7: =[4]SayfaKOC!E96 -> RB | D7: =[4]SayfaKOC!F96 -> 29846 | E7: =[4]SayfaKOC!G96 -> BOZ-KOC10-FF-095 | F7: =IF(H7="","",INT(H7)) -> 45809 | G7: =IF(H7="","",MOD(H7,1)) -> 0.25 | H7: =[4]SayfaKOC!H96 -> 45809.25 | I7: =[4]SayfaKOC!I96 -> Hat/Line | J7: =IF([4]SayfaKOC!J96="Müşteri","Notified by Customer","Notified by Bozankaya") -> Notified by Bozankaya | K7: =VLOOKUP([4]SayfaKOC!L96,Atamalar!$A$10:$B$53,2,FALSE) -> Passenger_HVAC_System | L7: =[4]SayfaKOC!X96 -> ELTESAN ELEKTRO MEKANİK SOĞUTMA SAN | M7: =A7&"-"&E7 -> KOC10-BOZ-KOC10-FF-095 | N7: =[4]SayfaKOC!M96 -> 5. ARACIN RB YOLCU KLİMA SLAVE KART ARIZASI | O7: =[4]SayfaKOC!P96 -> C-Uyarı, sürüş devamlılığı | P7: =[4]SayfaKOC!Q96 -> B(Servisten çekmeye etki eden arıza) | Q7: =[4]SayfaKOC!R96 -> N.A(Yaralanma yok) | R7: {=_xlfn.IFS([4]SayfaKOC!U96="Bozankaya","Bozankaya",[4]SayfaKOC!U96="Müşteri","Customer",[4]SayfaKOC!U96="Tedarikçi","Equipment Supplier")} -> Equipment Supplier | S7: =[4]SayfaKOC!GB96 -> ANTALYA SSH TA BULUNAN SLAVE KOCAELİ SSH A ÇEKİLİP DEĞİŞİMİ SAĞLANMIŞTIR. - ANTALYA DAN GELEN SLAVE KART İLE DEĞİŞTİRİLDİ. | T7: =[4]SayfaKOC!AD96 -> Ekipman yenisi ile değiştirildi | U7: =[4]SayfaKOC!W96 -> Evet | V7: =[4]SayfaKOC!AZ96 -> 2 | W7: =IF(Y7="","",INT(Y7)) -> 45809 | X7: =IF(Y7="","",TEXT(Y7,"ss:dd")) -> 07:30 | Y7: =[4]SayfaKOC!AE96 -> 45809.312 | Z7: =IF(AB7="","",INT(AB7)) -> 45811 | AA7: =IF(AB7="","",TEXT(AB7,"ss:dd")) -> 06:00 | AB7: =[4]SayfaKOC!BA96 -> 45811.25 | AC7: =(AF7-H7)*24*60 -> 2880 | AD7: =IF(AF7="","",INT(AF7)) -> 45811 | AE7: =IF(AF7="","",TEXT(AF7,"ss:dd")) -> 06:00 | AF7: =[4]SayfaKOC!BA96 -> 45811.25 | AG7: =[4]SayfaKOC!S96 -> (I) İlk Defa Karşılaşılan Arıza | AH7: =IF(P7="A(Hareket etmeyi engelleyen arıza)","Bu Arıza Aracın Servise Verilmesine Engel", IF(P7="B(Servisten çekmeye etki eden arıza)","Bu Arıza Aracın Servise Verilmesine Engel", IF(P7="C(Sisteme etki etmeyen arıza)","Bu Arıza Aracın Servise Verilmesine Engel Değil", IF(P7="D(Arıza Değil)","Bu Arıza Aracın Servise Verilmesine Engel Değil", "Bilinmeyen Durum")))) -> Bu Arıza Aracın Servise Verilmesine Engel | AI7: =[4]SayfaKOC!AV96 -> KOC10-HBR-25-095 | AJ7: =IF(AL7="","",INT(AL7)) | AK7: =IF(AL7="","",TEXT(AL7,"ss:dd")) | AL7: =[4]SayfaKOC!AX96 | AM7: =IF(AND(P7<>"D(Arıza Değil)",AH7="Bu Arıza Aracın Servise Verilmesine Engel Değil"),IF(Z7-F7>0,(AB7-Y7)*24*60,IF(OR(AND(G7>$AS$1,G7<$AT$1),AND(G7>$AU$1,G7<$AV$1)),(AF7-H7)*24*60,0)),AN7) -> 2880 | AN7: =IF(P7<>"D(Arıza Değil)",AC7,0) -> 2880 | AO7: =[4]SayfaKOC!AG96 -> ELTESAN ELEKTRO MEKANİK SOĞUTMA SAN | AP7: =[4]SayfaKOC!AI96 -> H500-7200 | AQ7: =[4]SayfaKOC!AQ96 | AR7: =[4]SayfaKOC!AH96 -> KLİMA UNİTESİ/Eltesan/Hispacold 41,5 KW | AS7: =[4]SayfaKOC!AJ96 | AT7: =[4]SayfaKOC!GC96 -> - | AU7: =[4]SayfaKOC!AL96 | AV7: =[4]SayfaKOC!AP96 | AW7: =[4]SayfaKOC!AT96 | AX7: =V7*AC7*BC$1 -> 63360 | AY7: =[4]SayfaKOC!BF96 | AZ7: =[4]SayfaKOC!BD96 | BB7: =IF($AQ$1="X", IF(AND(G7>=$AS$1,G7<=$AT$1),IF(P7<>"D(Arıza Değil)",AC7,0), IF(AND(G7>=$AU$1,G7<=$AV$1),IF(P7<>"D(Arıza Değil)",AC7,0), "")), "") | BK7: =[4]SayfaKOC!U96 -> Tedarikçi | BL7: =[4]SayfaKOC!V96 -> SSH | BN7: =IF($AQ$1="X", IF(AND(G7>=$AS$1,G7<=$AT$1),IF(P7<>"D(Arıza Değil",AC7,0),IF(AND(G7>=$AU$1,G7<=$AV$1),IF(P7<>"D:Arıza Değil",AC7,0), "x var")), "x yok") -> x var | BO7: =IF(OR(AND(G7>$AS$1,G7<$AT$1),AND(G7>$AU$1,G7<$AV$1)),"aynı gün giderilen arıza") -> FALSE | BP7: =IF(Z7-F7>0,"Bir günden fazla süren arıza",IF(OR(AND(G7>$AS$1,G7<$AT$1),AND(G7>$AU$1,G7<$AV$1)),"aynı gün giderilen arıza")) -> Bir günden fazla süren arıza | BQ7: =(Y7-H7)*24*60 -> 90 | BR7: =(AB7-Y7)*24*60 -> 2790 | BS7: =(AF7-H7)*24*60 -> 2880 | BV7: =COUNTIFS(B$5:B$9999,B7,H$5:H$9999,"<="&AF7,AF$5:AF$9999,">="&H7)-1 -> 0 | BW7: =IF(COUNTIFS(B$5:B$9999,B7,H$5:H$9999,"<="&AF7,AF$5:AF$9999,">="&H7)>1,"Evet, çakışma var","Hayır, çakışma yok") -> Hayır, çakışma yok | BY7: =Y7-H7 -> 0.0625 | BZ7: =AB7-Y7 -> 1.9375 | CA7: =AB7-H7 -> 2 | CE7: 95 | CF7: =H7 -> 45809.25 | CG7: =AB7 -> 45811.25 | CK7: =AB7-Y7 -> 1.9375 | CL7: =Y7-H7 -> 0.0625 | CM7: =AB7-H7 -> 2 | CQ7: =G7 -> 0.25 | CR7: =Y7 -> 45809.312 | CS7: =AB7 -> 45811.25 | CT7: =(CR7-CQ7)*1440 -> 65965050 | CU7: =(CS7-CR7)*1440 -> 2790 | CV7: =(CS7-CQ7)*1440 -> 65967840 | CW7: =CT7/CV7 -> 0.99995771
A8: =[4]SayfaKOC!C95 -> KOC10 | B8: =[4]SayfaKOC!D95 -> 4119(1) | C8: =[4]SayfaKOC!E95 -> RB | D8: =[4]SayfaKOC!F95 | E8: =[4]SayfaKOC!G95 -> BOZ-KOC10-FF-094 | F8: =IF(H8="","",INT(H8)) -> 45803 | G8: =IF(H8="","",MOD(H8,1)) -> 0.25 | H8: =[4]SayfaKOC!H95 -> 45803.25 | I8: =[4]SayfaKOC!I95 -> Hat/Line | J8: =IF([4]SayfaKOC!J95="Müşteri","Notified by Customer","Notified by Bozankaya") -> Notified by Bozankaya | K8: =VLOOKUP([4]SayfaKOC!L95,Atamalar!$A$10:$B$53,2,FALSE) -> Passenger_HVAC_System | L8: =[4]SayfaKOC!X95 -> ELTESAN ELEKTRO MEKANİK SOĞUTMA SAN | M8: =A8&"-"&E8 -> KOC10-BOZ-KOC10-FF-094 | N8: =[4]SayfaKOC!M95 -> YOLCU BÖLGESİ KLİMALARDA DRENAJLAR UYGUN DEĞİL. | O8: =[4]SayfaKOC!P95 -> C-Uyarı, sürüş devamlılığı | P8: =[4]SayfaKOC!Q95 -> B(Servisten çekmeye etki eden arıza) | Q8: =[4]SayfaKOC!R95 -> N.A(Yaralanma yok) | R8: {=_xlfn.IFS([4]SayfaKOC!U95="Bozankaya","Bozankaya",[4]SayfaKOC!U95="Müşteri","Customer",[4]SayfaKOC!U95="Tedarikçi","Equipment Supplier")} -> Equipment Supplier | S8: =[4]SayfaKOC!GB95 -> YOLCU BÖLGESİ KLİMALARDA DRENAJLARDAKİ ÖRDEK AĞIZLARI UYGUN DEĞİL. HBR YAPILIP AKSİYON ALINMALI, ARAÇ İÇİNDE YOLCUYA SU AKIYOR. - TEDARİKÇİ FİRMA TARAFINDAN DRENAJLARDAKİ ÖRDEK AĞIZLARINA REVİZYON GELMELİ. | T8: =[4]SayfaKOC!AD95 -> *Arıza çözülecek | U8: =[4]SayfaKOC!W95 | V8: =[4]SayfaKOC!AZ95 -> 2 | W8: =IF(Y8="","",INT(Y8)) -> 45804 | X8: =IF(Y8="","",TEXT(Y8,"ss:dd")) -> 09:00 | Y8: =[4]SayfaKOC!AE95 -> 45804.375 | Z8: =IF(AB8="","",INT(AB8)) | AA8: =IF(AB8="","",TEXT(AB8,"ss:dd")) | AB8: =[4]SayfaKOC!BA95 | AC8: =(AF8-H8)*24*60 -> #VALUE! | AD8: =IF(AF8="","",INT(AF8)) | AE8: =IF(AF8="","",TEXT(AF8,"ss:dd")) | AF8: =[4]SayfaKOC!BA95 | AG8: =[4]SayfaKOC!S95 -> (III) Farklı Araçlarda Tekrarlayan Arıza | AH8: =IF(P8="A(Hareket etmeyi engelleyen arıza)","Bu Arıza Aracın Servise Verilmesine Engel", IF(P8="B(Servisten çekmeye etki eden arıza)","Bu Arıza Aracın Servise Verilmesine Engel", IF(P8="C(Sisteme etki etmeyen arıza)","Bu Arıza Aracın Servise Verilmesine Engel Değil", IF(P8="D(Arıza Değil)","Bu Arıza Aracın Servise Verilmesine Engel Değil", "Bilinmeyen Durum")))) -> Bu Arıza Aracın Servise Verilmesine Engel | AI8: =[4]SayfaKOC!AV95 -> KOC10-HBR-25-094 | AJ8: =IF(AL8="","",INT(AL8)) | AK8: =IF(AL8="","",TEXT(AL8,"ss:dd")) | AL8: =[4]SayfaKOC!AX95 | AM8: =IF(AND(P8<>"D(Arıza Değil)",AH8="Bu Arıza Aracın Servise Verilmesine Engel Değil"),IF(Z8-F8>0,(AB8-Y8)*24*60,IF(OR(AND(G8>$AS$1,G8<$AT$1),AND(G8>$AU$1,G8<$AV$1)),(AF8-H8)*24*60,0)),AN8) -> #VALUE! | AN8: =IF(P8<>"D(Arıza Değil)",AC8,0) -> #VALUE! | AO8: =[4]SayfaKOC!AG95 -> ELTESAN ELEKTRO MEKANİK SOĞUTMA SAN | AP8: =[4]SayfaKOC!AI95 -> H500-7200 | AQ8: =[4]SayfaKOC!AQ95 -> - | AR8: =[4]SayfaKOC!AH95 -> KLİMA UNİTESİ/Eltesan/Hispacold 41,5 KW | AS8: =[4]SayfaKOC!AJ95 -> 1 | AT8: =[4]SayfaKOC!GC95 -> - | AU8: =[4]SayfaKOC!AL95 | AV8: =[4]SayfaKOC!AP95 | AW8: =[4]SayfaKOC!AT95 | AX8: =V8*AC8*BC$1 -> #VALUE! | AY8: =[4]SayfaKOC!BF95 | AZ8: =[4]SayfaKOC!BD95 | BB8: =IF($AQ$1="X", IF(AND(G8>=$AS$1,G8<=$AT$1),IF(P8<>"D(Arıza Değil)",AC8,0), IF(AND(G8>=$AU$1,G8<=$AV$1),IF(P8<>"D(Arıza Değil)",AC8,0), "")), "") | BK8: =[4]SayfaKOC!U95 -> Tedarikçi | BL8: =[4]SayfaKOC!V95 -> Bozankaya | BN8: =IF($AQ$1="X", IF(AND(G8>=$AS$1,G8<=$AT$1),IF(P8<>"D(Arıza Değil",AC8,0),IF(AND(G8>=$AU$1,G8<=$AV$1),IF(P8<>"D:Arıza Değil",AC8,0), "x var")), "x yok") -> x var | BO8: =IF(OR(AND(G8>$AS$1,G8<$AT$1),AND(G8>$AU$1,G8<$AV$1)),"aynı gün giderilen arıza") -> FALSE | BP8: =IF(Z8-F8>0,"Bir günden fazla süren arıza",IF(OR(AND(G8>$AS$1,G8<$AT$1),AND(G8>$AU$1,G8<$AV$1)),"aynı gün giderilen arıza")) -> #VALUE! | BQ8: =(Y8-H8)*24*60 -> 1620 | BR8: =(AB8-Y8)*24*60 -> #VALUE! | BS8: =(AF8-H8)*24*60 -> #VALUE! | BV8: =COUNTIFS(B$5:B$9999,B8,H$5:H$9999,"<="&AF8,AF$5:AF$9999,">="&H8)-1 -> -1 | BW8: =IF(COUNTIFS(B$5:B$9999,B8,H$5:H$9999,"<="&AF8,AF$5:AF$9999,">="&H8)>1,"Evet, çakışma var","Hayır, çakışma yok") -> Hayır, çakışma yok | BY8: =Y8-H8 -> 1.125 | BZ8: =AB8-Y8 -> #VALUE! | CA8: =AB8-H8 -> #VALUE! | CE8: 94 | CF8: =H8 -> 45803.25 | CG8: =AB8 | CK8: =AB8-Y8 -> #VALUE! | CL8: =Y8-H8 -> 1.125 | CM8: =AB8-H8 -> #VALUE! | CQ8: =G8 -> 0.25 | CR8: =Y8 -> 45804.375 | CS8: =AB8 | CT8: =(CR8-CQ8)*1440 -> 65957940 | CU8: =(CS8-CR8)*1440 -> #VALUE! | CV8: =(CS8-CQ8)*1440 -> #VALUE! | CW8: =CT8/CV8 -> #VALUE!
A9: =[4]SayfaKOC!C97 -> KOC10 | B9: =[4]SayfaKOC!D97 -> 4120(2) | C9: =[4]SayfaKOC!E97 -> RB | D9: =[4]SayfaKOC!F97 -> 11850 | E9: =[4]SayfaKOC!G97 -> BOZ-KOC10-FF-096 | F9: =IF(H9="","",INT(H9)) -> 45796 | G9: =IF(H9="","",MOD(H9,1)) -> 0.25 | H9: =[4]SayfaKOC!H97 -> 45796.25 | I9: =[4]SayfaKOC!I97 -> Hat/Line | J9: =IF([4]SayfaKOC!J97="Müşteri","Notified by Customer","Notified by Bozankaya") -> Notified by Bozankaya | K9: =VLOOKUP([4]SayfaKOC!L97,Atamalar!$A$10:$B$53,2,FALSE) -> Passenger_HVAC_System | L9: =[4]SayfaKOC!X97 -> ELTESAN ELEKTRO MEKANİK SOĞUTMA SAN | M9: =A9&"-"&E9 -> KOC10-BOZ-KOC10-FF-096 | N9: =[4]SayfaKOC!M97 -> RB YOLCU KLİMA KONDENSER FAN KİLİTLENMİŞ. | O9: =[4]SayfaKOC!P97 -> C-Uyarı, sürüş devamlılığı | P9: =[4]SayfaKOC!Q97 -> B(Servisten çekmeye etki eden arıza) | Q9: =[4]SayfaKOC!R97 -> N.A(Yaralanma yok) | R9: {=_xlfn.IFS([4]SayfaKOC!U97="Bozankaya","Bozankaya",[4]SayfaKOC!U97="Müşteri","Customer",[4]SayfaKOC!U97="Tedarikçi","Equipment Supplier")} -> Equipment Supplier | S9: =[4]SayfaKOC!GB97 -> ANTALYA SSH TA BULUNAN KONDENSER FAN KOCAELİ SSH A ÇEKİLİP, ELTESAN TARAFINDAN DEĞİŞİMİ SAĞLANMIŞTIR.. - ANTALYA SSH TA BULUNAN KONDENSER FAN KOCAELİ SSH A ÇEKİLİP, ELTESAN TARAFINDAN DEĞİŞİMİ SAĞLANMIŞTIR. | T9: =[4]SayfaKOC!AD97 -> Ekipman yenisi ile değiştirildi | U9: =[4]SayfaKOC!W97 -> Evet | V9: =[4]SayfaKOC!AZ97 -> 1 | W9: =IF(Y9="","",INT(Y9)) -> 45797 | X9: =IF(Y9="","",TEXT(Y9,"ss:dd")) -> 06:00 | Y9: =[4]SayfaKOC!AE97 -> 45797.25 | Z9: =IF(AB9="","",INT(AB9)) -> 45798 | AA9: =IF(AB9="","",TEXT(AB9,"ss:dd")) -> 09:00 | AB9: =[4]SayfaKOC!BA97 -> 45798.375 | AC9: =(AF9-H9)*24*60 -> 3060 | AD9: =IF(AF9="","",INT(AF9)) -> 45798 | AE9: =IF(AF9="","",TEXT(AF9,"ss:dd")) -> 09:00 | AF9: =[4]SayfaKOC!BA97 -> 45798.375 | AG9: =[4]SayfaKOC!S97 -> (I) İlk Defa Karşılaşılan Arıza | AH9: =IF(P9="A(Hareket etmeyi engelleyen arıza)","Bu Arıza Aracın Servise Verilmesine Engel", IF(P9="B(Servisten çekmeye etki eden arıza)","Bu Arıza Aracın Servise Verilmesine Engel", IF(P9="C(Sisteme etki etmeyen arıza)","Bu Arıza Aracın Servise Verilmesine Engel Değil", IF(P9="D(Arıza Değil)","Bu Arıza Aracın Servise Verilmesine Engel Değil", "Bilinmeyen Durum")))) -> Bu Arıza Aracın Servise Verilmesine Engel | AI9: =[4]SayfaKOC!AV97 -> KOC10-HBR-25-096 | AJ9: =IF(AL9="","",INT(AL9)) | AK9: =IF(AL9="","",TEXT(AL9,"ss:dd")) | AL9: =[4]SayfaKOC!AX97 | AM9: =IF(AND(P9<>"D(Arıza Değil)",AH9="Bu Arıza Aracın Servise Verilmesine Engel Değil"),IF(Z9-F9>0,(AB9-Y9)*24*60,IF(OR(AND(G9>$AS$1,G9<$AT$1),AND(G9>$AU$1,G9<$AV$1)),(AF9-H9)*24*60,0)),AN9) -> 3060 | AN9: =IF(P9<>"D(Arıza Değil)",AC9,0) -> 3060 | AO9: =[4]SayfaKOC!AG97 -> ELTESAN ELEKTRO MEKANİK SOĞUTMA SAN | AP9: =[4]SayfaKOC!AI97 -> H500-7200 | AQ9: =[4]SayfaKOC!AQ97 -> AO-3593738/2210/003 | AR9: =[4]SayfaKOC!AH97 -> KLİMA UNİTESİ/Eltesan/Hispacold 41,5 KW | AS9: =[4]SayfaKOC!AJ97 -> 1 | AT9: =[4]SayfaKOC!GC97 -> - | AU9: =[4]SayfaKOC!AL97 | AV9: =[4]SayfaKOC!AP97 | AW9: =[4]SayfaKOC!AT97 | AX9: =V9*AC9*BC$1 -> 33660 | AY9: =[4]SayfaKOC!BF97 | AZ9: =[4]SayfaKOC!BD97 | BB9: =IF($AQ$1="X", IF(AND(G9>=$AS$1,G9<=$AT$1),IF(P9<>"D(Arıza Değil)",AC9,0), IF(AND(G9>=$AU$1,G9<=$AV$1),IF(P9<>"D(Arıza Değil)",AC9,0), "")), "") | BK9: =[4]SayfaKOC!U97 -> Tedarikçi | BL9: =[4]SayfaKOC!V97 -> ELTESAN ELEKTRO MEKANİK SOĞUTMA SAN | BN9: =IF($AQ$1="X", IF(AND(G9>=$AS$1,G9<=$AT$1),IF(P9<>"D(Arıza Değil",AC9,0),IF(AND(G9>=$AU$1,G9<=$AV$1),IF(P9<>"D:Arıza Değil",AC9,0), "x var")), "x yok") -> x var | BO9: =IF(OR(AND(G9>$AS$1,G9<$AT$1),AND(G9>$AU$1,G9<$AV$1)),"aynı gün giderilen arıza") -> FALSE | BP9: =IF(Z9-F9>0,"Bir günden fazla süren arıza",IF(OR(AND(G9>$AS$1,G9<$AT$1),AND(G9>$AU$1,G9<$AV$1)),"aynı gün giderilen arıza")) -> Bir günden fazla süren arıza | BQ9: =(Y9-H9)*24*60 -> 1440 | BR9: =(AB9-Y9)*24*60 -> 1620 | BS9: =(AF9-H9)*24*60 -> 3060 | BV9: =COUNTIFS(B$5:B$9999,B9,H$5:H$9999,"<="&AF9,AF$5:AF$9999,">="&H9)-1 -> 0 | BW9: =IF(COUNTIFS(B$5:B$9999,B9,H$5:H$9999,"<="&AF9,AF$5:AF$9999,">="&H9)>1,"Evet, çakışma var","Hayır, çakışma yok") -> Hayır, çakışma yok | BY9: =Y9-H9 -> 1 | BZ9: =AB9-Y9 -> 1.125 | CA9: =AB9-H9 -> 2.125 | CE9: 96 | CF9: =H9 -> 45796.25 | CG9: =AB9 -> 45798.375 | CQ9: =G9 -> 0.25 | CR9: =Y9 -> 45797.25 | CS9: =AB9 -> 45798.375 | CT9: =(CR9-CQ9)*1440 -> 65947680 | CU9: =(CS9-CR9)*1440 -> 1620 | CV9: =(CS9-CQ9)*1440 -> 65949300 | CW9: =CT9/CV9 -> 0.99997544
A10: =[4]SayfaKOC!C94 -> KOC10 | B10: =[4]SayfaKOC!D94 -> 4123(5) | C10: =[4]SayfaKOC!E94 -> MB | D10: =[4]SayfaKOC!F94 -> 18631 | E10: =[4]SayfaKOC!G94 -> BOZ-KOC10-FF-093 | F10: =IF(H10="","",INT(H10)) -> 45735 | G10: =IF(H10="","",MOD(H10,1)) -> 0.51046296 | H10: =[4]SayfaKOC!H94 -> 45735.51 | I10: =[4]SayfaKOC!I94 -> Hat/Line | J10: =IF([4]SayfaKOC!J94="Müşteri","Notified by Customer","Notified by Bozankaya") -> Notified by Customer | K10: =VLOOKUP([4]SayfaKOC!L94,Atamalar!$A$10:$B$53,2,FALSE) -> Door_System | L10: =[4]SayfaKOC!X94 -> KNORR-BREMSE GMBH DİVİSİON IFE AUTO | M10: =A10&"-"&E10 -> KOC10-BOZ-KOC10-FF-093 | N10: =[4]SayfaKOC!M94 -> 12 NUMARALI KAPI HASSAS KENAR ARIZASI | O10: =[4]SayfaKOC!P94 -> C-Uyarı, sürüş devamlılığı | P10: =[4]SayfaKOC!Q94 -> B(Servisten çekmeye etki eden arıza) | Q10: =[4]SayfaKOC!R94 -> N.A(Yaralanma yok) | R10: {=_xlfn.IFS([4]SayfaKOC!U94="Bozankaya","Bozankaya",[4]SayfaKOC!U94="Müşteri","Customer",[4]SayfaKOC!U94="Tedarikçi","Equipment Supplier")} -> Equipment Supplier | S10: =[4]SayfaKOC!GB94 -> DCU ÜZERİNDEKİ FLASH SAYISI: 9 ARIZA AÇIKLAMASI: HASSAS KENAR. TEDARİKÇİYE BİLDİRİM YAPILACAK HASSAS KENAR DEĞİŞMELİ. - DCU ÜZERİNDEKİ FLASH SAYISI: 9 ARIZA AÇIKLAMASI: HASSAS KENAR. TEDARİKÇİYE BİLDİRİM YAPILACAK HASSAS KENAR DEĞİŞMELİ. | T10: =[4]SayfaKOC!AD94 -> Arıza çözülecek | U10: =[4]SayfaKOC!W94 -> Evet | V10: =[4]SayfaKOC!AZ94 -> 2 | W10: =IF(Y10="","",INT(Y10)) -> 45735 | X10: =IF(Y10="","",TEXT(Y10,"ss:dd")) -> 12:33 | Y10: =[4]SayfaKOC!AE94 -> 45735.523 | Z10: =IF(AB10="","",INT(AB10)) | AA10: =IF(AB10="","",TEXT(AB10,"ss:dd")) | AB10: =[4]SayfaKOC!BA94 | AC10: =(AF10-H10)*24*60 -> #VALUE! | AD10: =IF(AF10="","",INT(AF10)) | AE10: =IF(AF10="","",TEXT(AF10,"ss:dd")) | AF10: =[4]SayfaKOC!BA94 | AG10: =[4]SayfaKOC!S94 -> (I) İlk Defa Karşılaşılan Arıza | AH10: =IF(P10="A(Hareket etmeyi engelleyen arıza)","Bu Arıza Aracın Servise Verilmesine Engel", IF(P10="B(Servisten çekmeye etki eden arıza)","Bu Arıza Aracın Servise Verilmesine Engel", IF(P10="C(Sisteme etki etmeyen arıza)","Bu Arıza Aracın Servise Verilmesine Engel Değil", IF(P10="D(Arıza Değil)","Bu Arıza Aracın Servise Verilmesine Engel Değil", "Bilinmeyen Durum")))) -> Bu Arıza Aracın Servise Verilmesine Engel | AI10: =[4]SayfaKOC!AV94 -> KOC10-HBR-25-093 | AJ10: =IF(AL10="","",INT(AL10)) | AK10: =IF(AL10="","",TEXT(AL10,"ss:dd")) | AL10: =[4]SayfaKOC!AX94 | AM10: =IF(AND(P10<>"D(Arıza Değil)",AH10="Bu Arıza Aracın Servise Verilmesine Engel Değil"),IF(Z10-F10>0,(AB10-Y10)*24*60,IF(OR(AND(G10>$AS$1,G10<$AT$1),AND(G10>$AU$1,G10<$AV$1)),(AF10-H10)*24*60,0)),AN10) -> #VALUE! | AN10: =IF(P10<>"D(Arıza Değil)",AC10,0) -> #VALUE! | AO10: =[4]SayfaKOC!AG94 -> COFLE TK OTOMOTİV KONTROL SİSTEMLER | AP10: =[4]SayfaKOC!AI94 -> D125-7059 | AQ10: =[4]SayfaKOC!AQ94 | AR10: =[4]SayfaKOC!AH94 -> KUPLAJ KAPAK ACMA SOL | AS10: =[4]SayfaKOC!AJ94 | AT10: =[4]SayfaKOC!GC94 -> - | AU10: =[4]SayfaKOC!AL94 | AV10: =[4]SayfaKOC!AP94 | AW10: =[4]SayfaKOC!AT94 | AX10: =V10*AC10*BC$1 -> #VALUE! | AY10: =[4]SayfaKOC!BF94 -> 2bdb0b58 | AZ10: =[4]SayfaKOC!BD94 -> https://www.appsheet.com/Template/gettablefileurl?appname=KOC10_Failure_List-654943&tableName=SAYFA1&filename=Sayfa1_Images%2F2bdb0b58.Resim.113951.jpg | BB10: =IF($AQ$1="X", IF(AND(G10>=$AS$1,G10<=$AT$1),IF(P10<>"D(Arıza Değil)",AC10,0), IF(AND(G10>=$AU$1,G10<=$AV$1),IF(P10<>"D(Arıza Değil)",AC10,0), "")), "") | BK10: =[4]SayfaKOC!U94 -> Tedarikçi | BL10: =[4]SayfaKOC!V94 -> KNORR-BREMSE GMBH DİVİSİON IFE AUTO | BN10: =IF($AQ$1="X", IF(AND(G10>=$AS$1,G10<=$AT$1),IF(P10<>"D(Arıza Değil",AC10,0),IF(AND(G10>=$AU$1,G10<=$AV$1),IF(P10<>"D:Arıza Değil",AC10,0), "x var")), "x yok") -> x var | BO10: =IF(OR(AND(G10>$AS$1,G10<$AT$1),AND(G10>$AU$1,G10<$AV$1)),"aynı gün giderilen arıza") -> FALSE | BP10: =IF(Z10-F10>0,"Bir günden fazla süren arıza",IF(OR(AND(G10>$AS$1,G10<$AT$1),AND(G10>$AU$1,G10<$AV$1)),"aynı gün giderilen arıza")) -> #VALUE! | BQ10: =(Y10-H10)*24*60 -> 18.4 | BR10: =(AB10-Y10)*24*60 -> #VALUE! | BS10: =(AF10-H10)*24*60 -> #VALUE! | BV10: =COUNTIFS(B$5:B$9999,B10,H$5:H$9999,"<="&AF10,AF$5:AF$9999,">="&H10)-1 -> -1 | BW10: =IF(COUNTIFS(B$5:B$9999,B10,H$5:H$9999,"<="&AF10,AF$5:AF$9999,">="&H10)>1,"Evet, çakışma var","Hayır, çakışma yok") -> Hayır, çakışma yok | BY10: =Y10-H10 -> 0.012777778 | BZ10: =AB10-Y10 -> #VALUE! | CA10: =AB10-H10 -> #VALUE! | CE10: 93 | CF10: =H10 -> 45735.51 | CG10: =AB10 | CK10: =AB10-Y10 -> #VALUE! | CL10: =Y10-H10 -> 0.012777778 | CM10: =AB10-H10 -> #VALUE! | CQ10: =G10 -> 0.51046296 | CR10: =Y10 -> 45735.523 | CS10: =AB10 | CT10: =(CR10-CQ10)*1440 -> 65858418 | CU10: =(CS10-CR10)*1440 -> #VALUE! | CV10: =(CS10-CQ10)*1440 -> #VALUE! | CW10: =CT10/CV10 -> #VALUE!
A11: =[4]SayfaKOC!C92 -> KOC10 | B11: =[4]SayfaKOC!D92 -> 4121(3) | C11: =[4]SayfaKOC!E92 -> RA | D11: =[4]SayfaKOC!F92 -> 22860 | E11: =[4]SayfaKOC!G92 -> BOZ-KOC10-FF-091 | F11: =IF(H11="","",INT(H11)) -> 45716 | G11: =IF(H11="","",MOD(H11,1)) -> 0.44800926 | H11: =[4]SayfaKOC!H92 -> 45716.448 | I11: =[4]SayfaKOC!I92 -> Depo/Depot | J11: =IF([4]SayfaKOC!J92="Müşteri","Notified by Customer","Notified by Bozankaya") -> Notified by Bozankaya | K11: =VLOOKUP([4]SayfaKOC!L92,Atamalar!$A$10:$B$53,2,FALSE) -> Passenger_Information | L11: =[4]SayfaKOC!X92 -> ATAK ULAŞIM SAN.TİC.LTD.ŞTİ. | M11: =A11&"-"&E11 -> KOC10-BOZ-KOC10-FF-091 | N11: =[4]SayfaKOC!M92 -> KAPI ÜSTÜ STRETCH LCD EKRAN ARIZALI | O11: =[4]SayfaKOC!P92 -> C-Uyarı, sürüş devamlılığı | P11: =[4]SayfaKOC!Q92 -> C(Sisteme etki etmeyen arıza) | Q11: =[4]SayfaKOC!R92 -> N.A(Yaralanma yok) | R11: {=_xlfn.IFS([4]SayfaKOC!U92="Bozankaya","Bozankaya",[4]SayfaKOC!U92="Müşteri","Customer",[4]SayfaKOC!U92="Tedarikçi","Equipment Supplier")} -> Equipment Supplier | S11: =[4]SayfaKOC!GB92 -> GÜÇ SOKETİNDEN ÖLÇÜM YAPILDI ENERJİ OLDUĞU GÖRÜLDÜ SSH YEDEK MALZEMEDEN DEĞİŞİMİ SAĞLANDI, ÇALIŞIYOR. - GÜÇ SOKETİNDEN ÖLÇÜM YAPILDI ENERJİ OLDUĞU GÖRÜLDÜ SSH YEDEK MALZEMEDEN DEĞİŞİMİ SAĞLANDI, ÇALIŞIYOR. | T11: =[4]SayfaKOC!AD92 -> Ekipman değiştirilecek | U11: =[4]SayfaKOC!W92 -> Evet | V11: =[4]SayfaKOC!AZ92 -> 1 | W11: =IF(Y11="","",INT(Y11)) -> 45716 | X11: =IF(Y11="","",TEXT(Y11,"ss:dd")) -> 11:00 | Y11: =[4]SayfaKOC!AE92 -> 45716.458 | Z11: =IF(AB11="","",INT(AB11)) -> 45716 | AA11: =IF(AB11="","",TEXT(AB11,"ss:dd")) -> 11:15 | AB11: =[4]SayfaKOC!BA92 -> 45716.469 | AC11: =(AF11-H11)*24*60 -> 30.366667 | AD11: =IF(AF11="","",INT(AF11)) -> 45716 | AE11: =IF(AF11="","",TEXT(AF11,"ss:dd")) -> 11:15 | AF11: =[4]SayfaKOC!BA92 -> 45716.469 | AG11: =[4]SayfaKOC!S92 -> (II) Aynı Araçta Tekrarlayan Arıza | AH11: =IF(P11="A(Hareket etmeyi engelleyen arıza)","Bu Arıza Aracın Servise Verilmesine Engel", IF(P11="B(Servisten çekmeye etki eden arıza)","Bu Arıza Aracın Servise Verilmesine Engel", IF(P11="C(Sisteme etki etmeyen arıza)","Bu Arıza Aracın Servise Verilmesine Engel Değil", IF(P11="D(Arıza Değil)","Bu Arıza Aracın Servise Verilmesine Engel Değil", "Bilinmeyen Durum")))) -> Bu Arıza Aracın Servise Verilmesine Engel Değil | AI11: =[4]SayfaKOC!AV92 -> KOC10-HBR-25-091 | AJ11: =IF(AL11="","",INT(AL11)) | AK11: =IF(AL11="","",TEXT(AL11,"ss:dd")) | AL11: =[4]SayfaKOC!AX92 | AM11: =IF(AND(P11<>"D(Arıza Değil)",AH11="Bu Arıza Aracın Servise Verilmesine Engel Değil"),IF(Z11-F11>0,(AB11-Y11)*24*60,IF(OR(AND(G11>$AS$1,G11<$AT$1),AND(G11>$AU$1,G11<$AV$1)),(AF11-H11)*24*60,0)),AN11) -> 0 | AN11: =IF(P11<>"D(Arıza Değil)",AC11,0) -> 30.366667 | AO11: =[4]SayfaKOC!AG92 -> ATAK ULAŞIM SAN.TİC.LTD.ŞTİ. | AP11: =[4]SayfaKOC!AI92 -> E410-7003 | AQ11: =[4]SayfaKOC!AQ92 -> 2022281200046 | AR11: =[4]SayfaKOC!AH92 -> STRETCH LCD EKRAN | AS11: =[4]SayfaKOC!AJ92 -> 1 | AT11: =[4]SayfaKOC!GC92 -> - | AU11: =[4]SayfaKOC!AL92 | AV11: =[4]SayfaKOC!AP92 | AW11: =[4]SayfaKOC!AT92 | AX11: =V11*AC11*BC$1 -> 334.03333 | AY11: =[4]SayfaKOC!BF92 -> 7f61ba8d | AZ11: =[4]SayfaKOC!BD92 -> https://www.appsheet.com/Template/gettablefileurl?appname=KOC10_Failure_List-654943&tableName=SAYFA1&filename=Sayfa1_Images%2F7f61ba8d.Resim.113918.jpg | BB11: =IF($AQ$1="X", IF(AND(G11>=$AS$1,G11<=$AT$1),IF(P11<>"D(Arıza Değil)",AC11,0), IF(AND(G11>=$AU$1,G11<=$AV$1),IF(P11<>"D(Arıza Değil)",AC11,0), "")), "") | BK11: =[4]SayfaKOC!U92 -> Tedarikçi | BL11: =[4]SayfaKOC!V92 -> ATAK ULAŞIM SAN.TİC.LTD.ŞTİ. | BN11: =IF($AQ$1="X", IF(AND(G11>=$AS$1,G11<=$AT$1),IF(P11<>"D(Arıza Değil",AC11,0),IF(AND(G11>=$AU$1,G11<=$AV$1),IF(P11<>"D:Arıza Değil",AC11,0), "x var")), "x yok") -> x var | BO11: =IF(OR(AND(G11>$AS$1,G11<$AT$1),AND(G11>$AU$1,G11<$AV$1)),"aynı gün giderilen arıza") -> FALSE | BP11: =IF(Z11-F11>0,"Bir günden fazla süren arıza",IF(OR(AND(G11>$AS$1,G11<$AT$1),AND(G11>$AU$1,G11<$AV$1)),"aynı gün giderilen arıza")) -> FALSE | BQ11: =(Y11-H11)*24*60 -> 14.95 | BR11: =(AB11-Y11)*24*60 -> 15.416667 | BS11: =(AF11-H11)*24*60 -> 30.366667 | BV11: =COUNTIFS(B$5:B$9999,B11,H$5:H$9999,"<="&AF11,AF$5:AF$9999,">="&H11)-1 -> 0 | BW11: =IF(COUNTIFS(B$5:B$9999,B11,H$5:H$9999,"<="&AF11,AF$5:AF$9999,">="&H11)>1,"Evet, çakışma var","Hayır, çakışma yok") -> Hayır, çakışma yok | BY11: =Y11-H11 -> 0.010381944 | BZ11: =AB11-Y11 -> 0.010706019 | CA11: =AB11-H11 -> 0.021087963 | CE11: 91 | CF11: =H11 -> 45716.448 | CG11: =AB11 -> 45716.469 | CK11: =AB11-Y11 -> 0.010706019 | CL11: =Y11-H11 -> 0.010381944 | CM11: =AB11-H11 -> 0.021087963 | CQ11: =G11 -> 0.44800926 | CR11: =Y11 -> 45716.458 | CS11: =AB11 -> 45716.469 | CT11: =(CR11-CQ11)*1440 -> 65831055 | CU11: =(CS11-CR11)*1440 -> 15.416667 | CV11: =(CS11-CQ11)*1440 -> 65831070 | CW11: =CT11/CV11 -> 0.99999977
A12: =[4]SayfaKOC!C93 -> KOC10 | B12: =[4]SayfaKOC!D93 -> 4123(5) | C12: =[4]SayfaKOC!E93 -> MB | D12: =[4]SayfaKOC!F93 -> 15435 | E12: =[4]SayfaKOC!G93 -> BOZ-KOC10-FF-092 | F12: =IF(H12="","",INT(H12)) -> 45716 | G12: =IF(H12="","",MOD(H12,1)) -> 0.56302083 | H12: =[4]SayfaKOC!H93 -> 45716.563 | I12: =[4]SayfaKOC!I93 -> Hat/Line | J12: =IF([4]SayfaKOC!J93="Müşteri","Notified by Customer","Notified by Bozankaya") -> Notified by Customer | K12: =VLOOKUP([4]SayfaKOC!L93,Atamalar!$A$10:$B$53,2,FALSE) -> Passenger_Information | L12: =[4]SayfaKOC!X93 -> ATAK ULAŞIM SAN.TİC.LTD.ŞTİ. | M12: =A12&"-"&E12 -> KOC10-BOZ-KOC10-FF-092 | N12: =[4]SayfaKOC!M93 -> SÜRÜCÜ ARKASI LED EKRAN ARIZALI | O12: =[4]SayfaKOC!P93 -> C-Uyarı, sürüş devamlılığı | P12: =[4]SayfaKOC!Q93 -> C(Sisteme etki etmeyen arıza) | Q12: =[4]SayfaKOC!R93 -> N.A(Yaralanma yok) | R12: {=_xlfn.IFS([4]SayfaKOC!U93="Bozankaya","Bozankaya",[4]SayfaKOC!U93="Müşteri","Customer",[4]SayfaKOC!U93="Tedarikçi","Equipment Supplier")} -> Equipment Supplier | S12: =[4]SayfaKOC!GB93 -> GÜÇ SOKETİNDEN ENERJİ ÖLÇÜMÜ YAPILDI VOLTAJ GÖRÜLDÜ, EKİPMAN SSH YEDEK MALZEMEDEN DEĞİŞTİRİLDİ, ÇALIŞIYOR. - GÜÇ SOKETİNDEN ENERJİ ÖLÇÜMÜ YAPILDI VOLTAJ GÖRÜLDÜ, EKİPMAN SSH YEDEK MALZEMEDEN DEĞİŞTİRİLDİ, ÇALIŞIYOR. | T12: =[4]SayfaKOC!AD93 -> Ekipman değiştirilecek | U12: =[4]SayfaKOC!W93 -> Evet | V12: =[4]SayfaKOC!AZ93 -> 1 | W12: =IF(Y12="","",INT(Y12)) -> 45716 | X12: =IF(Y12="","",TEXT(Y12,"ss:dd")) -> 13:40 | Y12: =[4]SayfaKOC!AE93 -> 45716.57 | Z12: =IF(AB12="","",INT(AB12)) -> 45716 | AA12: =IF(AB12="","",TEXT(AB12,"ss:dd")) -> 14:10 | AB12: =[4]SayfaKOC!BA93 -> 45716.59 | AC12: =(AF12-H12)*24*60 -> 39.416667 | AD12: =IF(AF12="","",INT(AF12)) -> 45716 | AE12: =IF(AF12="","",TEXT(AF12,"ss:dd")) -> 14:10 | AF12: =[4]SayfaKOC!BA93 -> 45716.59 | AG12: =[4]SayfaKOC!S93 -> (II) Aynı Araçta Tekrarlayan Arıza | AH12: =IF(P12="A(Hareket etmeyi engelleyen arıza)","Bu Arıza Aracın Servise Verilmesine Engel", IF(P12="B(Servisten çekmeye etki eden arıza)","Bu Arıza Aracın Servise Verilmesine Engel", IF(P12="C(Sisteme etki etmeyen arıza)","Bu Arıza Aracın Servise Verilmesine Engel Değil", IF(P12="D(Arıza Değil)","Bu Arıza Aracın Servise Verilmesine Engel Değil", "Bilinmeyen Durum")))) -> Bu Arıza Aracın Servise Verilmesine Engel Değil | AI12: =[4]SayfaKOC!AV93 -> KOC10-HBR-25-092 | AJ12: =IF(AL12="","",INT(AL12)) | AK12: =IF(AL12="","",TEXT(AL12,"ss:dd")) | AL12: =[4]SayfaKOC!AX93 | AM12: =IF(AND(P12<>"D(Arıza Değil)",AH12="Bu Arıza Aracın Servise Verilmesine Engel Değil"),IF(Z12-F12>0,(AB12-Y12)*24*60,IF(OR(AND(G12>$AS$1,G12<$AT$1),AND(G12>$AU$1,G12<$AV$1)),(AF12-H12)*24*60,0)),AN12) -> 0 | AN12: =IF(P12<>"D(Arıza Değil)",AC12,0) -> 39.416667 | AO12: =[4]SayfaKOC!AG93 -> ATAK ULAŞIM SAN.TİC.LTD.ŞTİ. | AP12: =[4]SayfaKOC!AI93 -> E840-7100 | AQ12: =[4]SayfaKOC!AQ93 -> I100071002 | AR12: =[4]SayfaKOC!AH93 -> SÜRÜCÜ ARKASI LED ERKAN | AS12: =[4]SayfaKOC!AJ93 -> 1 | AT12: =[4]SayfaKOC!GC93 -> - | AU12: =[4]SayfaKOC!AL93 | AV12: =[4]SayfaKOC!AP93 | AW12: =[4]SayfaKOC!AT93 | AX12: =V12*AC12*BC$1 -> 433.58333 | AY12: =[4]SayfaKOC!BF93 -> 14819750 | AZ12: =[4]SayfaKOC!BD93 -> https://www.appsheet.com/Template/gettablefileurl?appname=KOC10_Failure_List-654943&tableName=SAYFA1&filename=Sayfa1_Images%2F14819750.Resim.114645.jpg | BB12: =IF($AQ$1="X", IF(AND(G12>=$AS$1,G12<=$AT$1),IF(P12<>"D(Arıza Değil)",AC12,0), IF(AND(G12>=$AU$1,G12<=$AV$1),IF(P12<>"D(Arıza Değil)",AC12,0), "")), "") | BK12: =[4]SayfaKOC!U93 -> Tedarikçi | BL12: =[4]SayfaKOC!V93 -> ATAK ULAŞIM SAN.TİC.LTD.ŞTİ. | BN12: =IF($AQ$1="X", IF(AND(G12>=$AS$1,G12<=$AT$1),IF(P12<>"D(Arıza Değil",AC12,0),IF(AND(G12>=$AU$1,G12<=$AV$1),IF(P12<>"D:Arıza Değil",AC12,0), "x var")), "x yok") -> x var | BO12: =IF(OR(AND(G12>$AS$1,G12<$AT$1),AND(G12>$AU$1,G12<$AV$1)),"aynı gün giderilen arıza") -> FALSE | BP12: =IF(Z12-F12>0,"Bir günden fazla süren arıza",IF(OR(AND(G12>$AS$1,G12<$AT$1),AND(G12>$AU$1,G12<$AV$1)),"aynı gün giderilen arıza")) -> FALSE | BQ12: =(Y12-H12)*24*60 -> 10.133333 | BR12: =(AB12-Y12)*24*60 -> 29.283333 | BS12: =(AF12-H12)*24*60 -> 39.416667 | BV12: =COUNTIFS(B$5:B$9999,B12,H$5:H$9999,"<="&AF12,AF$5:AF$9999,">="&H12)-1 -> 0 | BW12: =IF(COUNTIFS(B$5:B$9999,B12,H$5:H$9999,"<="&AF12,AF$5:AF$9999,">="&H12)>1,"Evet, çakışma var","Hayır, çakışma yok") -> Hayır, çakışma yok | BY12: =Y12-H12 -> 0.0070370371 | BZ12: =AB12-Y12 -> 0.020335648 | CA12: =AB12-H12 -> 0.027372685 | CE12: 92 | CF12: =H12 -> 45716.563 | CG12: =AB12 -> 45716.59 | CK12: =AB12-Y12 -> 0.020335648 | CL12: =Y12-H12 -> 0.0070370371 | CM12: =AB12-H12 -> 0.027372685 | CQ12: =G12 -> 0.56302083 | CR12: =Y12 -> 45716.57 | CS12: =AB12 -> 45716.59 | CT12: =(CR12-CQ12)*1440 -> 65831050 | CU12: =(CS12-CR12)*1440 -> 29.283333 | CV12: =(CS12-CQ12)*1440 -> 65831079 | CW12: =CT12/CV12 -> 0.99999956
A13: =[4]SayfaKOC!C91 -> KOC10 | B13: =[4]SayfaKOC!D91 -> 4120(2) | C13: =[4]SayfaKOC!E91 -> RA | D13: =[4]SayfaKOC!F91 -> 1221 | E13: =[4]SayfaKOC!G91 -> BOZ-KOC10-FF-090 | F13: =IF(H13="","",INT(H13)) -> 45715 | G13: =IF(H13="","",MOD(H13,1)) -> 0.45876157 | H13: =[4]SayfaKOC!H91 -> 45715.459 | I13: =[4]SayfaKOC!I91 -> Depo/Depot | J13: =IF([4]SayfaKOC!J91="Müşteri","Notified by Customer","Notified by Bozankaya") -> Notified by Bozankaya | K13: =VLOOKUP([4]SayfaKOC!L91,Atamalar!$A$10:$B$53,2,FALSE) -> Passenger_Information | L13: =[4]SayfaKOC!X91 -> ATAK ULAŞIM SAN.TİC.LTD.ŞTİ. | M13: =A13&"-"&E13 -> KOC10-BOZ-KOC10-FF-090 | N13: =[4]SayfaKOC!M91 -> 18,5 İNÇ REKLAM EKRANI ARIZALI | O13: =[4]SayfaKOC!P91 -> C-Uyarı, sürüş devamlılığı | P13: =[4]SayfaKOC!Q91 -> C(Sisteme etki etmeyen arıza) | Q13: =[4]SayfaKOC!R91 -> N.A(Yaralanma yok) | R13: {=_xlfn.IFS([4]SayfaKOC!U91="Bozankaya","Bozankaya",[4]SayfaKOC!U91="Müşteri","Customer",[4]SayfaKOC!U91="Tedarikçi","Equipment Supplier")} -> Equipment Supplier | S13: =[4]SayfaKOC!GB91 -> GÜÇ SOKETİNDEN ÖLÇÜM YAPILDI SORUN OLMADIĞI GÖRÜLDÜ, SSH YEDEK MALZEMEDEN DEĞİŞİMİ SAĞLANDI. - GÜÇ SOKETİNDEN ÖLÇÜM YAPILDI SORUN OLMADIĞI GÖRÜLDÜ, SSH YEDEK MALZEMEDEN DEĞİŞİMİ SAĞLANDI. | T13: =[4]SayfaKOC!AD91 -> Ekipman değiştirilecek | U13: =[4]SayfaKOC!W91 -> Evet | V13: =[4]SayfaKOC!AZ91 -> 2 | W13: =IF(Y13="","",INT(Y13)) -> 45717 | X13: =IF(Y13="","",TEXT(Y13,"ss:dd")) -> 11:10 | Y13: =[4]SayfaKOC!AE91 -> 45717.466 | Z13: =IF(AB13="","",INT(AB13)) -> 45715 | AA13: =IF(AB13="","",TEXT(AB13,"ss:dd")) -> 11:55 | AB13: =[4]SayfaKOC!BA91 -> 45715.497 | AC13: =(AF13-H13)*24*60 -> 54.383333 | AD13: =IF(AF13="","",INT(AF13)) -> 45715 | AE13: =IF(AF13="","",TEXT(AF13,"ss:dd")) -> 11:55 | AF13: =[4]SayfaKOC!BA91 -> 45715.497 | AG13: =[4]SayfaKOC!S91 -> (II) Aynı Araçta Tekrarlayan Arıza | AH13: =IF(P13="A(Hareket etmeyi engelleyen arıza)","Bu Arıza Aracın Servise Verilmesine Engel", IF(P13="B(Servisten çekmeye etki eden arıza)","Bu Arıza Aracın Servise Verilmesine Engel", IF(P13="C(Sisteme etki etmeyen arıza)","Bu Arıza Aracın Servise Verilmesine Engel Değil", IF(P13="D(Arıza Değil)","Bu Arıza Aracın Servise Verilmesine Engel Değil", "Bilinmeyen Durum")))) -> Bu Arıza Aracın Servise Verilmesine Engel Değil | AI13: =[4]SayfaKOC!AV91 -> KOC10-HBR-25-090 | AJ13: =IF(AL13="","",INT(AL13)) | AK13: =IF(AL13="","",TEXT(AL13,"ss:dd")) | AL13: =[4]SayfaKOC!AX91 | AM13: =IF(AND(P13<>"D(Arıza Değil)",AH13="Bu Arıza Aracın Servise Verilmesine Engel Değil"),IF(Z13-F13>0,(AB13-Y13)*24*60,IF(OR(AND(G13>$AS$1,G13<$AT$1),AND(G13>$AU$1,G13<$AV$1)),(AF13-H13)*24*60,0)),AN13) -> 0 | AN13: =IF(P13<>"D(Arıza Değil)",AC13,0) -> 54.383333 | AO13: =[4]SayfaKOC!AG91 -> ATAK ULAŞIM SAN.TİC.LTD.ŞTİ. | AP13: =[4]SayfaKOC!AI91 -> E840-7084 | AQ13: =[4]SayfaKOC!AQ91 -> YAZILACAK | AR13: =[4]SayfaKOC!AH91 -> 18,5 INÇ EKRAN | AS13: =[4]SayfaKOC!AJ91 -> 1 | AT13: =[4]SayfaKOC!GC91 -> - | AU13: =[4]SayfaKOC!AL91 | AV13: =[4]SayfaKOC!AP91 | AW13: =[4]SayfaKOC!AT91 | AX13: =V13*AC13*BC$1 -> 1196.4333 | AY13: =[4]SayfaKOC!BF91 -> 2869544e | AZ13: =[4]SayfaKOC!BD91 -> https://www.appsheet.com/Template/gettablefileurl?appname=KOC10_Failure_List-654943&tableName=SAYFA1&filename=Sayfa1_Images%2F2869544e.Resim.113307.jpg | BB13: =IF($AQ$1="X", IF(AND(G13>=$AS$1,G13<=$AT$1),IF(P13<>"D(Arıza Değil)",AC13,0), IF(AND(G13>=$AU$1,G13<=$AV$1),IF(P13<>"D(Arıza Değil)",AC13,0), "")), "") | BK13: =[4]SayfaKOC!U91 -> Tedarikçi | BL13: =[4]SayfaKOC!V91 -> ATAK ULAŞIM SAN.TİC.LTD.ŞTİ. | BN13: =IF($AQ$1="X", IF(AND(G13>=$AS$1,G13<=$AT$1),IF(P13<>"D(Arıza Değil",AC13,0),IF(AND(G13>=$AU$1,G13<=$AV$1),IF(P13<>"D:Arıza Değil",AC13,0), "x var")), "x yok") -> x var | BO13: =IF(OR(AND(G13>$AS$1,G13<$AT$1),AND(G13>$AU$1,G13<$AV$1)),"aynı gün giderilen arıza") -> FALSE | BP13: =IF(Z13-F13>0,"Bir günden fazla süren arıza",IF(OR(AND(G13>$AS$1,G13<$AT$1),AND(G13>$AU$1,G13<$AV$1)),"aynı gün giderilen arıza")) -> FALSE | BQ13: =(Y13-H13)*24*60 -> 2890.1333 | BR13: =(AB13-Y13)*24*60 -> -2835.75 | BS13: =(AF13-H13)*24*60 -> 54.383333 | BV13: =COUNTIFS(B$5:B$9999,B13,H$5:H$9999,"<="&AF13,AF$5:AF$9999,">="&H13)-1 -> 0 | BW13: =IF(COUNTIFS(B$5:B$9999,B13,H$5:H$9999,"<="&AF13,AF$5:AF$9999,">="&H13)>1,"Evet, çakışma var","Hayır, çakışma yok") -> Hayır, çakışma yok | BY13: =Y13-H13 -> 2.007037 | BZ13: =AB13-Y13 -> -1.9692708 | CA13: =AB13-H13 -> 0.037766204 | CE13: 90 | CF13: =H13 -> 45715.459 | CG13: =AB13 -> 45715.497 | CK13: =AB13-Y13 -> -1.9692708 | CL13: =Y13-H13 -> 2.007037 | CM13: =AB13-H13 -> 0.037766204 | CO13: =AC13 -> 54.383333 | CP13: =CU13/24 -> -118.15625 | CQ13: =G13 -> 0.45876157 | CR13: =Y13 -> 45717.466 | CS13: =AB13 -> 45715.497 | CT13: =(CR13-CQ13)*1440 -> 65832490 | CU13: =(CS13-CR13)*1440 -> -2835.75 | CV13: =(CS13-CQ13)*1440 -> 65829654 | CW13: =CT13/CV13 -> 1.0000431
A14: =[4]SayfaKOC!C90 -> KOC10 | B14: =[4]SayfaKOC!D90 -> 4123(5) | C14: =[4]SayfaKOC!E90 -> MA , MB | D14: =[4]SayfaKOC!F90 -> 15214 | E14: =[4]SayfaKOC!G90 -> BOZ-KOC10-FF-089 | F14: =IF(H14="","",INT(H14)) -> 45713 | G14: =IF(H14="","",MOD(H14,1)) -> 0.38335648 | H14: =[4]SayfaKOC!H90 -> 45713.383 | I14: =[4]SayfaKOC!I90 -> Hat/Line | J14: =IF([4]SayfaKOC!J90="Müşteri","Notified by Customer","Notified by Bozankaya") -> Notified by Bozankaya | K14: =VLOOKUP([4]SayfaKOC!L90,Atamalar!$A$10:$B$53,2,FALSE) -> Passenger_Information | L14: =[4]SayfaKOC!X90 -> ATAK ULAŞIM SAN.TİC.LTD.ŞTİ. | M14: =A14&"-"&E14 -> KOC10-BOZ-KOC10-FF-089 | N14: =[4]SayfaKOC!M90 -> 1-2 ve 11-12 KAPI ÜSTÜ STRETCH LCD EKRANLARIN SİGORTALARI ATIYOR. | O14: =[4]SayfaKOC!P90 -> C-Uyarı, sürüş devamlılığı | P14: =[4]SayfaKOC!Q90 -> C(Sisteme etki etmeyen arıza) | Q14: =[4]SayfaKOC!R90 -> N.A(Yaralanma yok) | R14: {=_xlfn.IFS([4]SayfaKOC!U90="Bozankaya","Bozankaya",[4]SayfaKOC!U90="Müşteri","Customer",[4]SayfaKOC!U90="Tedarikçi","Equipment Supplier")} -> Bozankaya | S14: =[4]SayfaKOC!GB90 -> SİGORTALAR KALDIRILIYOR, FAKAT DURUMU NİHAİ ÇÖZÜME KAVUŞTURMALIYIZ BU SEBEPLE HBR Sİ OLUŞTURULUP İLGİLİ BİRİME İLETİLMELİ. - ATAN SİGORTA SÜRÜCÜ KABİNDEN KALDIRILDI. | T14: =[4]SayfaKOC!AD90 -> Arıza çözülecek | U14: =[4]SayfaKOC!W90 -> Evet | V14: =[4]SayfaKOC!AZ90 -> 1 | W14: =IF(Y14="","",INT(Y14)) -> 45714 | X14: =IF(Y14="","",TEXT(Y14,"ss:dd")) -> 09:15 | Y14: =[4]SayfaKOC!AE90 -> 45714.386 | Z14: =IF(AB14="","",INT(AB14)) -> 45714 | AA14: =IF(AB14="","",TEXT(AB14,"ss:dd")) -> 09:22 | AB14: =[4]SayfaKOC!BA90 -> 45714.391 | AC14: =(AF14-H14)*24*60 -> 1450.7 | AD14: =IF(AF14="","",INT(AF14)) -> 45714 | AE14: =IF(AF14="","",TEXT(AF14,"ss:dd")) -> 09:22 | AF14: =[4]SayfaKOC!BA90 -> 45714.391 | AG14: =[4]SayfaKOC!S90 -> (II) Aynı Araçta Tekrarlayan Arıza | AH14: =IF(P14="A(Hareket etmeyi engelleyen arıza)","Bu Arıza Aracın Servise Verilmesine Engel", IF(P14="B(Servisten çekmeye etki eden arıza)","Bu Arıza Aracın Servise Verilmesine Engel", IF(P14="C(Sisteme etki etmeyen arıza)","Bu Arıza Aracın Servise Verilmesine Engel Değil", IF(P14="D(Arıza Değil)","Bu Arıza Aracın Servise Verilmesine Engel Değil", "Bilinmeyen Durum")))) -> Bu Arıza Aracın Servise Verilmesine Engel Değil | AI14: =[4]SayfaKOC!AV90 -> KOC10-HBR-25-089 | AJ14: =IF(AL14="","",INT(AL14)) | AK14: =IF(AL14="","",TEXT(AL14,"ss:dd")) | AL14: =[4]SayfaKOC!AX90 | AM14: =IF(AND(P14<>"D(Arıza Değil)",AH14="Bu Arıza Aracın Servise Verilmesine Engel Değil"),IF(Z14-F14>0,(AB14-Y14)*24*60,IF(OR(AND(G14>$AS$1,G14<$AT$1),AND(G14>$AU$1,G14<$AV$1)),(AF14-H14)*24*60,0)),AN14) -> 7.1499999 | AN14: =IF(P14<>"D(Arıza Değil)",AC14,0) -> 1450.7 | AO14: =[4]SayfaKOC!AG90 -> ATAK ULAŞIM SAN.TİC.LTD.ŞTİ. | AP14: =[4]SayfaKOC!AI90 -> E410-7003 | AQ14: =[4]SayfaKOC!AQ90 -> - | AR14: =[4]SayfaKOC!AH90 -> STRETCH LCD EKRAN | AS14: =[4]SayfaKOC!AJ90 -> 2 | AT14: =[4]SayfaKOC!GC90 -> - | AU14: =[4]SayfaKOC!AL90 | AV14: =[4]SayfaKOC!AP90 | AW14: =[4]SayfaKOC!AT90 | AX14: =V14*AC14*BC$1 -> 15957.7 | AY14: =[4]SayfaKOC!BF90 -> 8585b05a | AZ14: =[4]SayfaKOC!BD90 -> https://www.appsheet.com/Template/gettablefileurl?appname=KOC10_Failure_List-654943&tableName=SAYFA1&filename=Sayfa1_Images%2F8585b05a.Resim.062018.jpg | BB14: =IF($AQ$1="X", IF(AND(G14>=$AS$1,G14<=$AT$1),IF(P14<>"D(Arıza Değil)",AC14,0), IF(AND(G14>=$AU$1,G14<=$AV$1),IF(P14<>"D(Arıza Değil)",AC14,0), "")), "") | BK14: =[4]SayfaKOC!U90 -> Bozankaya | BL14: =[4]SayfaKOC!V90 -> Üretim | BN14: =IF($AQ$1="X", IF(AND(G14>=$AS$1,G14<=$AT$1),IF(P14<>"D(Arıza Değil",AC14,0),IF(AND(G14>=$AU$1,G14<=$AV$1),IF(P14<>"D:Arıza Değil",AC14,0), "x var")), "x yok") -> x var | BO14: =IF(OR(AND(G14>$AS$1,G14<$AT$1),AND(G14>$AU$1,G14<$AV$1)),"aynı gün giderilen arıza") -> FALSE | BP14: =IF(Z14-F14>0,"Bir günden fazla süren arıza",IF(OR(AND(G14>$AS$1,G14<$AT$1),AND(G14>$AU$1,G14<$AV$1)),"aynı gün giderilen arıza")) -> Bir günden fazla süren arıza | BQ14: =(Y14-H14)*24*60 -> 1443.55 | BR14: =(AB14-Y14)*24*60 -> 7.1499999 | BS14: =(AF14-H14)*24*60 -> 1450.7 | BV14: =COUNTIFS(B$5:B$9999,B14,H$5:H$9999,"<="&AF14,AF$5:AF$9999,">="&H14)-1 -> 0 | BW14: =IF(COUNTIFS(B$5:B$9999,B14,H$5:H$9999,"<="&AF14,AF$5:AF$9999,">="&H14)>1,"Evet, çakışma var","Hayır, çakışma yok") -> Hayır, çakışma yok | BY14: =Y14-H14 -> 1.0024653 | BZ14: =AB14-Y14 -> 0.0049652777 | CA14: =AB14-H14 -> 1.0074306 | CE14: 89 | CF14: =H14 -> 45713.383 | CG14: =AB14 -> 45714.391 | CK14: =AB14-Y14 -> 0.0049652777 | CL14: =Y14-H14 -> 1.0024653 | CM14: =AB14-H14 -> 1.0074306 | CQ14: =G14 -> 0.38335648 | CR14: =Y14 -> 45714.386 | CS14: =AB14 -> 45714.391 | CT14: =(CR14-CQ14)*1440 -> 65828164 | CU14: =(CS14-CR14)*1440 -> 7.1499999 | CV14: =(CS14-CQ14)*1440 -> 65828171 | CW14: =CT14/CV14 -> 0.99999989
A15: =[4]SayfaKOC!C89 -> KOC10 | B15: =[4]SayfaKOC!D89 -> 4120(2) | C15: =[4]SayfaKOC!E89 -> MA | D15: =[4]SayfaKOC!F89 -> 195 | E15: =[4]SayfaKOC!G89 -> BOZ-KOC10-FF-088 | F15: =IF(H15="","",INT(H15)) -> 45681 | G15: =IF(H15="","",MOD(H15,1)) -> 0.43756944 | H15: =[4]SayfaKOC!H89 -> 45681.438 | I15: =[4]SayfaKOC!I89 -> Depo/Depot | J15: =IF([4]SayfaKOC!J89="Müşteri","Notified by Customer","Notified by Bozankaya") -> Notified by Bozankaya | K15: =VLOOKUP([4]SayfaKOC!L89,Atamalar!$A$10:$B$53,2,FALSE) -> Passenger_Information | L15: =[4]SayfaKOC!X89 -> ELTESAN ELEKTRO MEKANİK SOĞUTMA SAN | M15: =A15&"-"&E15 -> KOC10-BOZ-KOC10-FF-088 | N15: =[4]SayfaKOC!M89 -> NVR KAYIT CİHAZININ İGNATİON UCUNUN (JE1023.01) KABİN AKTİFE BAĞLI OLMASI | O15: =[4]SayfaKOC!P89 -> C-Uyarı, sürüş devamlılığı | P15: =[4]SayfaKOC!Q89 -> C(Sisteme etki etmeyen arıza) | Q15: =[4]SayfaKOC!R89 -> N.A(Yaralanma yok) | R15: {=_xlfn.IFS([4]SayfaKOC!U89="Bozankaya","Bozankaya",[4]SayfaKOC!U89="Müşteri","Customer",[4]SayfaKOC!U89="Tedarikçi","Equipment Supplier")} -> Bozankaya | S15: =[4]SayfaKOC!GB89 -> HBR OLUŞTURULARAK İGNATİON UCUNUN (JE1023.01) KABİN AKTİF KISMINDAN ALINIP SÜREKLİ ÇALIŞAN KLEMENS GRUBUNA ALINMASI. - HBR OLUŞTURULARAK İGNATİON UCUNUN (JE1023.01) KABİN AKTİF KISMINDAN ALINIP SÜREKLİ ÇALIŞAN KLEMENS GRUBUNA ALINMASI. | T15: =[4]SayfaKOC!AD89 -> Arıza çözülecek | U15: =[4]SayfaKOC!W89 -> Evet | V15: =[4]SayfaKOC!AZ89 -> 1 | W15: =IF(Y15="","",INT(Y15)) -> 45681 | X15: =IF(Y15="","",TEXT(Y15,"ss:dd")) -> 10:45 | Y15: =[4]SayfaKOC!AE89 -> 45681.448 | Z15: =IF(AB15="","",INT(AB15)) | AA15: =IF(AB15="","",TEXT(AB15,"ss:dd")) | AB15: =[4]SayfaKOC!BA89 | AC15: =(AF15-H15)*24*60 -> #VALUE! | AD15: =IF(AF15="","",INT(AF15)) | AE15: =IF(AF15="","",TEXT(AF15,"ss:dd")) | AF15: =[4]SayfaKOC!BA89 | AG15: =[4]SayfaKOC!S89 -> (I) İlk Defa Karşılaşılan Arıza | AH15: =IF(P15="A(Hareket etmeyi engelleyen arıza)","Bu Arıza Aracın Servise Verilmesine Engel", IF(P15="B(Servisten çekmeye etki eden arıza)","Bu Arıza Aracın Servise Verilmesine Engel", IF(P15="C(Sisteme etki etmeyen arıza)","Bu Arıza Aracın Servise Verilmesine Engel Değil", IF(P15="D(Arıza Değil)","Bu Arıza Aracın Servise Verilmesine Engel Değil", "Bilinmeyen Durum")))) -> Bu Arıza Aracın Servise Verilmesine Engel Değil | AI15: =[4]SayfaKOC!AV89 -> KOC10-HBR-25-088 | AJ15: =IF(AL15="","",INT(AL15)) | AK15: =IF(AL15="","",TEXT(AL15,"ss:dd")) | AL15: =[4]SayfaKOC!AX89 | AM15: =IF(AND(P15<>"D(Arıza Değil)",AH15="Bu Arıza Aracın Servise Verilmesine Engel Değil"),IF(Z15-F15>0,(AB15-Y15)*24*60,IF(OR(AND(G15>$AS$1,G15<$AT$1),AND(G15>$AU$1,G15<$AV$1)),(AF15-H15)*24*60,0)),AN15) -> #VALUE! | AN15: =IF(P15<>"D(Arıza Değil)",AC15,0) -> #VALUE! | AO15: =[4]SayfaKOC!AG89 -> ELTESAN ELEKTRO MEKANİK SOĞUTMA SAN | AP15: =[4]SayfaKOC!AI89 -> 0 | AQ15: =[4]SayfaKOC!AQ89 -> AO-3593738/2210/003 | AR15: =[4]SayfaKOC!AH89 -> 0 | AS15: =[4]SayfaKOC!AJ89 -> 1 | AT15: =[4]SayfaKOC!GC89 -> - | AU15: =[4]SayfaKOC!AL89 | AV15: =[4]SayfaKOC!AP89 | AW15: =[4]SayfaKOC!AT89 | AX15: =V15*AC15*BC$1 -> #VALUE! | AY15: =[4]SayfaKOC!BF89 -> dd5feef8 | AZ15: =[4]SayfaKOC!BD89 -> https://www.appsheet.com/Template/gettablefileurl?appname=KOC10_Failure_List-654943&tableName=SAYFA1&filename=Sayfa1_Images%2Fdd5feef8.Resim.073924.png | BB15: =IF($AQ$1="X", IF(AND(G15>=$AS$1,G15<=$AT$1),IF(P15<>"D(Arıza Değil)",AC15,0), IF(AND(G15>=$AU$1,G15<=$AV$1),IF(P15<>"D(Arıza Değil)",AC15,0), "")), "") | BK15: =[4]SayfaKOC!U89 -> Bozankaya | BL15: =[4]SayfaKOC!V89 -> Üretim | BN15: =IF($AQ$1="X", IF(AND(G15>=$AS$1,G15<=$AT$1),IF(P15<>"D(Arıza Değil",AC15,0),IF(AND(G15>=$AU$1,G15<=$AV$1),IF(P15<>"D:Arıza Değil",AC15,0), "x var")), "x yok") -> x var | BO15: =IF(OR(AND(G15>$AS$1,G15<$AT$1),AND(G15>$AU$1,G15<$AV$1)),"aynı gün giderilen arıza") -> FALSE | BP15: =IF(Z15-F15>0,"Bir günden fazla süren arıza",IF(OR(AND(G15>$AS$1,G15<$AT$1),AND(G15>$AU$1,G15<$AV$1)),"aynı gün giderilen arıza")) -> #VALUE! | BQ15: =(Y15-H15)*24*60 -> 14.933333 | BR15: =(AB15-Y15)*24*60 -> #VALUE! | BS15: =(AF15-H15)*24*60 -> #VALUE! | BV15: =COUNTIFS(B$5:B$9999,B15,H$5:H$9999,"<="&AF15,AF$5:AF$9999,">="&H15)-1 -> -1 | BW15: =IF(COUNTIFS(B$5:B$9999,B15,H$5:H$9999,"<="&AF15,AF$5:AF$9999,">="&H15)>1,"Evet, çakışma var","Hayır, çakışma yok") -> Hayır, çakışma yok | BY15: =Y15-H15 -> 0.01037037 | BZ15: =AB15-Y15 -> #VALUE! | CA15: =AB15-H15 -> #VALUE! | CE15: 88 | CF15: =H15 -> 45681.438 | CG15: =AB15 | CK15: =AB15-Y15 -> #VALUE! | CL15: =Y15-H15 -> 0.01037037 | CM15: =AB15-H15 -> #VALUE! | CQ15: =G15 -> 0.43756944 | CR15: =Y15 -> 45681.448 | CS15: =AB15 | CT15: =(CR15-CQ15)*1440 -> 65780655 | CU15: =(CS15-CR15)*1440 -> #VALUE! | CV15: =(CS15-CQ15)*1440 -> #VALUE! | CW15: =CT15/CV15 -> #VALUE!
