Workbook
Name Ana_Kompanent: #REF!
Name Ana_Kompanent: #REF!
Name Ana_Kompanent: #REF!
Name Ant_2: #REF!
Name Araç_Şase: #REF!
Name Araç_Şase: #REF!
Name Araç_Şase_Numaraları: #REF!
Name Araç_Şase_Numaraları: #REF!
Name Araç_Tipi: #REF!
Name Araç_Tipi: #REF!
Name Assembly_Line: #REF!
Name Assembly_Line: #REF!
Name Auxiliary_Power_Unit: #REF!
Name Battery: #REF!
Name Bozankaya: #REF!
Name BOZANKAYA_Design: #REF!
Name BOZANKAYA_Design: #REF!
Name Bölüm: #REF!
Name Bölüm: #REF!
Name Brake_System: #REF!
Name Cab_Desk: #REF!
Name Cable_Duct: #REF!
Name CCTV: #REF!
Name Chassis_Design: #REF!
Name Chassis_Design: #REF!
Name Chassis_Production: #REF!
Name Chassis_Production: #REF!
Name Chassis_Quality: #REF!
Name Chassis_Quality: #REF!
Name Chassis_Quality_Controls: #REF!
Name Chassis_Quality_Controls: #REF!
Name Couplers: #REF!
Name Customer: #REF!
Name Department: #REF!
Name Department: #REF!
Name Door_System: #REF!
Name Driver_HVAC_System: #REF!
Name Driver_Seat: #REF!
Name E_Kabinet: #REF!
Name Electrical_Design: #REF!
Name Electrical_Design: #REF!
Name Electromechanic_Tasarım: #REF!
Name Electromechanic_Tasarım: #REF!
Name Elektrik_Tasarım: #REF!
Name Elektrik_Tasarım: #REF!
Name Emniyet_Sistemi: #REF!
Name Equipment_Supplier: #REF!
Name ESS_Battery_Box: #REF!
Name External_Light: #REF!
Name External_Trim: #REF!
Name Fire_System: #REF!
Name Gangway_Articulation: #REF!
Name Gearbox: #REF!
Name Giriş_Kalite_Kontrol: #REF!
Name Giriş_Kalite_Kontrol: #REF!
Name HataDurumu: #REF!
Name HataGidermeYöntemi1: #REF!
Name HataKaynağı: #REF!
Name HMI: #REF!
Name Horn_Bell: #REF!

Sheet FRACAS (YEDEK)
N1: FRACAS(Hata Raporlama Analizi ve Düzeltici Aksiyon Sitemi) Formu FRACAS(Failure Reporting Analysis And Corrective Action System) Form | AB1: Doküman No / Document Code; FR-549 Yayımlama Tarih / Publish Datei; 23.05.2023 Revizyon Tarihi / Revision; 04.08.2025 Revizyon No: 4 | AP1: =TODAY() -> 46026 | AQ1: X | AR1: Proje Pik Saatleri Proje Peak Times | AS1: 0.27083333 | AT1: 0.39583333 | AU1: 0.66666667 | AV1: 0.8125 | AW1: Proje Ort Hız Proje Avr. Speed | AY1: 18 | AZ1: km | BA1: Proje İşçilik Maliyeti Project Labor Cost | BC1: 11 | BD1: hbm.142536
A3: Araç Bilgileri Vhicle Information | E3: Problem Bilgileri Failure Information | P3: (EN 50126-1:2017 Tabl C.3 | Q3: (EN 50126-1:2017 Tabl C.5 | R3: Çözüm Adımları ve Bilgileri Solution Steps And Information | AO3: Tamir İçin Gerekli Parçalar Needed Parts For Repairing | AW3: Maliyet Cost
A4: Project | B4: Araç Numarası Vehicle Number | C4: Araç Module Vehicle Module | D4: Araç Kilometresi Vehicle Kilometer | E4: FRACAS ID | F4: Hata Tarih/Date | G4: Hata Saat/Time | I4: Arıza Konumu Failure Location | J4: Arıza Tespit Yöntemi Failure Detection Method | K4: Kapsam Scope | L4: İlgili Tedarikçi Relevant Supplier | M4: Proje Bazında Fracas ID Fracas ID Based on Project | N4: Arıza Tanımı Failure Description | O4: DDU Arıza Sınıfı DDU Failure Class | P4: Arıza Sınıfı Failure Class | Q4: Arızanın Emniyetle İlgili Şiddet Kategorisi Safety Related Severity Category of Failure | R4: Arıza Kaynağı Source of Failure | S4: Arıza Tespitini Takiben Yapılan İşlem Action Followed by Fault Detection | T4: Aksiyon Action | U4: Garanti Kapsamı Warranty Coverage | V4: Tamir için Gerekli Personel Sayısı Required Personnel Quantity for Repair | W4: Tamir/Değiştirme Başlama Tarihi Date of Starting to Repair/Replace | X4: Tamir/Değiştirme Başlama Saati Time of Starting to Repair/Replace | Z4: Tamir/Değiştirme Bitiş Tarihi Date of Fnish to Repair/Replace | AA4: Tamir/Değiştirme Bitiş Saati Time of Fnish to Repair/Replace | AC4: Tamir Süresi (dakika) Repair Time (dakika) | AD4: Servise Veriliş Tarih Date of Ready to Service | AE4: Servise Veriliş Saati Time of Ready to Service | AG4: Arıza Tipi Failure Type | AH4: Detaylı Bilgi Detail İnformation | AI4: NCR Numarası NCR Number | AJ4: NCR Kapanış Tarihi NCR Closing Date | AK4: NCR Kapanış Saati NCR Closing Time | AM4: Araç MTTR / MDT | AN4: Kompanent MTTR / MDT | AO4: Ekipman Tedarikçisi Equipment Supplier | AP4: Parça Kodu Part Code | AQ4: Seri Numarası Serial Number | AR4: Parça Adı Part Name | AS4: Adeti Quantity | AT4: Sipariş No Order No | AU4: Sipariş Tarihi Order Date | AV4: Teslim Tarihi Delivery Date | AW4: Malzeme Maliyeti Material Cost | AX4: İşçilik Maliyeti Labor Cost
A5: TIM_1624 | B5: 1001 | D5: 200 | F5: 45636 | G5: 0.29166667 | H5: =F5+G5 -> 45636.292 | I5: Hat/Line | J5: Notified By Customer | K5: Brake_System | L5: Hanning&Kall | M5: =A5&"-"&E5 -> TIM_1624- | N5: abv | O5: B | P5: C:Küçük Arıza | Q5: A | R5: Customer | S5: bndsi | T5: Tamir Edilecek/To Be Repaired | U5: Evet/Yes | V5: 2 | W5: 45636 | X5: 0.45833333 | Y5: =W5+X5 -> 45636.458 | Z5: 45636 | AA5: 0.85416667 | AB5: =Z5+AA5 -> 45636.854 | AC5: =(AF5-H5)*24*60 -> 810 | AD5: 45636 | AE5: 0.85416667 | AF5: =AD5+AE5 -> 45636.854 | AG5: İlk defa karşılaşılan arıza / First time failure | AH5: Bu Arıza Aracın Servise Verilmesine Engel | AL5: =AJ5+AK5 -> 0 | AM5: =IF(AND(P5<>"D:Arıza Değil",AH5="Bu Arıza Aracın Servise Verilmesine Engel Değil"),IF(Z5-F5>0,(AB5-Y5)*24,IF(OR(AND(G5>AS$1,G5<AT$1),AND(G5>AU$1,G5<AV$1)),(AF5-H5)*24,0)),AN5) -> 810 | AN5: =IF(P5<>"D:Arıza Değil",AC5,0) -> 810 | AP5: =IF(AQ1="X", IF(AND(G5>=AS1,G5<=AT1),IF(P5<>"D:Arıza Değil",AC5,0), IF(AND(G5>=AU1,G5<=AV1),IF(P5<>"D:Arıza Değil",AC5,0), "")), "") -> 810 | AW5: 0 | AX5: =V5*AC5*BC$1 -> 17820
M6: =A6&"-"&E6 -> - | Y6: =W6+X6 -> 0 | AB6: =Z6+AA6 -> 0 | AC6: =(AB6-Y6)*24*60 -> 0 | AF6: =AD6+AE6 -> 0 | AL6: =AJ6+AK6 -> 0 | AM6: =IF(AND(P6<>"D:Arıza Değil",AH6="Bu Arıza Aracın Servise Verilmesine Engel Değil"),IF(Z6-F6>0,(AB6-Y6)*24,IF(OR(AND(G6>AS$1,G6<AT$1),AND(G6>AU$1,G6<AV$1)),(AL6-Y6)*24,0)),AN6) -> 0 | AN6: =IF(P6<>"D:Arıza Değil",AC6,0) -> 0 | AP6: =IF(AND(P5<>"D:Arıza Değil",AH5="Bu Arıza Aracın Servise Verilmesine Engel Değil"),IF(Z5-F5>0,(AB5-Y5)*24,IF(AQ1="X",IF(AND(G5>=AS1,G5<=AT1),IF(P5<>"D:Arıza Değil",AC5,0),IF(AND(G5>=AU1,G5<=AV1),IF(P5<>"D:Arıza Değil",AC5,0),"")),0)),AN5) -> 810 | AW6: 0 | AX6: =V6*AC6*BC$1 -> 0
M7: =A7&"-"&E7 -> - | Y7: =W7+X7 -> 0 | AB7: =Z7+AA7 -> 0 | AC7: =(AB7-Y7)*24*60 -> 0 | AF7: =AD7+AE7 -> 0 | AL7: =AJ7+AK7 -> 0 | AM7: =IF(AND(P7<>"D:Arıza Değil",AH7="Bu Arıza Aracın Servise Verilmesine Engel Değil"),IF(Z7-F7>0,(AB7-Y7)*24,IF(OR(AND(G7>AS$1,G7<AT$1),AND(G7>AU$1,G7<AV$1)),(AL7-Y7)*24,0)),AN7) -> 0 | AN7: =IF(P7<>"D:Arıza Değil",AC7,0) -> 0 | AW7: 0 | AX7: =V7*AC7*BC$1 -> 0
M8: =A8&"-"&E8 -> - | Y8: =W8+X8 -> 0 | AB8: =Z8+AA8 -> 0 | AC8: =(AB8-Y8)*24*60 -> 0 | AF8: =AD8+AE8 -> 0 | AL8: =AJ8+AK8 -> 0 | AM8: =IF(AND(P8<>"D:Arıza Değil",AH8="Bu Arıza Aracın Servise Verilmesine Engel Değil"),IF(Z8-F8>0,(AB8-Y8)*24,IF(OR(AND(G8>AS$1,G8<AT$1),AND(G8>AU$1,G8<AV$1)),(AL8-Y8)*24,0)),AN8) -> 0 | AN8: =IF(P8<>"D:Arıza Değil",AC8,0) -> 0 | AW8: 0 | AX8: =V8*AC8*BC$1 -> 0
M9: =A9&"-"&E9 -> - | Y9: =W9+X9 -> 0 | AB9: =Z9+AA9 -> 0 | AC9: =(AB9-Y9)*24*60 -> 0 | AF9: =AD9+AE9 -> 0 | AL9: =AJ9+AK9 -> 0 | AM9: =IF(AND(P9<>"D:Arıza Değil",AH9="Bu Arıza Aracın Servise Verilmesine Engel Değil"),IF(Z9-F9>0,(AB9-Y9)*24,IF(OR(AND(G9>AS$1,G9<AT$1),AND(G9>AU$1,G9<AV$1)),(AL9-Y9)*24,0)),AN9) -> 0 | AN9: =IF(P9<>"D:Arıza Değil",AC9,0) -> 0 | AW9: 0 | AX9: =V9*AC9*BC$1 -> 0
M10: =A10&"-"&E10 -> - | Y10: =W10+X10 -> 0 | AB10: =Z10+AA10 -> 0 | AC10: =(AB10-Y10)*24*60 -> 0 | AF10: =AD10+AE10 -> 0 | AL10: =AJ10+AK10 -> 0 | AM10: =IF(AND(P10<>"D:Arıza Değil",AH10="Bu Arıza Aracın Servise Verilmesine Engel Değil"),IF(Z10-F10>0,(AB10-Y10)*24,IF(OR(AND(G10>AS$1,G10<AT$1),AND(G10>AU$1,G10<AV$1)),(AL10-Y10)*24,0)),AN10) -> 0 | AN10: =IF(P10<>"D:Arıza Değil",AC10,0) -> 0 | AW10: 0 | AX10: =V10*AC10*BC$1 -> 0
M11: =A11&"-"&E11 -> - | Y11: =W11+X11 -> 0 | AB11: =Z11+AA11 -> 0 | AC11: =(AB11-Y11)*24*60 -> 0 | AF11: =AD11+AE11 -> 0 | AL11: =AJ11+AK11 -> 0 | AM11: =IF(AND(P11<>"D:Arıza Değil",AH11="Bu Arıza Aracın Servise Verilmesine Engel Değil"),IF(Z11-F11>0,(AB11-Y11)*24,IF(OR(AND(G11>AS$1,G11<AT$1),AND(G11>AU$1,G11<AV$1)),(AL11-Y11)*24,0)),AN11) -> 0 | AN11: =IF(P11<>"D:Arıza Değil",AC11,0) -> 0 | AW11: 0 | AX11: =V11*AC11*BC$1 -> 0
M12: =A12&"-"&E12 -> - | Y12: =W12+X12 -> 0 | AB12: =Z12+AA12 -> 0 | AC12: =(AB12-Y12)*24*60 -> 0 | AF12: =AD12+AE12 -> 0 | AL12: =AJ12+AK12 -> 0 | AM12: =IF(AND(P12<>"D:Arıza Değil",AH12="Bu Arıza Aracın Servise Verilmesine Engel Değil"),IF(Z12-F12>0,(AB12-Y12)*24,IF(OR(AND(G12>AS$1,G12<AT$1),AND(G12>AU$1,G12<AV$1)),(AL12-Y12)*24,0)),AN12) -> 0 | AN12: =IF(P12<>"D:Arıza Değil",AC12,0) -> 0 | AW12: 0 | AX12: =V12*AC12*BC$1 -> 0
M13: =A13&"-"&E13 -> - | Y13: =W13+X13 -> 0 | AB13: =Z13+AA13 -> 0 | AC13: =(AB13-Y13)*24*60 -> 0 | AF13: =AD13+AE13 -> 0 | AL13: =AJ13+AK13 -> 0 | AM13: =IF(AND(P13<>"D:Arıza Değil",AH13="Bu Arıza Aracın Servise Verilmesine Engel Değil"),IF(Z13-F13>0,(AB13-Y13)*24,IF(OR(AND(G13>AS$1,G13<AT$1),AND(G13>AU$1,G13<AV$1)),(AL13-Y13)*24,0)),AN13) -> 0 | AN13: =IF(P13<>"D:Arıza Değil",AC13,0) -> 0 | AW13: 0 | AX13: =V13*AC13*BC$1 -> 0
M14: =A14&"-"&E14 -> - | Y14: =W14+X14 -> 0 | AB14: =Z14+AA14 -> 0 | AC14: =(AB14-Y14)*24*60 -> 0 | AF14: =AD14+AE14 -> 0 | AL14: =AJ14+AK14 -> 0 | AM14: =IF(AND(P14<>"D:Arıza Değil",AH14="Bu Arıza Aracın Servise Verilmesine Engel Değil"),IF(Z14-F14>0,(AB14-Y14)*24,IF(OR(AND(G14>AS$1,G14<AT$1),AND(G14>AU$1,G14<AV$1)),(AL14-Y14)*24,0)),AN14) -> 0 | AN14: =IF(P14<>"D:Arıza Değil",AC14,0) -> 0 | AW14: 0 | AX14: =V14*AC14*BC$1 -> 0
M15: =A15&"-"&E15 -> - | Y15: =W15+X15 -> 0 | AB15: =Z15+AA15 -> 0 | AC15: =(AB15-Y15)*24*60 -> 0 | AF15: =AD15+AE15 -> 0 | AL15: =AJ15+AK15 -> 0 | AM15: =IF(AND(P15<>"D:Arıza Değil",AH15="Bu Arıza Aracın Servise Verilmesine Engel Değil"),IF(Z15-F15>0,(AB15-Y15)*24,IF(OR(AND(G15>AS$1,G15<AT$1),AND(G15>AU$1,G15<AV$1)),(AL15-Y15)*24,0)),AN15) -> 0 | AN15: =IF(P15<>"D:Arıza Değil",AC15,0) -> 0 | AW15: 0 | AX15: =V15*AC15*BC$1 -> 0
M16: =A16&"-"&E16 -> - | Y16: =W16+X16 -> 0 | AB16: =Z16+AA16 -> 0 | AC16: =(AB16-Y16)*24*60 -> 0 | AF16: =AD16+AE16 -> 0 | AL16: =AJ16+AK16 -> 0 | AM16: =IF(AND(P16<>"D:Arıza Değil",AH16="Bu Arıza Aracın Servise Verilmesine Engel Değil"),IF(Z16-F16>0,(AB16-Y16)*24,IF(OR(AND(G16>AS$1,G16<AT$1),AND(G16>AU$1,G16<AV$1)),(AL16-Y16)*24,0)),AN16) -> 0 | AN16: =IF(P16<>"D:Arıza Değil",AC16,0) -> 0 | AW16: 0 | AX16: =V16*AC16*BC$1 -> 0
M17: =A17&"-"&E17 -> - | Y17: =W17+X17 -> 0 | AB17: =Z17+AA17 -> 0 | AC17: =(AB17-Y17)*24*60 -> 0 | AF17: =AD17+AE17 -> 0 | AL17: =AJ17+AK17 -> 0 | AM17: =IF(AND(P17<>"D:Arıza Değil",AH17="Bu Arıza Aracın Servise Verilmesine Engel Değil"),IF(Z17-F17>0,(AB17-Y17)*24,IF(OR(AND(G17>AS$1,G17<AT$1),AND(G17>AU$1,G17<AV$1)),(AL17-Y17)*24,0)),AN17) -> 0 | AN17: =IF(P17<>"D:Arıza Değil",AC17,0) -> 0 | AW17: 0 | AX17: =V17*AC17*BC$1 -> 0
M18: =A18&"-"&E18 -> - | Y18: =W18+X18 -> 0 | AB18: =Z18+AA18 -> 0 | AC18: =(AB18-Y18)*24*60 -> 0 | AF18: =AD18+AE18 -> 0 | AL18: =AJ18+AK18 -> 0 | AM18: =IF(AND(P18<>"D:Arıza Değil",AH18="Bu Arıza Aracın Servise Verilmesine Engel Değil"),IF(Z18-F18>0,(AB18-Y18)*24,IF(OR(AND(G18>AS$1,G18<AT$1),AND(G18>AU$1,G18<AV$1)),(AL18-Y18)*24,0)),AN18) -> 0 | AN18: =IF(P18<>"D:Arıza Değil",AC18,0) -> 0 | AW18: 0 | AX18: =V18*AC18*BC$1 -> 0
... M856: =A856&"-"&E856 -> - | Y856: =W856+X856 -> 0 | AB856: =Z856+AA856 -> 0 | AC856: =(AB856-Y856)*24*60 -> 0 | AF856: =AD856+AE856 -> 0 | AL856: =AJ856+AK856 -> 0 | AM856: =IF(AND(P856<>"D:Arıza Değil",AH856="Bu Arıza Aracın Servise Verilmesine Engel Değil"),IF(Z856-F856>0,(AB856-Y856)*24,IF(OR(AND(G856>AS$1,G856<AT$1),AND(G856>AU$1,G856<AV$1)),(AL856-Y856)*24,0)),AN856) -> 0 | AN856: =IF(P856<>"D:Arıza Değil",AC856,0) -> 0 | AW856: 0 | AX856: =V856*AC856*BC$1 -> 0

Sheet Haftalık KM Bilgisi ESKİ
C2: Availablity İçin Araç Max Km | D2: =MAX(D5:D56) -> 1200 | E2: =MAX(E5:E56) -> 233 | F2: =MAX(F5:F56) -> 0 | G2: =MAX(G5:G56) -> 0 | H2: =MAX(H5:H56) -> 0 | I2: =MAX(I5:I56) -> 0 | J2: =MAX(J5:J56) -> 0 | K2: =MAX(K5:K56) -> 0 | ... AQ2: =MAX(AQ5:AQ56) -> 0
C3: Araç Son Arıza Km | D3: =_xlfn.MAXIFS(FRACAS!D5:D5,FRACAS!B5:B5,D4) -> 0 | E3: =_xlfn.MAXIFS(FRACAS!E5:E5,FRACAS!C5:C5,E4) -> 0
B4: Tarih | C4: Araç No | D4: 1001 | E4: 1002 | F4: 1003 | G4: 1004 | H4: 1005 | I4: 1006 | J4: 1007 | K4: 1008 | L4: 1009 | M4: 1010 | N4: 1011 | O4: 1012 | P4: 1013 | Q4: 1014 | R4: 1015 | S4: 1016 | T4: 1017 | U4: 1018 | V4: 1019 | W4: 1020 | X4: 1021 | Y4: 1022 | Z4: 1023 | AA4: 1024 | AB4: 1025 | AC4: 1026 | AD4: 1027 | AE4: 1028 | AF4: 1029 | AG4: 1030 | AH4: 1031 | AI4: 1032 | AJ4: 1033 | AK4: 1034 | AL4: 1035 | AM4: 1036 | AN4: 1037 | AO4: 1038 | AP4: 1039 | AQ4: 1040
C5: CW1 | E5: 23
C6: CW2 | D6: 20 | E6: 45
C7: CW3 | D7: 30 | E7: 66
C8: CW4 | D8: 40 | E8: 88
C9: CW5 | D9: 500 | E9: 99
C10: CW6 | D10: 700 | E10: 111
C11: CW7 | D11: 800 | E11: 145
C12: CW8 | D12: 1200 | E12: 233
C13: CW9
C14: CW10
C15: CW11
C16: CW12
C17: CW13
C18: CW14
C19: CW15
C20: CW16
C21: CW17
C22: CW18
C23: CW19
C24: CW20
... C56: CW52

Sheet Analizler ESKİ
C1: Toplam Çalışma Zamanı (min) | D1: Toplam Arıza Sayısı (PCs) | E1: MTTR (min) | F1: MTBF (hour) | G1: Availability | J1: Toplam Çalışma Zamanı (min) | K1: Toplam Arıza Sayısı (PCs) | L1: MTTR (min) | M1: MTBF (hour) | N1: Availability
A2: TIM_16+24 | B2: 1001 | C2: =#REF!/FRACAS!AY$1*60 -> #REF! | D2: =COUNTIF(FRACAS!B$5:B$5,B2) -> 0 | E2: =SUMIF(FRACAS!B$5:B$5,B2,FRACAS!AM$5:AM$5) -> 0 | F2: =IFERROR((1/(D2/C2)),0) -> 0 | G2: =IFERROR((C2-E2)/C2,1) -> 1 | I2: Traction_Converter | J2: =IFERROR(Q$26/FRACAS!AY$1*60,0) -> 0 | K2: =COUNTIF(FRACAS!K$5:K$5,I2) -> 0 | L2: =SUMIF(FRACAS!K$5:K$5,I2,FRACAS!AN$5:AN$8973) -> 0 | M2: =IFERROR((1/(K2/J2)),0) -> 0 | N2: =IFERROR((J2-L2)/J2,1) -> 1 | O2: TIM_16+24 | P2: 1001 | Q2: =#REF! -> #REF!
A3: TIM_16+24 | B3: 1002 | C3: =#REF!/FRACAS!AY$1*60 -> #REF! | D3: =COUNTIF(FRACAS!B$5:B$5,B3) -> 0 | E3: =SUMIF(FRACAS!B$5:B$5,B3,FRACAS!AM$5:AM$5) -> 0 | F3: =IFERROR((1/(D3/C3)),0) -> 0 | G3: =IFERROR((C3-E3)/C3,1) -> 1 | I3: Brake_System | J3: =IFERROR(Q$26/FRACAS!AY$1*60,0) -> 0 | K3: =COUNTIF(FRACAS!K$5:K$5,I3) -> 0 | L3: =SUMIF(FRACAS!K$5:K$5,I3,FRACAS!AN$5:AN$8973) -> 0 | M3: =IFERROR((1/(K3/J3)),0) -> 0 | N3: =IFERROR((J3-L3)/J3,1) -> 1 | O3: TIM_16+24 | P3: 1002 | Q3: =#REF! -> #REF!
A4: TIM_16+24 | B4: 1003 | C4: =#REF!/FRACAS!AY$1*60 -> #REF! | D4: =COUNTIF(FRACAS!B$5:B$5,B4) -> 0 | E4: =SUMIF(FRACAS!B$5:B$5,B4,FRACAS!AM$5:AM$5) -> 0 | F4: =IFERROR((1/(D4/C4)),0) -> 0 | G4: =IFERROR((C4-E4)/C4,1) -> 1 | I4: Pantograf | J4: =IFERROR(Q$26/FRACAS!AY$1*60,0) -> 0 | K4: =COUNTIF(FRACAS!K$5:K$5,I4) -> 0 | L4: =SUMIF(FRACAS!K$5:K$5,I4,FRACAS!AN$5:AN$8973) -> 0 | M4: =IFERROR((1/(K4/J4)),0) -> 0 | N4: =IFERROR((J4-L4)/J4,1) -> 1 | O4: TIM_16+24 | P4: 1003 | Q4: =#REF! -> #REF!
A5: TIM_16+24 | B5: 1004 | C5: =#REF!/FRACAS!AY$1*60 -> #REF! | D5: =COUNTIF(FRACAS!B$5:B$5,B5) -> 0 | E5: =SUMIF(FRACAS!B$5:B$5,B5,FRACAS!AM$5:AM$5) -> 0 | F5: =IFERROR((1/(D5/C5)),0) -> 0 | G5: =IFERROR((C5-E5)/C5,1) -> 1 | I5: TCMS | J5: =IFERROR(Q$26/FRACAS!AY$1*60,0) -> 0 | K5: =COUNTIF(FRACAS!K$5:K$5,I5) -> 0 | L5: =SUMIF(FRACAS!K$5:K$5,I5,FRACAS!AN$5:AN$8973) -> 0 | M5: =IFERROR((1/(K5/J5)),0) -> 0 | N5: =IFERROR((J5-L5)/J5,1) -> 1 | O5: TIM_16+24 | P5: 1004 | Q5: =#REF! -> #REF!
A6: TIM_16+24 | B6: 1005 | C6: =#REF!/FRACAS!AY$1*60 -> #REF! | D6: =COUNTIF(FRACAS!B$5:B$5,B6) -> 0 | E6: =SUMIF(FRACAS!B$5:B$5,B6,FRACAS!AM$5:AM$5) -> 0 | F6: =IFERROR((1/(D6/C6)),0) -> 0 | G6: =IFERROR((C6-E6)/C6,1) -> 1 | I6: Passenger_HVAC_System | J6: =IFERROR(Q$26/FRACAS!AY$1*60,0) -> 0 | K6: =COUNTIF(FRACAS!K$5:K$5,I6) -> 0 | L6: =SUMIF(FRACAS!K$5:K$5,I6,FRACAS!AN$5:AN$8973) -> 0 | M6: =IFERROR((1/(K6/J6)),0) -> 0 | N6: =IFERROR((J6-L6)/J6,1) -> 1 | O6: TIM_16+24 | P6: 1005 | Q6: =#REF! -> #REF!
A7: TIM_16+24 | B7: 1006 | C7: =#REF!/FRACAS!AY$1*60 -> #REF! | D7: =COUNTIF(FRACAS!B$5:B$5,B7) -> 0 | E7: =SUMIF(FRACAS!B$5:B$5,B7,FRACAS!AM$5:AM$5) -> 0 | F7: =IFERROR((1/(D7/C7)),0) -> 0 | G7: =IFERROR((C7-E7)/C7,1) -> 1 | I7: Driver_HVAC_System | J7: =IFERROR(Q$26/FRACAS!AY$1*60,0) -> 0 | K7: =COUNTIF(FRACAS!K$5:K$5,I7) -> 0 | L7: =SUMIF(FRACAS!K$5:K$5,I7,FRACAS!AN$5:AN$8973) -> 0 | M7: =IFERROR((1/(K7/J7)),0) -> 0 | N7: =IFERROR((J7-L7)/J7,1) -> 1 | O7: TIM_16+24 | P7: 1006 | Q7: =#REF! -> #REF!
A8: TIM_16+24 | B8: 1007 | C8: =#REF!/FRACAS!AY$1*60 -> #REF! | D8: =COUNTIF(FRACAS!B$5:B$5,B8) -> 0 | E8: =SUMIF(FRACAS!B$5:B$5,B8,FRACAS!AM$5:AM$5) -> 0 | F8: =IFERROR((1/(D8/C8)),0) -> 0 | G8: =IFERROR((C8-E8)/C8,1) -> 1 | I8: Master_Controler | J8: =IFERROR(Q$26/FRACAS!AY$1*60,0) -> 0 | K8: =COUNTIF(FRACAS!K$5:K$5,I8) -> 0 | L8: =SUMIF(FRACAS!K$5:K$5,I8,FRACAS!AN$5:AN$8973) -> 0 | M8: =IFERROR((1/(K8/J8)),0) -> 0 | N8: =IFERROR((J8-L8)/J8,1) -> 1 | O8: TIM_16+24 | P8: 1007 | Q8: =#REF! -> #REF!
A9: TIM_16+24 | B9: 1008 | C9: =#REF!/FRACAS!AY$1*60 -> #REF! | D9: =COUNTIF(FRACAS!B$5:B$5,B9) -> 0 | E9: =SUMIF(FRACAS!B$5:B$5,B9,FRACAS!AM$5:AM$5) -> 0 | F9: =IFERROR((1/(D9/C9)),0) -> 0 | G9: =IFERROR((C9-E9)/C9,1) -> 1 | I9: CCTV | J9: =IFERROR(Q$26/FRACAS!AY$1*60,0) -> 0 | K9: =COUNTIF(FRACAS!K$5:K$5,I9) -> 0 | L9: =SUMIF(FRACAS!K$5:K$5,I9,FRACAS!AN$5:AN$8973) -> 0 | M9: =IFERROR((1/(K9/J9)),0) -> 0 | N9: =IFERROR((J9-L9)/J9,1) -> 1 | O9: TIM_16+24 | P9: 1008 | Q9: =#REF! -> #REF!
A10: TIM_16+24 | B10: 1009 | C10: =#REF!/FRACAS!AY$1*60 -> #REF! | D10: =COUNTIF(FRACAS!B$5:B$5,B10) -> 0 | E10: =SUMIF(FRACAS!B$5:B$5,B10,FRACAS!AM$5:AM$5) -> 0 | F10: =IFERROR((1/(D10/C10)),0) -> 0 | G10: =IFERROR((C10-E10)/C10,1) -> 1 | I10: HMI | J10: =IFERROR(Q$26/FRACAS!AY$1*60,0) -> 0 | K10: =COUNTIF(FRACAS!K$5:K$5,I10) -> 0 | L10: =SUMIF(FRACAS!K$5:K$5,I10,FRACAS!AN$5:AN$8973) -> 0 | M10: =IFERROR((1/(K10/J10)),0) -> 0 | N10: =IFERROR((J10-L10)/J10,1) -> 1 | O10: TIM_16+24 | P10: 1009 | Q10: =#REF! -> #REF!
A11: TIM_16+24 | B11: 1010 | C11: =#REF!/FRACAS!AY$1*60 -> #REF! | D11: =COUNTIF(FRACAS!B$5:B$5,B11) -> 0 | E11: =SUMIF(FRACAS!B$5:B$5,B11,FRACAS!AM$5:AM$5) -> 0 | F11: =IFERROR((1/(D11/C11)),0) -> 0 | G11: =IFERROR((C11-E11)/C11,1) -> 1 | I11: Passenger_Information | J11: =IFERROR(Q$26/FRACAS!AY$1*60,0) -> 0 | K11: =COUNTIF(FRACAS!K$5:K$5,I11) -> 0 | L11: =SUMIF(FRACAS!K$5:K$5,I11,FRACAS!AN$5:AN$8973) -> 0 | M11: =IFERROR((1/(K11/J11)),0) -> 0 | N11: =IFERROR((J11-L11)/J11,1) -> 1 | O11: TIM_16+24 | P11: 1010 | Q11: =#REF! -> #REF!
A12: TIM_16+24 | B12: 1011 | C12: =#REF!/FRACAS!AY$1*60 -> #REF! | D12: =COUNTIF(FRACAS!B$5:B$5,B12) -> 0 | E12: =SUMIF(FRACAS!B$5:B$5,B12,FRACAS!AM$5:AM$5) -> 0 | F12: =IFERROR((1/(D12/C12)),0) -> 0 | G12: =IFERROR((C12-E12)/C12,1) -> 1 | I12: Sanding_System | J12: =IFERROR(Q$26/FRACAS!AY$1*60,0) -> 0 | K12: =COUNTIF(FRACAS!K$5:K$5,I12) -> 0 | L12: =SUMIF(FRACAS!K$5:K$5,I12,FRACAS!AN$5:AN$8973) -> 0 | M12: =IFERROR((1/(K12/J12)),0) -> 0 | N12: =IFERROR((J12-L12)/J12,1) -> 1 | O12: TIM_16+24 | P12: 1011 | Q12: =#REF! -> #REF!
A13: TIM_16+24 | B13: 1012 | C13: =#REF!/FRACAS!AY$1*60 -> #REF! | D13: =COUNTIF(FRACAS!B$5:B$5,B13) -> 0 | E13: =SUMIF(FRACAS!B$5:B$5,B13,FRACAS!AM$5:AM$5) -> 0 | F13: =IFERROR((1/(D13/C13)),0) -> 0 | G13: =IFERROR((C13-E13)/C13,1) -> 1 | I13: Motor | J13: =IFERROR(Q$26/FRACAS!AY$1*60,0) -> 0 | K13: =COUNTIF(FRACAS!K$5:K$5,I13) -> 0 | L13: =SUMIF(FRACAS!K$5:K$5,I13,FRACAS!AN$5:AN$8973) -> 0 | M13: =IFERROR((1/(K13/J13)),0) -> 0 | N13: =IFERROR((J13-L13)/J13,1) -> 1 | O13: TIM_16+24 | P13: 1012 | Q13: =#REF! -> #REF!
... A25: TIM_16+24 | B25: 1024 | C25: =#REF!/FRACAS!AY$1*60 -> #REF! | D25: =COUNTIF(FRACAS!B$5:B$5,B25) -> 0 | E25: =SUMIF(FRACAS!B$5:B$5,B25,FRACAS!AM$5:AM$5) -> 0 | F25: =IFERROR((1/(D25/C25)),0) -> 0 | G25: =IFERROR((C25-E25)/C25,1) -> 1 | I25: Other | J25: =IFERROR(Q$26/FRACAS!AY$1*60,0) -> 0 | K25: =COUNTIF(FRACAS!K$5:K$5,I25) -> 1 | L25: =SUMIF(FRACAS!K$5:K$5,I25,FRACAS!AN$5:AN$8973) -> 65952540 | M25: =IFERROR((1/(K25/J25)),0) -> 0 | N25: =IFERROR((J25-L25)/J25,1) -> 1 | O25: TIM_16+24 | P25: 1024 | Q25: =#REF! -> #REF!
P26: toplam filo KM | Q26: =SUM(Q2:Q25) -> #REF!
C27: Toplam Arıza Sayısı (PCs) | D27: Bozankaya | E27: Customer | F27: Equipment Supplier
A28: TIM_16+24 | B28: 1001 | C28: =D2 -> 0 | D28: =COUNTIFS(FRACAS!B$5:B$5,B28,FRACAS!R$5:R$5,D$27) -> 0 | E28: =COUNTIFS(FRACAS!B$5:B$5,B28,FRACAS!R$5:R$5,E$27) -> 0 | F28: =COUNTIFS(FRACAS!B$5:B$5,B28,FRACAS!R$5:R$5,F$27) -> 0
A29: TIM_16+24 | B29: 1002 | C29: =D3 -> 0 | D29: =COUNTIFS(FRACAS!B$5:B$5,B29,FRACAS!R$5:R$5,D$27) -> 0 | E29: =COUNTIFS(FRACAS!B$5:B$5,B29,FRACAS!R$5:R$5,E$27) -> 0 | F29: =COUNTIFS(FRACAS!B$5:B$5,B29,FRACAS!R$5:R$5,F$27) -> 0
A30: TIM_16+24 | B30: 1003 | C30: =D4 -> 0 | D30: =COUNTIFS(FRACAS!B$5:B$5,B30,FRACAS!R$5:R$5,D$27) -> 0 | E30: =COUNTIFS(FRACAS!B$5:B$5,B30,FRACAS!R$5:R$5,E$27) -> 0 | F30: =COUNTIFS(FRACAS!B$5:B$5,B30,FRACAS!R$5:R$5,F$27) -> 0
A31: TIM_16+24 | B31: 1004 | C31: =D5 -> 0 | D31: =COUNTIFS(FRACAS!B$5:B$5,B31,FRACAS!R$5:R$5,D$27) -> 0 | E31: =COUNTIFS(FRACAS!B$5:B$5,B31,FRACAS!R$5:R$5,E$27) -> 0 | F31: =COUNTIFS(FRACAS!B$5:B$5,B31,FRACAS!R$5:R$5,F$27) -> 0
A32: TIM_16+24 | B32: 1005 | C32: =D6 -> 0 | D32: =COUNTIFS(FRACAS!B$5:B$5,B32,FRACAS!R$5:R$5,D$27) -> 0 | E32: =COUNTIFS(FRACAS!B$5:B$5,B32,FRACAS!R$5:R$5,E$27) -> 0 | F32: =COUNTIFS(FRACAS!B$5:B$5,B32,FRACAS!R$5:R$5,F$27) -> 0
A33: TIM_16+24 | B33: 1006 | C33: =D7 -> 0 | D33: =COUNTIFS(FRACAS!B$5:B$5,B33,FRACAS!R$5:R$5,D$27) -> 0 | E33: =COUNTIFS(FRACAS!B$5:B$5,B33,FRACAS!R$5:R$5,E$27) -> 0 | F33: =COUNTIFS(FRACAS!B$5:B$5,B33,FRACAS!R$5:R$5,F$27) -> 0
A34: TIM_16+24 | B34: 1007 | C34: =D8 -> 0 | D34: =COUNTIFS(FRACAS!B$5:B$5,B34,FRACAS!R$5:R$5,D$27) -> 0 | E34: =COUNTIFS(FRACAS!B$5:B$5,B34,FRACAS!R$5:R$5,E$27) -> 0 | F34: =COUNTIFS(FRACAS!B$5:B$5,B34,FRACAS!R$5:R$5,F$27) -> 0
A35: TIM_16+24 | B35: 1008 | C35: =D9 -> 0 | D35: =COUNTIFS(FRACAS!B$5:B$5,B35,FRACAS!R$5:R$5,D$27) -> 0 | E35: =COUNTIFS(FRACAS!B$5:B$5,B35,FRACAS!R$5:R$5,E$27) -> 0 | F35: =COUNTIFS(FRACAS!B$5:B$5,B35,FRACAS!R$5:R$5,F$27) -> 0
A36: TIM_16+24 | B36: 1009 | C36: =D10 -> 0 | D36: =COUNTIFS(FRACAS!B$5:B$5,B36,FRACAS!R$5:R$5,D$27) -> 0 | E36: =COUNTIFS(FRACAS!B$5:B$5,B36,FRACAS!R$5:R$5,E$27) -> 0 | F36: =COUNTIFS(FRACAS!B$5:B$5,B36,FRACAS!R$5:R$5,F$27) -> 0
A37: TIM_16+24 | B37: 1010 | C37: =D11 -> 0 | D37: =COUNTIFS(FRACAS!B$5:B$5,B37,FRACAS!R$5:R$5,D$27) -> 0 | E37: =COUNTIFS(FRACAS!B$5:B$5,B37,FRACAS!R$5:R$5,E$27) -> 0 | F37: =COUNTIFS(FRACAS!B$5:B$5,B37,FRACAS!R$5:R$5,F$27) -> 0
A38: TIM_16+24 | B38: 1011 | C38: =D12 -> 0 | D38: =COUNTIFS(FRACAS!B$5:B$5,B38,FRACAS!R$5:R$5,D$27) -> 0 | E38: =COUNTIFS(FRACAS!B$5:B$5,B38,FRACAS!R$5:R$5,E$27) -> 0 | F38: =COUNTIFS(FRACAS!B$5:B$5,B38,FRACAS!R$5:R$5,F$27) -> 0
A39: TIM_16+24 | B39: 1012 | C39: =D13 -> 0 | D39: =COUNTIFS(FRACAS!B$5:B$5,B39,FRACAS!R$5:R$5,D$27) -> 0 | E39: =COUNTIFS(FRACAS!B$5:B$5,B39,FRACAS!R$5:R$5,E$27) -> 0 | F39: =COUNTIFS(FRACAS!B$5:B$5,B39,FRACAS!R$5:R$5,F$27) -> 0
... A51: TIM_16+24 | B51: 1024 | C51: =D25 -> 0 | D51: =COUNTIFS(FRACAS!B$5:B$5,B51,FRACAS!R$5:R$5,D$27) -> 0 | E51: =COUNTIFS(FRACAS!B$5:B$5,B51,FRACAS!R$5:R$5,E$27) -> 0 | F51: =COUNTIFS(FRACAS!B$5:B$5,B51,FRACAS!R$5:R$5,F$27) -> 0
C53: MTTR (min) | D53: Bozankaya | E53: Customer | F53: Equipment Supplier
A54: TIM_16+24 | B54: 1001 | C54: =E2 -> 0 | D54: =SUMIFS(FRACAS!AN$5:AN$5,FRACAS!B$5:B$5,'Analizler ESKİ'!B54,FRACAS!R$5:R$5,D$53) -> 0 | E54: =SUMIFS(FRACAS!AN$5:AN$5,FRACAS!B$5:B$5,'Analizler ESKİ'!B54,FRACAS!R$5:R$5,E$53) -> 0 | F54: =SUMIFS(FRACAS!AN$5:AN$5,FRACAS!B$5:B$5,'Analizler ESKİ'!B54,FRACAS!R$5:R$5,F$53) -> 0
A55: TIM_16+24 | B55: 1002 | C55: =E3 -> 0 | D55: =SUMIFS(FRACAS!AN$5:AN$5,FRACAS!B$5:B$5,'Analizler ESKİ'!B55,FRACAS!R$5:R$5,D$53) -> 0 | E55: =SUMIFS(FRACAS!AN$5:AN$5,FRACAS!B$5:B$5,'Analizler ESKİ'!B55,FRACAS!R$5:R$5,E$53) -> 0 | F55: =SUMIFS(FRACAS!AN$5:AN$5,FRACAS!B$5:B$5,'Analizler ESKİ'!B55,FRACAS!R$5:R$5,F$53) -> 0
A56: TIM_16+24 | B56: 1003 | C56: =E4 -> 0 | D56: =SUMIFS(FRACAS!AN$5:AN$5,FRACAS!B$5:B$5,'Analizler ESKİ'!B56,FRACAS!R$5:R$5,D$53) -> 0 | E56: =SUMIFS(FRACAS!AN$5:AN$5,FRACAS!B$5:B$5,'Analizler ESKİ'!B56,FRACAS!R$5:R$5,E$53) -> 0 | F56: =SUMIFS(FRACAS!AN$5:AN$5,FRACAS!B$5:B$5,'Analizler ESKİ'!B56,FRACAS!R$5:R$5,F$53) -> 0
A57: TIM_16+24 | B57: 1004 | C57: =E5 -> 0 | D57: =SUMIFS(FRACAS!AN$5:AN$5,FRACAS!B$5:B$5,'Analizler ESKİ'!B57,FRACAS!R$5:R$5,D$53) -> 0 | E57: =SUMIFS(FRACAS!AN$5:AN$5,FRACAS!B$5:B$5,'Analizler ESKİ'!B57,FRACAS!R$5:R$5,E$53) -> 0 | F57: =SUMIFS(FRACAS!AN$5:AN$5,FRACAS!B$5:B$5,'Analizler ESKİ'!B57,FRACAS!R$5:R$5,F$53) -> 0
A58: TIM_16+24 | B58: 1005 | C58: =E6 -> 0 | D58: =SUMIFS(FRACAS!AN$5:AN$5,FRACAS!B$5:B$5,'Analizler ESKİ'!B58,FRACAS!R$5:R$5,D$53) -> 0 | E58: =SUMIFS(FRACAS!AN$5:AN$5,FRACAS!B$5:B$5,'Analizler ESKİ'!B58,FRACAS!R$5:R$5,E$53) -> 0 | F58: =SUMIFS(FRACAS!AN$5:AN$5,FRACAS!B$5:B$5,'Analizler ESKİ'!B58,FRACAS!R$5:R$5,F$53) -> 0
A59: TIM_16+24 | B59: 1006 | C59: =E7 -> 0 | D59: =SUMIFS(FRACAS!AN$5:AN$5,FRACAS!B$5:B$5,'Analizler ESKİ'!B59,FRACAS!R$5:R$5,D$53) -> 0 | E59: =SUMIFS(FRACAS!AN$5:AN$5,FRACAS!B$5:B$5,'Analizler ESKİ'!B59,FRACAS!R$5:R$5,E$53) -> 0 | F59: =SUMIFS(FRACAS!AN$5:AN$5,FRACAS!B$5:B$5,'Analizler ESKİ'!B59,FRACAS!R$5:R$5,F$53) -> 0
A60: TIM_16+24 | B60: 1007 | C60: =E8 -> 0 | D60: =SUMIFS(FRACAS!AN$5:AN$5,FRACAS!B$5:B$5,'Analizler ESKİ'!B60,FRACAS!R$5:R$5,D$53) -> 0 | E60: =SUMIFS(FRACAS!AN$5:AN$5,FRACAS!B$5:B$5,'Analizler ESKİ'!B60,FRACAS!R$5:R$5,E$53) -> 0 | F60: =SUMIFS(FRACAS!AN$5:AN$5,FRACAS!B$5:B$5,'Analizler ESKİ'!B60,FRACAS!R$5:R$5,F$53) -> 0
A61: TIM_16+24 | B61: 1008 | C61: =E9 -> 0 | D61: =SUMIFS(FRACAS!AN$5:AN$5,FRACAS!B$5:B$5,'Analizler ESKİ'!B61,FRACAS!R$5:R$5,D$53) -> 0 | E61: =SUMIFS(FRACAS!AN$5:AN$5,FRACAS!B$5:B$5,'Analizler ESKİ'!B61,FRACAS!R$5:R$5,E$53) -> 0 | F61: =SUMIFS(FRACAS!AN$5:AN$5,FRACAS!B$5:B$5,'Analizler ESKİ'!B61,FRACAS!R$5:R$5,F$53) -> 0
A62: TIM_16+24 | B62: 1009 | C62: =E10 -> 0 | D62: =SUMIFS(FRACAS!AN$5:AN$5,FRACAS!B$5:B$5,'Analizler ESKİ'!B62,FRACAS!R$5:R$5,D$53) -> 0 | E62: =SUMIFS(FRACAS!AN$5:AN$5,FRACAS!B$5:B$5,'Analizler ESKİ'!B62,FRACAS!R$5:R$5,E$53) -> 0 | F62: =SUMIFS(FRACAS!AN$5:AN$5,FRACAS!B$5:B$5,'Analizler ESKİ'!B62,FRACAS!R$5:R$5,F$53) -> 0
A63: TIM_16+24 | B63: 1010 | C63: =E11 -> 0 | D63: =SUMIFS(FRACAS!AN$5:AN$5,FRACAS!B$5:B$5,'Analizler ESKİ'!B63,FRACAS!R$5:R$5,D$53) -> 0 | E63: =SUMIFS(FRACAS!AN$5:AN$5,FRACAS!B$5:B$5,'Analizler ESKİ'!B63,FRACAS!R$5:R$5,E$53) -> 0 | F63: =SUMIFS(FRACAS!AN$5:AN$5,FRACAS!B$5:B$5,'Analizler ESKİ'!B63,FRACAS!R$5:R$5,F$53) -> 0
...

Sheet Arıza Tarih -K

Sheet Tamirat süreleri -K

Sheet Açıklama (Description)
C2: FRACAS FORMU | G2: Doküman Kodu Document Code | H2: FR-549
G3: Yayım Tarihi Publish Date | H3: 45873
G4: Revizyon Revision | H4: 4
G5: Sayfa Page | H5: 2/3
B7: * DDU'da arıza sınıfı tanımlanmamış bir arıza tespit edildiğinde, yeni arızaya ait arıza sınıfının belirlenmesi Bozankaya ve Müşteri'nin ilgili mühendisleri tarafından koordine edilecektir.
B9: * When a failure detected which is failure class undefined at DDU, determine the failure classes of new failures will be co-ordinated by relevant engineers of Bozankaya and Customer.
B12: ** Aşağıdaki tabloda yer alan örnekler tamamiyle örneklendirme amaçlı yazılmıştır, gerçek araç konfigürasyonları ile tutarsızlıkları olabilir.
B14: ** The examples in the table below are purely for illustrative purposes, they may be inconsistent with actual vehicle configurations.
B17: FRACAS Page Description
B18: Sütun (Column) | D18: Açıklama (Description) | N18: Örnek (Example)
B19: FRACAS ID | D19: Bu sütun aşağıdaki konfigurasyona göre olşturulmuş FRACAS ID ile doldurulacaktır. | N19: BOZ-IAS16-FF-001
B20: FRACAS ID | D20: This column fill with the FRACAS ID which is created according to below configuration method.
B21: Yıl | D21: Bu sütuna arızanın meydana geldiği yıl yazılacaktır. | N21: 2022
B22: Year | D22: This column fill with the year of failure occurred.
B23: Ay | D23: Bu sütuna arızanın meydana geldiği ay yazılacaktır. | N23: 7
B24: Month | D24: This column fill with the month of failure occurred.
B25: Tarih | D25: Bu sütuna arızanın meydana geldiği tarih yazılacaktır. | N25: 44768
B26: Date | D26: This column fill with the date of failure occurred.
B27: Saat | D27: Bu sütuna arızanın meydana geldiği saat yazılacaktır. | N27: 0.65416667
B28: Time | D28: This column fill with the hour of failure occurred.
B29: Araç ID | D29: Bu sütuna arızanın meydana geldiği araç numarası yazılacaktır. | N29: IAS16-1
B30: Vehicle ID | D30: This column fill with the failured vehicles id.
B31: Araç Modülü | D31: Bu sütuna arızanın meydana geldiği araç modulü yazılacaktır. | N31: T
B32: Vehicle Module | D32: This column fill with the failured vehicles module id.
B33: Arıza Konumu | D33: Bu sütuna arızanın meydana geldiği yer yazılacaktır. | N33: Hat/Line
B34: Failure Location | D34: This column fill with the failure occurred location.
B35: DDU Arıza Sınıfı | D35: Bu sütuna arızalı aracın sürücü ekranındaki (DDU) arıza sınıfı yazılacaktır. | N35: B
B36: DDU Failure Class | D36: This column fill with the failure class which is defined at driver display (DDU) of failured vehicle.
B37: Arıza Tanımı | D37: Bu sütuna arızanın tanımı yazılacaktır. | N37: Yanyana iki yolcu kapısının bypass edilmesi gerekiyor
B38: Failure Description | D38: This column fill with the failure description.
B39: Araç Kilometresi | D39: Bu sütuna aracın kilometresi yazılacaktır. | N39: 12345
B40: Vehicle Kilometer | D40: This column fill with vehicle kilometer.
B41: Arıza Kaynaklı İşlete Gecikmesi (dakika) | D41: Arızanın işletmede kaç dakika gecikme oluşturmuştur? | N41: 17
B42: Failure Caused Operational Delay (min) | D42: How many minutes of delay did the failure cause in the operation?
B43: Arıza Sınıfı (EN 50126-1:2017 Tablo C.3'e göre) | D43: Arıza EN 50126-1:2017 Table C.3'e göre hangi kategoriye girmektedir? | N43: Major/Majör
B44: Failure Class (acc. to EN 50126-1:2017 Table C.3) | D44: What is the category of failure acc. to EN 50126-1:2017 Table C.3?
B45: Arızanın Emniyetle İlgili Şiddet Kategorisi | D45: Arıza EN 50126-1:2017 Table C.5'e göre hangi kategoriye girmektedir? | N45: n.a.
B46: Safety Related Severity Category of Failure | D46: What is the category of failure acc. to EN 50126-1:2017 Table C.5?
B47: Sorumlu | D47: Arızanın sorumlusu kim? | N47: Bozankaya
B48: Responsible | D48: Who is the reponsible of failure?
...

Sheet FRACAS
N1: FRACAS(Hata Raporlama Analizi ve Düzeltici Aksiyon Sitemi) Formu FRACAS(Failure Reporting Analysis And Corrective Action System) Form | AB1: Doküman No / Document Code; FR-549 Yayımlama Tarih / Publish Datei; 23.05.2023 Revizyon Tarihi / Revision; 04.08.2025 Revizyon No: 4 | AP1: =TODAY() -> 46026 | AQ1: X | AR1: Proje Pik Saatleri Proje Peak Times | AS1: 0.27083333 | AT1: 0.39583333 | AU1: 0.66666667 | AV1: 0.8125 | AW1: Proje Ort Hız Proje Avr. Speed | AY1: 18 | AZ1: km | BA1: Proje İşçilik Maliyeti Project Labor Cost | BC1: 11 | BD1: hbm.142536
A3: Araç Bilgileri Vhicle Information | E3: Problem Bilgileri Failure Information | P3: (EN 50126-1:2017 Tabl C.3 | Q3: (EN 50126-1:2017 Tabl C.5 | R3: Çözüm Adımları ve Bilgileri Solution Steps And Information | AO3: Tamir İçin Gerekli Parçalar Needed Parts For Repairing | AW3: Maliyet Cost | AY3: SSH Detayı | BB3: X | CL3: Kompanent MTTR / MDT
A4: Project | B4: Araç Numarası Vehicle Number | C4: Araç Module Vehicle Module | D4: Araç Kilometresi Vehicle Kilometer | E4: FRACAS ID | F4: Hata Tarih/Date | G4: Hata Saat/Time | I4: Arıza Konumu Failure Location | J4: Arıza Tespit Yöntemi Failure Detection Method | K4: Kapsam Scope | L4: İlgili Tedarikçi Relevant Supplier | M4: Proje Bazında Fracas ID Fracas ID Based on Project | N4: Arıza Tanımı Failure Description | O4: DDU Arıza Sınıfı DDU Failure Class | P4: Arıza Sınıfı Failure Class | Q4: Arızanın Emniyetle İlgili Şiddet Kategorisi Safety Related Severity Category of Failure | R4: Arıza Kaynağı Source of Failure | S4: Arıza Tespitini Takiben Yapılan İşlem Action Followed by Fault Detection | T4: Aksiyon Action | U4: Garanti Kapsamı Warranty Coverage | V4: Tamir için Gerekli Personel Sayısı Required Personnel Quantity for Repair | W4: Tamir/Değiştirme Başlama Tarihi Date of Starting to Repair/Replace | X4: Tamir/Değiştirme Başlama Saati Time of Starting to Repair/Replace | Z4: Tamir/Değiştirme Bitiş Tarihi Date of Fnish to Repair/Replace | AA4: Tamir/Değiştirme Bitiş Saati Time of Fnish to Repair/Replace | AC4: Tamir Süresi (dakika) Repair Time (dakika) | AD4: Servise Veriliş Tarih Date of Ready to Service | AE4: Servise Veriliş Saati Time of Ready to Service | AG4: Arıza Tipi Failure Type | AH4: Detaylı Bilgi Detail İnformation | AI4: NCR Numarası NCR Number | AJ4: NCR Kapanış Tarihi NCR Closing Date | AK4: NCR Kapanış Saati NCR Closing Time | AM4: Araç MTTR / MDT | AN4: Kompanent MTTR / MDT | AO4: Ekipman Tedarikçisi Equipment Supplier | AP4: Parça Kodu Part Code | AQ4: Seri Numarası Serial Number | AR4: Parça Adı Part Name | AS4: Adeti Quantity | AT4: Sipariş No Order No | AU4: Sipariş Tarihi Order Date | AV4: Teslim Tarihi Delivery Date | AW4: Malzeme Maliyeti Material Cost | AX4: İşçilik Maliyeti Labor Cost | AY4: No | AZ4: Photo URL | BA4: Arıza Resmi | BB4: Pik Saat Hes. | BE4: NCR Bildiriliş Tarihi | BF4: Arıza Kaynağı (Sorumlu 2) | BJ4: tamire başlama | BK4: tamir süresi | BL4: servise verilme süresi | BM4: Ncr açık kalma süresi | BY4: Tamire Başlama Süresi | BZ4: Tamirat süresi | CA4: toplam arıza süresi | CI4: AYNI GÜN | CJ4: tamir süresi (saat) =(AB-Y)*24 | CK4: servis dışı kalma süresi (saat) =(AF-H)*24 | CL4: servis dışı kalma süresi (dakika)
A5: IASI_18 | B5: 2233 | C5: Tüm Modüller | D5: 0 | E5: BOZ-IASI18-FF-001 | F5: 45793 | G5: 0.625 | H5: =IF(AND(F5="",G5=""),"",(F5+G5)) -> 45793.625 | I5: Depo/Depot | J5: Notified By Bozankaya | K5: Other | L5: Bozankya | M5: =IF(AND(A5="",E5=""),"",(A5&"-"&E5)) -> IASI_18-BOZ-IASI18-FF-001 | N5: Araç gövdesi hilal şeklinde aşırı yamuk. | O5: sürüş devamlılığı | P5: C(Sisteme etki etmeyen arıza) | Q5: N.A(Yaralanma yok) | R5: Bozankaya | S5: Araç şasiden ters tarafa esnatilerek çoğunlukla düzeltilmiştir. | T5: Tamir Edilecek/To Be Repaired | U5: Evet/Yes | V5: 2 | W5: 45797 | X5: 0.58333333 | Y5: =IF(AND(W5="",X5=""),"",(W5+X5)) -> 45797.583 | Z5: 45797 | AA5: 0.79166667 | AB5: =IF(AND(Z5="",AA5=""),"",(Z5+AA5)) -> 45797.792 | AC5: =(AF5-H5)*24*60 -> 65952540 | AD5: 45797 | AE5: 45797 | AF5: =IF(AND(AD5="",AE5=""),"",(AD5+AE5)) -> 91594 | AG5: (I) İlk Defa Karşılaşılan Arıza | AH5: Bu Arıza Aracın Servise Verilmesine Engel Değil | AI5: IASI18-NCR-005 | AL5: =IF(AND(AJ5="",AK5=""),"",(AJ5+AK5)) | AM5: =IF(AND(P5<>"D(Arıza Değil)",AH5="Bu Arıza Aracın Servise Verilmesine Engel Değil"),IF(Z5-F5>0,(AB5-Y5)*24*60,IF(OR(AND(G5>$AS$1,G5<$AT$1),AND(G5>$AU$1,G5<$AV$1)),(AF5-H5)*24*60,0)),AN5) -> 300 | AN5: =IF(P5<>"D(Arıza Değil)",AC5,0) -> 65952540 | AW5: 0 | AX5: 0 | BB5: =IF($AQ$1="X", IF(AND(G5>=$AS$1,G5<=$AT$1),IF(P5<>"D(Arıza Değil)",AC5,0), IF(AND(G5>=$AU$1,G5<=$AV$1),IF(P5<>"D(Arıza Değil)",AC5,0), "")), "") | BJ5: =Y5-H5 -> 3.9583333 | BK5: =AB5-Y5 -> 0.20833333 | BL5: =AF5-AB5 -> 45796.208 | BM5: =AL5-#REF! -> #VALUE! | BY5: =Y5-H5 -> 3.9583333 | BZ5: =AB5-Y5 -> 0.20833333 | CA5: =AB5-H5 -> 4.1666667 | CI5: =IF(Z5=F5,"AYNI GÜN","") | CJ5: =(AB5-Y5)*24 -> 5 | CK5: =(AF5-H5)*24 -> 1099209 | CL5: =(AF5-H5)*24*60 -> 65952540
A6: IASI_18 | B6: 2233 | C6: MC | D6: 0 | E6: BOZ-IASI18-FF-002 | F6: 45793 | G6: 0.625 | H6: =IF(AND(F6="",G6=""),"",(F6+G6)) -> 45793.625 | I6: Depo/Depot | J6: Notified By Bozankaya | K6: Windows | L6: DORAGLASS | M6: =IF(AND(A6="",E6=""),"",(A6&"-"&E6)) -> IASI_18-BOZ-IASI18-FF-002 | N6: MC ön sağ yan cam çatlak. | O6: sürüş devamlılığı | P6: C(Sisteme etki etmeyen arıza) | Q6: N.A(Yaralanma yok) | R6: Bozankaya | S6: Araç indirildikten sonra MC ön sağ yan camın çatlak olduğu tespit edildi. Bu şekilde servise devam edecek. İleri zamanlarda müşteriye cam verilecek ve ihtiyaç halinde değiştirilecek. | T6: Değiştirilecek/To Be Changed | U6: Evet/Yes | V6: 1 | W6: 45793 | X6: 0.625 | Y6: =IF(AND(W6="",X6=""),"",(W6+X6)) -> 45793.625 | Z6: 45793 | AA6: 0.64583333 | AB6: =IF(AND(Z6="",AA6=""),"",(Z6+AA6)) -> 45793.646 | AC6: =(AF6-H6)*24*60 -> 30 | AD6: 45793 | AE6: 0.64583333 | AF6: =IF(AND(AD6="",AE6=""),"",(AD6+AE6)) -> 45793.646 | AG6: (I) İlk Defa Karşılaşılan Arıza | AH6: Bu Arıza Aracın Servise Verilmesine Engel Değil | AI6: IASI18-NCR-001 | AL6: =IF(AND(AJ6="",AK6=""),"",(AJ6+AK6)) | AM6: =IF(AND(P6<>"D(Arıza Değil)",AH6="Bu Arıza Aracın Servise Verilmesine Engel Değil"),IF(Z6-F6>0,(AB6-Y6)*24*60,IF(OR(AND(G6>$AS$1,G6<$AT$1),AND(G6>$AU$1,G6<$AV$1)),(AF6-H6)*24*60,0)),AN6) -> 0 | AN6: =IF(P6<>"D(Arıza Değil)",AC6,0) -> 30 | AW6: 0 | AX6: 0 | BB6: =IF($AQ$1="X", IF(AND(G6>=$AS$1,G6<=$AT$1),IF(P6<>"D(Arıza Değil)",AC6,0), IF(AND(G6>=$AU$1,G6<=$AV$1),IF(P6<>"D(Arıza Değil)",AC6,0), "")), "") | BJ6: =Y6-H6 -> 0 | BK6: =AB6-Y6 -> 0.020833333 | BL6: =AF6-AB6 -> 0 | BM6: =AL6-BE6 -> #VALUE! | BY6: =Y6-H6 -> 0 | BZ6: =AB6-Y6 -> 0.020833333 | CA6: =AB6-H6 -> 0.020833333 | CI6: =IF(Z6=F6,"AYNI GÜN","") -> AYNI GÜN | CJ6: =(AB6-Y6)*24 -> 0.5 | CK6: =(AF6-H6)*24 -> 0.5 | CL6: =(AF6-H6)*24*60 -> 30
A7: IASI_18 | B7: 2233 | C7: MC-M | D7: 0 | E7: BOZ-IASI18-FF-003 | F7: 45793 | G7: 0.625 | H7: =IF(AND(F7="",G7=""),"",(F7+G7)) -> 45793.625 | I7: Depo/Depot | J7: Notified By Bozankaya | K7: Brake_System | L7: Hanning&Kall | M7: =IF(AND(A7="",E7=""),"",(A7&"-"&E7)) -> IASI_18-BOZ-IASI18-FF-003 | N7: MC ve M hidrolik fren hattı boruları araç şasesine sürtüyor. | O7: sürüş devamlılığı | P7: B(Servisten çekmeye etki eden arıza) | Q7: N.A(Yaralanma yok) | R7: Bozankaya | S7: Hidrolik fren hattı boruları şaseye değmektedir. Servise verildikten kısa süre sonra borular delinetek fren arızasına sebebiyet verecektir. Borular şaseye değmeyecek şekilde ayarlandı ve izolasyon yapıldı. | T7: Tamir Edilecek/To Be Repaired | U7: Evet/Yes | V7: 2 | W7: 45793 | X7: 0.66666667 | Y7: =IF(AND(W7="",X7=""),"",(W7+X7)) -> 45793.667 | Z7: 45793 | AA7: 0.6875 | AB7: =IF(AND(Z7="",AA7=""),"",(Z7+AA7)) -> 45793.688 | AC7: =(AF7-H7)*24*60 -> 90 | AD7: 45793 | AE7: 0.6875 | AF7: =IF(AND(AD7="",AE7=""),"",(AD7+AE7)) -> 45793.688 | AG7: (I) İlk Defa Karşılaşılan Arıza | AH7: Bu Arıza Aracın Servise Verilmesine Engel | AI7: IASI18-NCR-002 | AL7: =IF(AND(AJ7="",AK7=""),"",(AJ7+AK7)) | AM7: =IF(AND(P7<>"D(Arıza Değil)",AH7="Bu Arıza Aracın Servise Verilmesine Engel Değil"),IF(Z7-F7>0,(AB7-Y7)*24*60,IF(OR(AND(G7>$AS$1,G7<$AT$1),AND(G7>$AU$1,G7<$AV$1)),(AF7-H7)*24*60,0)),AN7) -> 90 | AN7: =IF(P7<>"D(Arıza Değil)",AC7,0) -> 90 | AW7: 0 | AX7: 0 | BB7: =IF($AQ$1="X", IF(AND(G7>=$AS$1,G7<=$AT$1),IF(P7<>"D(Arıza Değil)",AC7,0), IF(AND(G7>=$AU$1,G7<=$AV$1),IF(P7<>"D(Arıza Değil)",AC7,0), "")), "") | BJ7: =Y7-H7 -> 0.041666667 | BK7: =AB7-Y7 -> 0.020833333 | BL7: =AF7-AB7 -> 0 | BM7: =AL7-BE7 -> #VALUE! | BY7: =Y7-H7 -> 0.041666667 | BZ7: =AB7-Y7 -> 0.020833333 | CA7: =AB7-H7 -> 0.0625 | CI7: =IF(Z7=F7,"AYNI GÜN","") -> AYNI GÜN | CJ7: =(AB7-Y7)*24 -> 0.5 | CK7: =(AF7-H7)*24 -> 1.5 | CL7: =(AF7-H7)*24*60 -> 90
A8: IASI_18 | B8: 2233 | C8: Tüm Modüller | D8: 0 | E8: BOZ-IASI18-FF-004 | F8: 45793 | G8: 0.625 | H8: =IF(AND(F8="",G8=""),"",(F8+G8)) -> 45793.625 | I8: Depo/Depot | J8: Notified By Bozankaya | K8: TCMS | L8: Medcom | M8: =IF(AND(A8="",E8=""),"",(A8&"-"&E8)) -> IASI_18-BOZ-IASI18-FF-004 | N8: CAN2 hattı üsrekli çöküyor. | O8: B-Hız veya güç azalması | P8: B(Servisten çekmeye etki eden arıza) | Q8: N.A(Yaralanma yok) | R8: Equipment_Supplier | S8: Testler esnasında sahaya gelen Medcom ekibi tarafından incelendi. HDMI değişi ile arıza giderildi. | T8: Değiştirilecek/To Be Changed | U8: Evet/Yes | V8: 1 | W8: 45802 | X8: 0.33333333 | Y8: =IF(AND(W8="",X8=""),"",(W8+X8)) -> 45802.333 | Z8: 45802 | AA8: 0.58333333 | AB8: =IF(AND(Z8="",AA8=""),"",(Z8+AA8)) -> 45802.583 | AC8: =(AF8-H8)*24*60 -> 12900 | AD8: 45802 | AE8: 0.58333333 | AF8: =IF(AND(AD8="",AE8=""),"",(AD8+AE8)) -> 45802.583 | AG8: (I) İlk Defa Karşılaşılan Arıza | AH8: Bu Arıza Aracın Servise Verilmesine Engel | AL8: =IF(AND(AJ8="",AK8=""),"",(AJ8+AK8)) | AM8: =IF(AND(P8<>"D(Arıza Değil)",AH8="Bu Arıza Aracın Servise Verilmesine Engel Değil"),IF(Z8-F8>0,(AB8-Y8)*24*60,IF(OR(AND(G8>$AS$1,G8<$AT$1),AND(G8>$AU$1,G8<$AV$1)),(AF8-H8)*24*60,0)),AN8) -> 12900 | AN8: =IF(P8<>"D(Arıza Değil)",AC8,0) -> 12900 | AW8: 0 | AX8: 0 | BB8: =IF($AQ$1="X", IF(AND(G8>=$AS$1,G8<=$AT$1),IF(P8<>"D(Arıza Değil)",AC8,0), IF(AND(G8>=$AU$1,G8<=$AV$1),IF(P8<>"D(Arıza Değil)",AC8,0), "")), "") | BJ8: =Y8-H8 -> 8.7083333 | BK8: =AB8-Y8 -> 0.25 | BL8: =AF8-AB8 -> 0 | BM8: =AL8-BE8 -> #VALUE! | BY8: =Y8-H8 -> 8.7083333 | BZ8: =AB8-Y8 -> 0.25 | CA8: =AB8-H8 -> 8.9583333 | CI8: =IF(Z8=F8,"AYNI GÜN","") | CJ8: =(AB8-Y8)*24 -> 6 | CK8: =(AF8-H8)*24 -> 215 | CL8: =(AF8-H8)*24*60 -> 12900
A9: IASI_18 | B9: 2233 | C9: MC-M | D9: 0 | E9: BOZ-IASI18-FF-005 | F9: 45795 | G9: 0.33333333 | H9: =IF(AND(F9="",G9=""),"",(F9+G9)) -> 45795.333 | I9: Depo/Depot | J9: Notified By Bozankaya | K9: Brake_System | L9: Hanning&Kall | M9: =IF(AND(A9="",E9=""),"",(A9&"-"&E9)) -> IASI_18-BOZ-IASI18-FF-005 | N9: Kabin değişimi için anahtar çevrildiğinde frenler minör arızaya düşüyor. | O9: sürüş devamlılığı | P9: B(Servisten çekmeye etki eden arıza) | Q9: N.A(Yaralanma yok) | R9: Bozankaya | S9: TCMS yazılım güncellemesi ile arıza düzeltildi. | T9: Tamir Edilecek/To Be Repaired | U9: Evet/Yes | V9: 1 | W9: 45795 | X9: 0.41666667 | Y9: =IF(AND(W9="",X9=""),"",(W9+X9)) -> 45795.417 | Z9: 45795 | AA9: 0.5 | AB9: =IF(AND(Z9="",AA9=""),"",(Z9+AA9)) -> 45795.5 | AC9: =(AF9-H9)*24*60 -> 240 | AD9: 45795 | AE9: 0.5 | AF9: =IF(AND(AD9="",AE9=""),"",(AD9+AE9)) -> 45795.5 | AG9: (I) İlk Defa Karşılaşılan Arıza | AH9: Bu Arıza Aracın Servise Verilmesine Engel Değil | AL9: =IF(AND(AJ9="",AK9=""),"",(AJ9+AK9)) | AM9: =IF(AND(P9<>"D(Arıza Değil)",AH9="Bu Arıza Aracın Servise Verilmesine Engel Değil"),IF(Z9-F9>0,(AB9-Y9)*24*60,IF(OR(AND(G9>$AS$1,G9<$AT$1),AND(G9>$AU$1,G9<$AV$1)),(AF9-H9)*24*60,0)),AN9) -> 240 | AN9: =IF(P9<>"D(Arıza Değil)",AC9,0) -> 240 | AW9: 0 | AX9: 0 | BB9: =IF($AQ$1="X", IF(AND(G9>=$AS$1,G9<=$AT$1),IF(P9<>"D(Arıza Değil)",AC9,0), IF(AND(G9>=$AU$1,G9<=$AV$1),IF(P9<>"D(Arıza Değil)",AC9,0), "")), "") -> 240 | BJ9: =Y9-H9 -> 0.083333333 | BK9: =AB9-Y9 -> 0.083333333 | BL9: =AF9-AB9 -> 0 | BM9: =AL9-BE9 -> #VALUE! | BY9: =Y9-H9 -> 0.083333333 | BZ9: =AB9-Y9 -> 0.083333333 | CA9: =AB9-H9 -> 0.16666667 | CI9: =IF(Z9=F9,"AYNI GÜN","") -> AYNI GÜN | CJ9: =(AB9-Y9)*24 -> 2 | CK9: =(AF9-H9)*24 -> 4 | CL9: =(AF9-H9)*24*60 -> 240
A10: IASI_18 | B10: 2233 | C10: MC | D10: 0 | E10: BOZ-IASI18-FF-006 | F10: 45803 | G10: 0.79166667 | H10: =IF(AND(F10="",G10=""),"",(F10+G10)) -> 45803.792 | I10: Depo/Depot | J10: Notified By Bozankaya | K10: Other | L10: Bozankya | M10: =IF(AND(A10="",E10=""),"",(A10&"-"&E10)) -> IASI_18-BOZ-IASI18-FF-006 | N10: Pantograf kaldırma telinin bulunduğu delikten araç içine su alıyor. | O10: sürüş devamlılığı | P10: C(Sisteme etki etmeyen arıza) | Q10: N.A(Yaralanma yok) | R10: Bozankaya | S10: Çatıdan telin indiği braket vidaları tam sıkılmadığı tespit edildi. Vida etraflarında su aldığı tespit edildi. Sıkılarak sorun giderildi. | T10: Tamir Edilecek/To Be Repaired | U10: Evet/Yes | V10: 1 | W10: 45803 | X10: 0.79166667 | Y10: =IF(AND(W10="",X10=""),"",(W10+X10)) -> 45803.792 | Z10: 45803 | AA10: 0.83333333 | AB10: =IF(AND(Z10="",AA10=""),"",(Z10+AA10)) -> 45803.833 | AC10: =(AF10-H10)*24*60 -> 60 | AD10: 45803 | AE10: 0.83333333 | AF10: =IF(AND(AD10="",AE10=""),"",(AD10+AE10)) -> 45803.833 | AG10: (I) İlk Defa Karşılaşılan Arıza | AH10: Bu Arıza Aracın Servise Verilmesine Engel Değil | AI10: IASI18-NCR-007 | AL10: =IF(AND(AJ10="",AK10=""),"",(AJ10+AK10)) | AM10: =IF(AND(P10<>"D(Arıza Değil)",AH10="Bu Arıza Aracın Servise Verilmesine Engel Değil"),IF(Z10-F10>0,(AB10-Y10)*24*60,IF(OR(AND(G10>$AS$1,G10<$AT$1),AND(G10>$AU$1,G10<$AV$1)),(AF10-H10)*24*60,0)),AN10) -> 60 | AN10: =IF(P10<>"D(Arıza Değil)",AC10,0) -> 60 | AW10: 0 | AX10: 0 | BB10: =IF($AQ$1="X", IF(AND(G10>=$AS$1,G10<=$AT$1),IF(P10<>"D(Arıza Değil)",AC10,0), IF(AND(G10>=$AU$1,G10<=$AV$1),IF(P10<>"D(Arıza Değil)",AC10,0), "")), "") -> 60 | BJ10: =Y10-H10 -> 0 | BK10: =AB10-Y10 -> 0.041666667 | BL10: =AF10-AB10 -> 0 | BM10: =AL10-BE10 -> #VALUE! | BY10: =Y10-H10 -> 0 | BZ10: =AB10-Y10 -> 0.041666667 | CA10: =AB10-H10 -> 0.041666667 | CI10: =IF(Z10=F10,"AYNI GÜN","") -> AYNI GÜN | CJ10: =(AB10-Y10)*24 -> 1 | CK10: =(AF10-H10)*24 -> 1 | CL10: =(AF10-H10)*24*60 -> 60
A11: IASI_18 | B11: 2233 | C11: MC-M | D11: 0 | E11: BOZ-IASI18-FF-007 | F11: 45803 | G11: 0.95833333 | H11: =IF(AND(F11="",G11=""),"",(F11+G11)) -> 45803.958 | I11: Hat/Line | J11: Notified By Bozankaya | K11: Internal_Trim | L11: Sazcılar | M11: =IF(AND(A11="",E11=""),"",(A11&"-"&E11)) -> IASI_18-BOZ-IASI18-FF-007 | N11: Boji karkaslarının etraflarından araç içine su almaktadır. | O11: sürüş devamlılığı | P11: C(Sisteme etki etmeyen arıza) | Q11: N.A(Yaralanma yok) | R11: Bozankaya | S11: Araç altından boji üstü kaarkasların araya izolasyon yapıldı. | T11: Tamir Edilecek/To Be Repaired | U11: Evet/Yes | V11: 2 | W11: 45804 | X11: 0.33333333 | Y11: =IF(AND(W11="",X11=""),"",(W11+X11)) -> 45804.333 | Z11: 45804 | AA11: 0.5 | AB11: =IF(AND(Z11="",AA11=""),"",(Z11+AA11)) -> 45804.5 | AC11: =(AF11-H11)*24*60 -> 780 | AD11: 45804 | AE11: 0.5 | AF11: =IF(AND(AD11="",AE11=""),"",(AD11+AE11)) -> 45804.5 | AG11: (I) İlk Defa Karşılaşılan Arıza | AH11: Bu Arıza Aracın Servise Verilmesine Engel Değil | AI11: IASI18-NCR-007 | AL11: =IF(AND(AJ11="",AK11=""),"",(AJ11+AK11)) | AM11: =IF(AND(P11<>"D(Arıza Değil)",AH11="Bu Arıza Aracın Servise Verilmesine Engel Değil"),IF(Z11-F11>0,(AB11-Y11)*24*60,IF(OR(AND(G11>$AS$1,G11<$AT$1),AND(G11>$AU$1,G11<$AV$1)),(AF11-H11)*24*60,0)),AN11) -> 240 | AN11: =IF(P11<>"D(Arıza Değil)",AC11,0) -> 780 | AW11: 0 | AX11: 0 | BB11: =IF($AQ$1="X", IF(AND(G11>=$AS$1,G11<=$AT$1),IF(P11<>"D(Arıza Değil)",AC11,0), IF(AND(G11>=$AU$1,G11<=$AV$1),IF(P11<>"D(Arıza Değil)",AC11,0), "")), "") | BJ11: =Y11-H11 -> 0.375 | BK11: =AB11-Y11 -> 0.16666667 | BL11: =AF11-AB11 -> 0 | BM11: =AL11-BE11 -> #VALUE! | BY11: =Y11-H11 -> 0.375 | BZ11: =AB11-Y11 -> 0.16666667 | CA11: =AB11-H11 -> 0.54166667 | CI11: =IF(Z11=F11,"AYNI GÜN","") | CJ11: =(AB11-Y11)*24 -> 4 | CK11: =(AF11-H11)*24 -> 13 | CL11: =(AF11-H11)*24*60 -> 780
A12: IASI_18 | B12: 2234 | C12: Tüm Modüller | D12: 0 | E12: BOZ-IASI18-FF-008 | F12: 45834 | G12: 0.45833333 | H12: =IF(AND(F12="",G12=""),"",(F12+G12)) -> 45834.458 | I12: Depo/Depot | J12: Notified By Bozankaya | K12: Other | L12: Bozankya | M12: =IF(AND(A12="",E12=""),"",(A12&"-"&E12)) -> IASI_18-BOZ-IASI18-FF-008 | N12: Araç gövdesi yamuk. | O12: sürüş devamlılığı | P12: C(Sisteme etki etmeyen arıza) | Q12: N.A(Yaralanma yok) | R12: Bozankaya | S12: Müşteriden bildirim gelene kadar düzeltme çalışması yapılmayacak. Konu şuanda kapalı konumda. | T12: Tamir Edilecek/To Be Repaired | U12: Evet/Yes | V12: 2 | W12: 45895 | X12: 0.45833333 | Y12: =IF(AND(W12="",X12=""),"",(W12+X12)) -> 45895.458 | Z12: 45834 | AA12: 0.47916667 | AB12: =IF(AND(Z12="",AA12=""),"",(Z12+AA12)) -> 45834.479 | AC12: =(AF12-H12)*24*60 -> 30 | AD12: 45834 | AE12: 0.47916667 | AF12: =IF(AND(AD12="",AE12=""),"",(AD12+AE12)) -> 45834.479 | AG12: (III) Farklı Araçlarda Tekrarlayan Arıza | AH12: Bu Arıza Aracın Servise Verilmesine Engel Değil | AL12: =IF(AND(AJ12="",AK12=""),"",(AJ12+AK12)) | AM12: =IF(AND(P12<>"D(Arıza Değil)",AH12="Bu Arıza Aracın Servise Verilmesine Engel Değil"),IF(Z12-F12>0,(AB12-Y12)*24*60,IF(OR(AND(G12>$AS$1,G12<$AT$1),AND(G12>$AU$1,G12<$AV$1)),(AF12-H12)*24*60,0)),AN12) -> 0 | AN12: =IF(P12<>"D(Arıza Değil)",AC12,0) -> 30 | AW12: 0 | AX12: 0 | BB12: =IF($AQ$1="X", IF(AND(G12>=$AS$1,G12<=$AT$1),IF(P12<>"D(Arıza Değil)",AC12,0), IF(AND(G12>=$AU$1,G12<=$AV$1),IF(P12<>"D(Arıza Değil)",AC12,0), "")), "") | BJ12: =Y12-H12 -> 61 | BK12: =AB12-Y12 -> -60.979167 | BL12: =AF12-AB12 -> 0 | BM12: =AL12-BE12 -> #VALUE! | BY12: =Y12-H12 -> 61 | BZ12: =AB12-Y12 -> -60.979167 | CA12: =AB12-H12 -> 0.020833333 | CI12: =IF(Z12=F12,"AYNI GÜN","") -> AYNI GÜN | CJ12: =(AB12-Y12)*24 -> -1463.5 | CK12: =(AF12-H12)*24 -> 0.5 | CL12: =(AF12-H12)*24*60 -> 30
A13: IASI_18 | B13: 2234 | C13: MC-M | D13: 0 | E13: BOZ-IASI18-FF-009 | F13: 45834 | G13: 0.5 | H13: =IF(AND(F13="",G13=""),"",(F13+G13)) -> 45834.5 | I13: Depo/Depot | J13: Notified By Bozankaya | K13: Brake_System | L13: Hanning&Kall | M13: =IF(AND(A13="",E13=""),"",(A13&"-"&E13)) -> IASI_18-BOZ-IASI18-FF-009 | N13: Ray frenleri çalışmıyor. | O13: sürüş devamlılığı | P13: B(Servisten çekmeye etki eden arıza) | Q13: N.A(Yaralanma yok) | R13: Bozankaya | S13: Yapılan kontrollerde ray fren buton bağlantılarının yapılmadığı görüldü. Buton bağlantısı yapılıp arıza giderildi. | T13: Tamir Edilecek/To Be Repaired | U13: Evet/Yes | V13: 1 | W13: 45834 | X13: 0.5 | Y13: =IF(AND(W13="",X13=""),"",(W13+X13)) -> 45834.5 | Z13: 45834 | AA13: 0.52083333 | AB13: =IF(AND(Z13="",AA13=""),"",(Z13+AA13)) -> 45834.521 | AC13: =(AF13-H13)*24*60 -> 30 | AD13: 45834 | AE13: 0.52083333 | AF13: =IF(AND(AD13="",AE13=""),"",(AD13+AE13)) -> 45834.521 | AG13: (I) İlk Defa Karşılaşılan Arıza | AH13: Bu Arıza Aracın Servise Verilmesine Engel | AL13: =IF(AND(AJ13="",AK13=""),"",(AJ13+AK13)) | AM13: =IF(AND(P13<>"D(Arıza Değil)",AH13="Bu Arıza Aracın Servise Verilmesine Engel Değil"),IF(Z13-F13>0,(AB13-Y13)*24*60,IF(OR(AND(G13>$AS$1,G13<$AT$1),AND(G13>$AU$1,G13<$AV$1)),(AF13-H13)*24*60,0)),AN13) -> 30 | AN13: =IF(P13<>"D(Arıza Değil)",AC13,0) -> 30 | AW13: 0 | AX13: 0 | BB13: =IF($AQ$1="X", IF(AND(G13>=$AS$1,G13<=$AT$1),IF(P13<>"D(Arıza Değil)",AC13,0), IF(AND(G13>=$AU$1,G13<=$AV$1),IF(P13<>"D(Arıza Değil)",AC13,0), "")), "") | BJ13: =Y13-H13 -> 0 | BK13: =AB13-Y13 -> 0.020833333 | BL13: =AF13-AB13 -> 0 | BM13: =AL13-BE13 -> #VALUE! | BY13: =Y13-H13 -> 0 | BZ13: =AB13-Y13 -> 0.020833333 | CA13: =AB13-H13 -> 0.020833333 | CI13: =IF(Z13=F13,"AYNI GÜN","") -> AYNI GÜN | CJ13: =(AB13-Y13)*24 -> 0.5 | CK13: =(AF13-H13)*24 -> 0.5 | CL13: =(AF13-H13)*24*60 -> 30
A14: IASI_18 | B14: 2235 | C14: MC-m | D14: 0 | E14: BOZ-IASI18-FF-010 | F14: 45863 | G14: 0.625 | H14: =IF(AND(F14="",G14=""),"",(F14+G14)) -> 45863.625 | I14: Depo/Depot | J14: Notified By Bozankaya | K14: Brake_System | L14: Hanning&Kall | M14: =IF(AND(A14="",E14=""),"",(A14&"-"&E14)) -> IASI_18-BOZ-IASI18-FF-010 | N14: MC ve M hidrolik fren hattı boruları araç şasesine sürtüyor. | O14: sürüş devamlılığı | P14: B(Servisten çekmeye etki eden arıza) | Q14: N.A(Yaralanma yok) | R14: Bozankaya | S14: Hidrolik fren hattı boruları şaseye değmektedir. Servise verildikten kısa süre sonra borular delinetek fren arızasına sebebiyet verecektir. Borular şaseye değmeyecek şekilde ayarlandı ve izolasyon yapıldı. | T14: Tamir Edilecek/To Be Repaired | U14: Evet/Yes | V14: 2 | W14: 45863 | X14: 0.625 | Y14: =IF(AND(W14="",X14=""),"",(W14+X14)) -> 45863.625 | Z14: 45863 | AA14: 0.66666667 | AB14: =IF(AND(Z14="",AA14=""),"",(Z14+AA14)) -> 45863.667 | AC14: =(AF14-H14)*24*60 -> 60 | AD14: 45863 | AE14: 0.66666667 | AF14: =IF(AND(AD14="",AE14=""),"",(AD14+AE14)) -> 45863.667 | AG14: (III) Farklı Araçlarda Tekrarlayan Arıza | AH14: Bu Arıza Aracın Servise Verilmesine Engel | AL14: =IF(AND(AJ14="",AK14=""),"",(AJ14+AK14)) | AM14: =IF(AND(P14<>"D(Arıza Değil)",AH14="Bu Arıza Aracın Servise Verilmesine Engel Değil"),IF(Z14-F14>0,(AB14-Y14)*24*60,IF(OR(AND(G14>$AS$1,G14<$AT$1),AND(G14>$AU$1,G14<$AV$1)),(AF14-H14)*24*60,0)),AN14) -> 60 | AN14: =IF(P14<>"D(Arıza Değil)",AC14,0) -> 60 | AW14: 0 | AX14: 0 | BB14: =IF($AQ$1="X", IF(AND(G14>=$AS$1,G14<=$AT$1),IF(P14<>"D(Arıza Değil)",AC14,0), IF(AND(G14>=$AU$1,G14<=$AV$1),IF(P14<>"D(Arıza Değil)",AC14,0), "")), "") | BJ14: =Y14-H14 -> 0 | BK14: =AB14-Y14 -> 0.041666667 | BL14: =AF14-AB14 -> 0 | BM14: =AL14-BE14 -> #VALUE! | BY14: =Y14-H14 -> 0 | BZ14: =AB14-Y14 -> 0.041666667 | CA14: =AB14-H14 -> 0.041666667 | CI14: =IF(Z14=F14,"AYNI GÜN","") -> AYNI GÜN | CJ14: =(AB14-Y14)*24 -> 1 | CK14: =(AF14-H14)*24 -> 1 | CL14: =(AF14-H14)*24*60 -> 60
A15: IASI_18 | B15: 2239 | C15: M | D15: 100 | E15: BOZ-IASI18-FF-011 | F15: 45968 | G15: 0.41666667 | H15: =IF(AND(F15="",G15=""),"",(F15+G15)) -> 45968.417 | I15: Hat/Line | J15: Notified By Customer | K15: Suspantion_Damper | L15: 7 | M15: =IF(AND(A15="",E15=""),"",(A15&"-"&E15)) -> IASI_18-BOZ-IASI18-FF-011 | N15: M modül yanal damper vidaları gevşeyerek araç şasesini delmiş. | O15: sürüş devamlılığı | P15: B(Servisten çekmeye etki eden arıza) | Q15: N.A(Yaralanma yok) | R15: Bozankaya | S15: Yapılan incelemelerde M modül tüm damper vidalarının sıkılmadığı ve aracın servise başlamasıdan kısa bir süre sonra yanal damper vidalarının gevşeme soncu araç yan duvarını delerek deforme ettiği düşünülmektedir. Vidaları sıkarak ve eksik olanların yerine de yenilerini takarak sorun giderilmiştir. | T15: Tamir Edilecek/To Be Repaired | U15: Evet/Yes | V15: 2 | W15: 45968 | X15: 0.41666667 | Y15: =IF(AND(W15="",X15=""),"",(W15+X15)) -> 45968.417 | Z15: 45968 | AA15: 0.58333333 | AB15: =IF(AND(Z15="",AA15=""),"",(Z15+AA15)) -> 45968.583 | AC15: =(AF15-H15)*24*60 -> 240 | AD15: 45968 | AE15: 0.58333333 | AF15: =IF(AND(AD15="",AE15=""),"",(AD15+AE15)) -> 45968.583 | AG15: (I) İlk Defa Karşılaşılan Arıza | AH15: Bu Arıza Aracın Servise Verilmesine Engel | AL15: =IF(AND(AJ15="",AK15=""),"",(AJ15+AK15)) | AM15: =IF(AND(P15<>"D(Arıza Değil)",AH15="Bu Arıza Aracın Servise Verilmesine Engel Değil"),IF(Z15-F15>0,(AB15-Y15)*24*60,IF(OR(AND(G15>$AS$1,G15<$AT$1),AND(G15>$AU$1,G15<$AV$1)),(AF15-H15)*24*60,0)),AN15) -> 240 | AN15: =IF(P15<>"D(Arıza Değil)",AC15,0) -> 240 | AW15: 0 | AX15: 0 | BB15: =IF($AQ$1="X", IF(AND(G15>=$AS$1,G15<=$AT$1),IF(P15<>"D(Arıza Değil)",AC15,0), IF(AND(G15>=$AU$1,G15<=$AV$1),IF(P15<>"D(Arıza Değil)",AC15,0), "")), "") | BJ15: =Y15-H15 -> 0 | BK15: =AB15-Y15 -> 0.16666667 | BL15: =AF15-AB15 -> 0 | BM15: =AL15-BE15 -> #VALUE! | BY15: =Y15-H15 -> 0 | BZ15: =AB15-Y15 -> 0.16666667 | CA15: =AB15-H15 -> 0.16666667 | CI15: =IF(Z15=F15,"AYNI GÜN","") -> AYNI GÜN | CJ15: =(AB15-Y15)*24 -> 4 | CK15: =(AF15-H15)*24 -> 4 | CL15: =(AF15-H15)*24*60 -> 240
A16: IASI_18 | B16: 2236 | C16: MC | D16: 1200 | E16: BOZ-IASI18-FF-012 | F16: 45936 | G16: 0.375 | H16: =IF(AND(F16="",G16=""),"",(F16+G16)) -> 45936.375 | I16: Hat/Line | J16: Notified By Customer | K16: Wiper_System | M16: =IF(AND(A16="",E16=""),"",(A16&"-"&E16)) -> IASI_18-BOZ-IASI18-FF-012 | N16: Silecek kolu boş dönüyor ve işlevini yerine getirmiyor. | O16: sürüş devamlılığı | P16: B(Servisten çekmeye etki eden arıza) | Q16: N.A(Yaralanma yok) | R16: Equipment_Supplier | S16: Silecek mekanizma kolu ile siecek fırça kolunun birleştiği yerden deforme olmuş. Onarıldı. Araç servise verildi. | T16: Tamir Edilecek/To Be Repaired | U16: Evet/Yes | V16: 2 | W16: 45936 | X16: 0.39583333 | Y16: =IF(AND(W16="",X16=""),"",(W16+X16)) -> 45936.396 | Z16: 45936 | AA16: 0.47916667 | AB16: =IF(AND(Z16="",AA16=""),"",(Z16+AA16)) -> 45936.479 | AC16: =(AF16-H16)*24*60 -> 180 | AD16: 45936 | AE16: 0.5 | AF16: =IF(AND(AD16="",AE16=""),"",(AD16+AE16)) -> 45936.5 | AG16: (I) İlk Defa Karşılaşılan Arıza | AH16: Bu Arıza Aracın Servise Verilmesine Engel | AL16: =IF(AND(AJ16="",AK16=""),"",(AJ16+AK16)) | AM16: =IF(AND(P16<>"D(Arıza Değil)",AH16="Bu Arıza Aracın Servise Verilmesine Engel Değil"),IF(Z16-F16>0,(AB16-Y16)*24*60,IF(OR(AND(G16>$AS$1,G16<$AT$1),AND(G16>$AU$1,G16<$AV$1)),(AF16-H16)*24*60,0)),AN16) -> 180 | AN16: =IF(P16<>"D(Arıza Değil)",AC16,0) -> 180 | AW16: 0 | AX16: 0 | BB16: =IF($AQ$1="X", IF(AND(G16>=$AS$1,G16<=$AT$1),IF(P16<>"D(Arıza Değil)",AC16,0), IF(AND(G16>=$AU$1,G16<=$AV$1),IF(P16<>"D(Arıza Değil)",AC16,0), "")), "") -> 180 | BJ16: =Y16-H16 -> 0.020833333 | BK16: =AB16-Y16 -> 0.083333333 | BL16: =AF16-AB16 -> 0.020833333 | BM16: =AL16-BE16 -> #VALUE! | BY16: =Y16-H16 -> 0.020833333 | BZ16: =AB16-Y16 -> 0.083333333 | CA16: =AB16-H16 -> 0.10416667 | CI16: =IF(Z16=F16,"AYNI GÜN","") -> AYNI GÜN | CJ16: =(AB16-Y16)*24 -> 2 | CK16: =(AF16-H16)*24 -> 3 | CL16: =(AF16-H16)*24*60 -> 180
A17: IASI_18 | B17: 2233 | C17: MC | D17: 2150 | E17: BOZ-IASI18-FF-013 | F17: 45936 | G17: 0.41666667 | H17: =IF(AND(F17="",G17=""),"",(F17+G17)) -> 45936.417 | I17: Hat/Line | J17: Notified By Customer | K17: Wiper_System | M17: =IF(AND(A17="",E17=""),"",(A17&"-"&E17)) -> IASI_18-BOZ-IASI18-FF-013 | N17: Silecek kolu boş dönüyor ve işlevini yerine getirmiyor. | O17: sürüş devamlılığı | P17: B(Servisten çekmeye etki eden arıza) | Q17: N.A(Yaralanma yok) | R17: Equipment_Supplier | S17: Silecek mekanizma kolu ile siecek fırça kolunun birleştiği yerden deforme olmuş. Onarıldı. Araç servise verildi. | T17: Tamir Edilecek/To Be Repaired | U17: Evet/Yes | V17: 2 | W17: 45936 | X17: 0.41666667 | Y17: =IF(AND(W17="",X17=""),"",(W17+X17)) -> 45936.417 | Z17: 45936 | AA17: 0.5 | AB17: =IF(AND(Z17="",AA17=""),"",(Z17+AA17)) -> 45936.5 | AC17: =(AF17-H17)*24*60 -> 150 | AD17: 45936 | AE17: 0.52083333 | AF17: =IF(AND(AD17="",AE17=""),"",(AD17+AE17)) -> 45936.521 | AG17: (III) Farklı Araçlarda Tekrarlayan Arıza | AH17: Bu Arıza Aracın Servise Verilmesine Engel | AL17: =IF(AND(AJ17="",AK17=""),"",(AJ17+AK17)) | AM17: =IF(AND(P17<>"D(Arıza Değil)",AH17="Bu Arıza Aracın Servise Verilmesine Engel Değil"),IF(Z17-F17>0,(AB17-Y17)*24*60,IF(OR(AND(G17>$AS$1,G17<$AT$1),AND(G17>$AU$1,G17<$AV$1)),(AF17-H17)*24*60,0)),AN17) -> 150 | AN17: =IF(P17<>"D(Arıza Değil)",AC17,0) -> 150 | AW17: 0 | AX17: 0 | BB17: =IF($AQ$1="X", IF(AND(G17>=$AS$1,G17<=$AT$1),IF(P17<>"D(Arıza Değil)",AC17,0), IF(AND(G17>=$AU$1,G17<=$AV$1),IF(P17<>"D(Arıza Değil)",AC17,0), "")), "") | BJ17: =Y17-H17 -> 0 | BK17: =AB17-Y17 -> 0.083333333 | BL17: =AF17-AB17 -> 0.020833333 | BM17: =AL17-BE17 -> #VALUE! | BY17: =Y17-H17 -> 0 | BZ17: =AB17-Y17 -> 0.083333333 | CA17: =AB17-H17 -> 0.083333333 | CI17: =IF(Z17=F17,"AYNI GÜN","") -> AYNI GÜN | CJ17: =(AB17-Y17)*24 -> 2 | CK17: =(AF17-H17)*24 -> 2.5 | CL17: =(AF17-H17)*24*60 -> 150
A18: IASI_18 | B18: 2237 | C18: MC | D18: 1780 | E18: BOZ-IASI18-FF-014 | F18: 45937 | G18: 0.33333333 | H18: =IF(AND(F18="",G18=""),"",(F18+G18)) -> 45937.333 | I18: Hat/Line | J18: Notified By Customer | K18: Wiper_System | M18: =IF(AND(A18="",E18=""),"",(A18&"-"&E18)) -> IASI_18-BOZ-IASI18-FF-014 | N18: Silecek kolu boş dönüyor ve işlevini yerine getirmiyor. | O18: sürüş devamlılığı | P18: B(Servisten çekmeye etki eden arıza) | Q18: N.A(Yaralanma yok) | R18: Equipment_Supplier | S18: Silecek mekanizmasında motoru tutan vidalar gevşekti. Motor başta idi. Onarılarak araç servise verildi. | T18: Tamir Edilecek/To Be Repaired | U18: Evet/Yes | V18: 2 | W18: 45937 | X18: 0.375 | Y18: =IF(AND(W18="",X18=""),"",(W18+X18)) -> 45937.375 | Z18: 45937 | AA18: 0.45833333 | AB18: =IF(AND(Z18="",AA18=""),"",(Z18+AA18)) -> 45937.458 | AC18: =(AF18-H18)*24*60 -> 180 | AD18: 45937 | AE18: 0.45833333 | AF18: =IF(AND(AD18="",AE18=""),"",(AD18+AE18)) -> 45937.458 | AG18: (III) Farklı Araçlarda Tekrarlayan Arıza | AH18: Bu Arıza Aracın Servise Verilmesine Engel | AL18: =IF(AND(AJ18="",AK18=""),"",(AJ18+AK18)) | AM18: =IF(AND(P18<>"D(Arıza Değil)",AH18="Bu Arıza Aracın Servise Verilmesine Engel Değil"),IF(Z18-F18>0,(AB18-Y18)*24*60,IF(OR(AND(G18>$AS$1,G18<$AT$1),AND(G18>$AU$1,G18<$AV$1)),(AF18-H18)*24*60,0)),AN18) -> 180 | AN18: =IF(P18<>"D(Arıza Değil)",AC18,0) -> 180 | AW18: 0 | AX18: 0 | BB18: =IF($AQ$1="X", IF(AND(G18>=$AS$1,G18<=$AT$1),IF(P18<>"D(Arıza Değil)",AC18,0), IF(AND(G18>=$AU$1,G18<=$AV$1),IF(P18<>"D(Arıza Değil)",AC18,0), "")), "") -> 180 | BJ18: =Y18-H18 -> 0.041666667 | BK18: =AB18-Y18 -> 0.083333333 | BL18: =AF18-AB18 -> 0 | BM18: =AL18-BE18 -> #VALUE! | BY18: =Y18-H18 -> 0.041666667 | BZ18: =AB18-Y18 -> 0.083333333 | CA18: =AB18-H18 -> 0.125 | CI18: =IF(Z18=F18,"AYNI GÜN","") -> AYNI GÜN | CJ18: =(AB18-Y18)*24 -> 2 | CK18: =(AF18-H18)*24 -> 3 | CL18: =(AF18-H18)*24*60 -> 180
